Workbook

Sheet Overview
B2: BEST BUY CO., INC. (BBY)
B4: Investor Analysis
B5: Prepared by: | C5: Team 1
B6: Course: | C6: SP26: VALUE FUND: 9810
B7: Date: | C7: =TODAY() -> 46172
B8: Fiscal Year End: | C8: Late January to early February
B9: Currency: | C9: USD ($ millions unless noted)
B10: Sources: | C10: Best Buy 10-Ks (FY2022–FY2024), Earnings Call Transcripts, Facset, CapitalIQ etc
B12: Content:
B13: 1. Assumptions
B14: 2. Historical Data | C14: 3-year actuals pulled from 10-K (FY2022–FY2024), geographic revenue, business segment, industry metrics, and multiples
B15: 3. Revenue Build | C15: P&L with actuals + 5-year forecasts, base case, bear case, bottom up and top down comparision
B16: 4. DCF Model | C16: base and bear case
B17: 5. FCFE Valuation
B18: 6. Comp Analysis | C18: EV/Revenue, EV/EBITDA, P/E
B19: 7. Blended Implied Price Summary
B20: 8. Unit Economics | C20: revenue changes compares to store count etc
B21: 7. WACC | C21: WACC calculation taking market estimates
B22: 8. Estimates in CAGR | C22: 5 year CAGR

Sheet Assumptions
A1: BEST BUY BUSINESS MODEL ASSUMPTIONS BASED ON HISTORICALS AND MARKET DATA
A2: All assumptions finalized and validated against SEC filings (10-K / 10-Q), Q4 FY2026 Earnings Call (Mar 3, 2026), and analyst consensus.
A3: PRIMARY SOURCES: (1) 10-K FY2025: https://www.sec.gov/Archives/edgar/data/0000764478/000076447825000007/bby-20250201x10k.htm (2) 10-Q Q1 FY2026: https://www.sec.gov/Archives/edgar/data/0000764478/000076447825000019/bby-20250503x10q.htm (3) 10-Q Q3 FY2026: https://www.sec.gov/Archives/edgar/data/0000764478/000076447825000057/bby-20251101.htm (4) Q4 FY2026 Transcript: https://www.theglobeandmail.com/investing/markets/stocks/BBY/pressreleases/536814/best-buy-bby-q4-2026-earnings-call-transcript/ (5) Q4 FY2026 Highlights: https://www.dailypolitical.com/2026/03/04/best-buy-q4-earnings-call-highlights.html | H3: Source Links
A4: Assumptions | B4: 2027E | C4: 2028E | D4: 2029E | E4: 2030E | F4: 2031E | G4: Notes
A5: Comparable sales and online mix | H5: Best Buy Q4 FY2026 8-K / Earnings Call, Mar 3, 2026: https://finance.yahoo.com/news/best-buy-q4-earnings-call-194703419.html Earnings Call Full Transcript (Globe & Mail): https://www.theglobeandmail.com/investing/markets/stocks/BBY/pressreleases/536814/best-buy-bby-q4-2026-earnings-call-transcript/
A6: Total Sales Growth % | B6: 0.01 | C6: 0.015 | D6: 0.02 | E6: 0.02 | F6: 0.02 | G6: FY2027E: Midpoint of management guidance range of -1% to +1%. FY2028 to FY2031: Analyst consensus CAGR of 1.5–2.0%, supported by AI PC refresh cycle, Windows 10 EOL tailwind, and gradual housing recovery. | H6: Best Buy Q4 FY2026 Earnings Call, Mar 3, 2026: https://www.theglobeandmail.com/investing/markets/stocks/BBY/pressreleases/536814/best-buy-bby-q4-2026-earnings-call-transcript/ Q4 FY2026 Earnings Call Highlights: https://www.dailypolitical.com/2026/03/04/best-buy-q4-earnings-call-highlights.html
A7: Domestic Sales Growth (%) | B7: 0.01 | C7: 0.015 | D7: 0.02 | E7: 0.02 | F7: 0.02 | G7: FY2027E: midpoint of BBY guidance -1% to +1% (Q4 FY26 8-K, 3-Mar-2026, SEC EDGAR). FY2028-31: analyst consensus 1.5-2.0% CAGR. Same driver set as total comp sales above. | H7: Best Buy 10-K FY2025, International Segment Disclosures: https://www.sec.gov/Archives/edgar/data/0000764478/000076447825000007/bby-20250201x10k.htm
A8: International Sales Growth (%) | B8: 0.01 | C8: 0.015 | D8: 0.02 | E8: 0.02 | F8: 0.02 | G8: No separate Canada guidance issued. Mirrors domestic SSS given similar product mix and consumer electronics cycle. CAD/USD assumed broadly neutral. | H8: Best Buy Q4 FY2026 Earnings Call, Mar 3, 2026: https://finance.yahoo.com/news/best-buy-q4-earnings-call-194703419.html
A9: Online Revenue % of Domestic | B9: 0.4 | C9: 0.41 | D9: 0.42 | E9: 0.43 | F9: 0.44 | G9: FY2027E: continuing upward trend from 39.0% (FY26 actual). FY2028-31: +1ppt/yr assumption; consistent with historical shift to online. Trajectory slowing post-COVID peak (about 37% in FY2023): conservative assumption.
A10: Store Count | H10: Best Buy Q4 FY2026 8-K/Earnings Call, Mar 3, 2026: https://finance.yahoo.com/news/best-buy-q4-earnings-call-194703419.html Earnings Call Full Transcript: https://www.theglobeandmail.com/investing/markets/stocks/BBY/pressreleases/536814/best-buy-bby-q4-2026-earnings-call-transcript/
A11: Total Stores Opened | B11: 6 | C11: 6 | D11: 5 | E11: 5 | F11: 5 | G11: FY2027E: 6 new domestic stores (BBY Q4 FY26 8-K: "first time in several years... six new locations"). FY2028 to 31: gradual normalization | H11: Best Buy Q4 FY2026 Earnings Call, Mar 3, 2026: https://finance.yahoo.com/news/best-buy-q4-earnings-call-194703419.html
A12: Total Stores Closed | B12: 18 | C12: 18 | D12: 16 | E12: 15 | F12: 15 | G12: FY2027E: 20 dom + 15 intl = 35 total, this would be extrapolating FY2026 number which is a one-time restructuring, based on portfolio rationalization trend from BBY 10-K FY2026. New FY2026E: 2 traditional domestic (mgmt guided) + approx.3 residual non-traditional (Outlet/Yardbird tail per restructuring note) + 3 international, which makes about 8 total. FY2028 to FY2031: Normalized lease-expiry attrition of 7 to 10/yr. Our prior assumption was over-relying on one quote from management about traditional domestic closures and ignoring both the non-traditional format wind-down still in progress and the company's own stated long-run closure policy. Revise upward to approx. 18 for FY2027E and 15–18 thereafter. | H12: Best Buy Q4 FY2026 Earnings Call, Mar 3, 2026: https://finance.yahoo.com/news/best-buy-q4-earnings-call-194703419.html
A13: Domestic Stores Opened | B13: 6 | C13: 6 | D13: 5 | E13: 5 | F13: 5 | G13: All new openings are domestic small-format. No international openings planned. | H13: Q4 FY2026 Earnings Call: '6 new stores, closing two as leases come up': https://www.dailypolitical.com/2026/03/04/best-buy-q4-earnings-call-highlights.html Q3 FY2026 10-Q: Restructuring, 'additional [non-traditional] closures FY2027': https://www.sec.gov/Archives/edgar/data/0000764478/000076447825000057/bby-20251101.htm
A14: Domestic Stores Closed | B14: =B12-B16 -> 15 | C14: =C12-C16 -> 15 | D14: =D12-D16 -> 14 | E14: =E12-E16 -> 13 | F14: =F12-F16 -> 13 | G14: Management guided only 2 traditional domestic closures in FY2027. FY2027E: 2 traditional (mgmt) + approx.3 non-traditional residual (Outlet Centers / Yardbird tail from FY2026 restructuring) which makes up 5 total. FY2028 to FY2031: Normalized lease-expiry run-rate of 5 to 7/yr. Yardbird went from 23 to 2 stores during FY2026. Outlet Centers dropped from 25 to 18. The Q3 FY2026 10-Q explicitly states "additional [non-traditional] closures expected in fiscal 2027" as the restructuring winds down. | H14: 10-K FY2025, Intl stores: 160 (Feb-25), 160 (Feb-24), 160 (Jan-23): https://www.sec.gov/Archives/edgar/data/0000764478/000076447825000007/bby-20250201x10k.htm
A15: International Stores Opened | B15: 0 | C15: 0 | D15: 0 | E15: 0 | F15: 0 | G15: No international openings planned. Canada store count flat for 3+ consecutive years with no announced expansion plans. | H15: 10-K FY2025, Intl stores = 160: https://www.sec.gov/Archives/edgar/data/0000764478/000076447825000007/bby-20250201x10k.htm 10-Q Q1 FY2026 (May 2025), Intl stores = 157: https://www.sec.gov/Archives/edgar/data/0000764478/000076447825000019/bby-20250503x10q.htm 10-Q Q3 FY2026 (Nov 2025), Intl stores still 157, no further movement: https://www.sec.gov/Archives/edgar/data/0000764478/000076447825000057/bby-20251101.htm
A16: International Stores Closed | B16: 3 | C16: 3 | D16: 2 | E16: 2 | F16: 2 | G16: No evidence in any filing or guidance supports aggressive Canadian closures. International went 160 to 157 across ALL of FY2026 (3 stores). FY2027E: 3, matching the FY2026 observed run-rate. FY2028 to FY2031: Conservative lease-expiry attrition of 2/yr.
A17: Segment growth | H17: Q4 FY2026 Earnings Call (memory/ASP commentary), Mar 3, 2026: https://www.theglobeandmail.com/investing/markets/stocks/BBY/pressreleases/536814/best-buy-bby-q4-2026-earnings-call-transcript/
A18: Computing & Mobile Phones | B18: 0.02 | C18: 0.04 | D18: 0.03 | E18: 0.02 | F18: 0.02 | G18: FY2027E +2.0%: AI PC upgrade cycle "sweet spot" 2026-27 (finterra/FinContent Mar 2026); memory cost inflation headwind (Q4 FY26 earnings call). FY2028E +4.0%: cycle peaks. Normalizes to +2% FY2029+ | H18: D.A. Davidson / BNN Bloomberg analysis, Nov 2025 (TV units vs. dollars). Q4 FY2026 Earnings Call (category performance), Mar 3, 2026: https://finance.yahoo.com/news/best-buy-q4-earnings-call-194703419.html
A19: Consumer Electronics | B19: -0.02 | C19: 0.015 | D19: 0.02 | E19: 0.02 | F19: 0.02 | G19: FY2027E -2.0%: TV units inflected positive but dollars still -ve (D.A. Davidson, BNN Bloomberg Nov 2025); home theater challenged. FY2028E +1.5%: dollar recovery. FY2029+ +2.0% as housing normalizes | H19: Q4 FY2026 Earnings Call: 'structural shift toward duress replacements': https://www.dailypolitical.com/2026/03/04/best-buy-q4-earnings-call-highlights.html Home Improvement Research Institute (HIRI): 2025–2028 Appliance CAGR ~4.4%: https://www.hiriinfo.org
A20: Appliances | B20: -0.05 | C20: 0 | D20: 0.025 | E20: 0.03 | F20: 0.03 | G20: FY2027E -5.0%: "structural shift toward duress replacements" (Q4 FY26 earnings call); HD/Lowes share pressure. FY2028E flat. FY2029+ +2.5-3.0%: HIRI ~4.4% appliance CAGR 2025-28; housing recovery | H20: Q4 FY2026 Earnings Call: 'AI glasses, PC gaming handhelds, collectibles delivered notable growth'; Meta store layout expansion: https://www.theglobeandmail.com/investing/markets/stocks/BBY/pressreleases/536814/best-buy-bby-q4-2026-earnings-call-transcript/
A21: Entertainment | B21: 0.03 | C21: 0.025 | D21: 0.02 | E21: 0.02 | F21: 0.02 | G21: FY2027E +3.0%: gaming console cycle; AI glasses/Meta partnership. Stable +2-2.5% FY2028+ | H21: Q4 FY2026 Earnings Call: Ads $900M+ run-rate, 10% growth guided: https://www.dailypolitical.com/2026/03/04/best-buy-q4-earnings-call-highlights.html Full transcript (Ads & Marketplace profitability FY2028 commentary): https://www.theglobeandmail.com/investing/markets/stocks/BBY/pressreleases/536814/best-buy-bby-q4-2026-earnings-call-transcript/
A22: Services (Geek Squad/Totaltech/My Best Buy) | B22: 0.04 | C22: 0.05 | D22: 0.05 | E22: 0.04 | F22: 0.04 | G22: FY2027E +4.0% / FY2028+ +5.0%: "material Ads & Marketplace contribution starting FY2028" (Q4 FY26 earnings call); My Best Buy membership; Geek Squad pivot. Eases to +4% FY2030+ | H22: Q4 FY2026 Earnings Call: Ads growth, Marketplace launch, FY2028 inflection: https://www.theglobeandmail.com/investing/markets/stocks/BBY/pressreleases/536814/best-buy-bby-q4-2026-earnings-call-transcript/ Q4 FY2026 Earnings Call Highlights: https://finance.yahoo.com/news/best-buy-q4-earnings-call-194703419.html
A23: Other (Best Buy Ads/Marketplace/New Ventures) | B23: 0.08 | C23: 0.1 | D23: 0.08 | E23: 0.06 | F23: 0.05 | G23: FY2027E +8.0% / FY2028E +10.0%: Best Buy Ads $900M run-rate (FinContent 2026); Marketplace >1,100 sellers; FY2027 final investment year per mgmt. Moderates to +5% by FY2031E
A24: Domestic SSS Growth (%) | B24: 0.004 | C24: 0.01 | D24: 0.0228 | E24: 0.03 | F24: =E24 -> 0.03 | G24: expected 1% to 3.5%, validated hrough PY revenue changes from revenue build. ranges derived from revenue growth consensus (~1.3to 1.9% CAGR), store-level math, and structural driver analysis. A bear scenario (persistent tariffs + macro weakness + memory cost inflation) could keep FY28 to FY29 near flat or slightly negative, while a bull scenario (housing recovery + AI supercycle) could push FY29–FY31 toward 4 to 5%.
A25: International stores SSS Growth (%) | B25: 0.01 | C25: 0.01 | D25: 0.01 | E25: 0.01 | F25: 0.01 | G25: flat growth expected
A26: Services comparables Sales Growth% | B26: 0.11 | C26: 0.12 | D26: 0.12 | E26: 0.1 | F26: 0.09 | G26: Marketplace ramp up due to ads scaling and healthdrag. Entering FY28, heath stabalizes and AI device services helps with the growth rate. Towards FY30 and after, predicting a mature and more stabalized % representation at around 10%
A28: DCF Parameters
A29: WACC | B29: 0.105 | C29: - | D29: - | E29: - | F29: - | G29: 10.5% — elevated vs. sector peers. Reflects tariff/macro uncertainty, consumer electronics cyclicality, and appliance softness. Source: CAPM + peer comp.
A30: Terminal Growth Rate (TGR) | B30: 0.02 | C30: - | D30: - | E30: - | F30: - | G30: 2.0% — conservative; in line with long-run nominal GDP. ~25bps below historical retail median. Implies 12.4× terminal FCFF multiple.
A31: Net Debt ($M) | B31: 1000 | C31: - | D31: - | E31: - | F31: - | G31: Gross debt ~$1.3B less cash ~$0.3B per Q4 FY26 balance sheet. BBY investment-grade rated (BBB); sustainable dividend. Source: Q4 FY26 10-K.
A32: Diluted Shares Outstanding (M) | B32: 210 | C32: - | D32: - | E32: - | F32: - | G32: Reflects ongoing repurchase program. ~200–210M diluted shares. Source: BBY FY26 10-K.
A33: Effective Tax Rate | B33: 0.24 | C33: =B33 -> 0.24 | D33: =C33 -> 0.24 | E33: =D33 -> 0.24 | F33: =E33 -> 0.24 | G33: Consistent with BBY recent historical effective tax rate (~24%). Source: BBY FY26 10-K.
A34: Depreciation & Amortization ($M) | B34: 800 | C34: 793 | D34: 782 | E34: 772 | F34: 762 | G34: Contracting as store count falls,
A35: Capital Expenditures ($M) | B35: 750 | C35: 710 | D35: 700 | E35: 690 | F35: 680 | G35: Modest decline as big-box remodel cycle winds down. Small-format openings (~$2M each × 15/yr = $30M incremental) partially offset savings.
A36: Change in Net Working Capital ($M) | B36: 75 | C36: 50 | D36: 35 | E36: 25 | F36: 20 | G36: Conservative modest outflow; BBY historically runs a lean / negative working capital cycle as a retailer.
A37: Operating Margin % | B37: 0.043 | C37: 0.046 | D37: 0.049 | E37: 0.051 | F37: 0.053
A39: Current Stock Price Used In this Model | B39: 63.39 | C39: as of 4/15/2026
A40: FFCF 2026A | B40: CFO ($1,962) + After-tax interest ($44*24% = $33) − CapEx ($704) ≈ ~$1,291M
A42: PRIMARY SOURCES: (1) 10-K FY2025: https://www.sec.gov/Archives/edgar/data/0000764478/000076447825000007/bby-20250201x10k.htm (2) 10-Q Q1 FY2026: https://www.sec.gov/Archives/edgar/data/0000764478/000076447825000019/bby-20250503x10q.htm (3) 10-Q Q3 FY2026: https://www.sec.gov/Archives/edgar/data/0000764478/000076447825000057/bby-20251101.htm (4) Q4 FY2026 Transcript: https://www.theglobeandmail.com/investing/markets/stocks/BBY/pressreleases/536814/best-buy-bby-q4-2026-earnings-call-transcript/ (5) Q4 FY2026 Highlights: https://www.dailypolitical.com/2026/03/04/best-buy-q4-earnings-call-highlights.html

Sheet Revenue Build - Draft
B2: Description | C2: Units | D2: 2021A | E2: 2022A | F2: 2023A | G2: 2024A | H2: 2025A | I2: 2026A | J2: 2027E | K2: 2028E | L2: 2029E | M2: 2030E | N2: 2031E | O2: Notes
B4: Key Revenue Drivers and Assumptions
B5: Store Sales
B6: Total Comparable Sales Growth | D6: ='Industry Metrics'!G3 -> 0.097 | E6: ='Industry Metrics'!F3 -> 0.104 | F6: ='Industry Metrics'!E3 -> -0.099 | G6: ='Industry Metrics'!D3 -> -0.068 | H6: ='Industry Metrics'!C3 -> -0.023 | I6: ='Industry Metrics'!B3 -> 0.005 | J6: =Assumptions!B6 -> 0.01 | K6: =Assumptions!C6 -> 0.015 | L6: =Assumptions!D6 -> 0.02 | M6: =Assumptions!E6 -> 0.02 | N6: =Assumptions!F6 -> 0.02 | O6: FY2027E: midpoint of BBY guidance -1% to +1% (Q4 FY26 8-K, 3-Mar-2026, SEC EDGAR). FY2028-31: analyst consensus 1.5-2.0% CAGR
B7: Domestic Comparable Sales Growth | D7: ='Industry Metrics'!G4 -> 0.092 | E7: ='Industry Metrics'!F4 -> 0.11 | F7: ='Industry Metrics'!E4 -> -0.103 | G7: ='Industry Metrics'!D4 -> -0.071 | H7: ='Industry Metrics'!C4 -> -0.025 | I7: ='Industry Metrics'!B4 -> 0.004 | J7: =Assumptions!B7 -> 0.01 | K7: =Assumptions!C7 -> 0.015 | L7: =Assumptions!D7 -> 0.02 | M7: =Assumptions!E7 -> 0.02 | N7: =Assumptions!F7 -> 0.02
B8: International Comparable Sales Growth | D8: ='Industry Metrics'!G5 -> 0.15 | E8: ='Industry Metrics'!F5 -> 0.033 | F8: ='Industry Metrics'!E5 -> -0.054 | G8: ='Industry Metrics'!D5 -> -0.032 | H8: ='Industry Metrics'!C5 -> -0.005 | I8: ='Industry Metrics'!B5 -> 0.023 | J8: =Assumptions!B8 -> 0.01 | K8: =Assumptions!C8 -> 0.015 | L8: =Assumptions!D8 -> 0.02 | M8: =Assumptions!E8 -> 0.02 | N8: =Assumptions!F8 -> 0.02
B9: Online Revenue as % of Domestic Rev | D9: ='Industry Metrics'!G9 -> 0.33 | E9: ='Industry Metrics'!F9 -> 0.36 | F9: ='Industry Metrics'!E9 -> 0.34 | G9: ='Industry Metrics'!D9 -> 0.38 | H9: ='Industry Metrics'!C9 -> 0.395 | I9: ='Industry Metrics'!B9 -> 0.39 | J9: =Assumptions!B9 -> 0.4 | K9: =Assumptions!C9 -> 0.41 | L9: =Assumptions!D9 -> 0.42 | M9: =Assumptions!E9 -> 0.43 | N9: =Assumptions!F9 -> 0.44 | O9: FY2027E: continuing upward trend from 39.0% (FY26 actual). FY2028-31: +1ppt/yr assumption; consistent with historical shift to online
B12: Total Store Count
B13: Beginning Store Count | D13: ='Industry Metrics'!G12 -> 1231 | E13: ='Industry Metrics'!F12 -> 1159 | F13: ='Industry Metrics'!E12 -> 1144 | G13: ='Industry Metrics'!D12 -> 1138 | H13: ='Industry Metrics'!C12 -> 1125 | I13: ='Industry Metrics'!B12 -> 1117 | J13: =I16 -> 1068 | K13: =J16 -> 1039 | L13: =K16 -> 1019 | M13: =L16 -> 1004 | N13: =M16 -> 994
B14: Stores Opened | D14: ='Industry Metrics'!G19 -> 3 | E14: ='Industry Metrics'!F19 -> 13 | F14: ='Industry Metrics'!E19 -> 9 | G14: ='Industry Metrics'!D20 -> 15 | H14: ='Industry Metrics'!C19 -> 0 | I14: ='Industry Metrics'!B20 -> 0 | J14: =Assumptions!B11 -> 6 | K14: =Assumptions!C11 -> 6 | L14: =Assumptions!D11 -> 5 | M14: =Assumptions!E11 -> 5 | N14: =Assumptions!F11 -> 5 | O14: FY2027E: 6 new domestic stores (BBY Q4 FY26 8-K: "first time in several years... six new locations"). FY2028-31: gradual normalization
B15: Stores Closed | D15: ='Industry Metrics'!G23 -> 75 | E15: ='Industry Metrics'!F23 -> 28 | F15: ='Industry Metrics'!E23 -> 15 | G15: ='Industry Metrics'!D23 -> 28 | H15: ='Industry Metrics'!C23 -> 8 | I15: ='Industry Metrics'!B23 -> 49 | J15: 35 | K15: 26 | L15: 20 | M15: 15 | N15: 13 | O15: FY2027E: 20 dom + 15 intl = 35 total. Declining from 49 in FY26; based on portfolio rationalization trend from BBY 10-K FY2026
B16: Ending Store Count | D16: =D13+D14-D15 -> 1159 | E16: =E13+E14-E15 -> 1144 | F16: =F13+F14-F15 -> 1138 | G16: =G13+G14-G15 -> 1125 | H16: =H13+H14-H15 -> 1117 | I16: =I13+I14-I15 -> 1068 | J16: =J13+J14-J15 -> 1039 | K16: =K13+K14-K15 -> 1019 | ... N16: =N13+N14-N15 -> 986
B17: Average Store Count | D17: =(D13+D16)/2 -> 1195 | E17: =(E13+E16)/2 -> 1151.5 | F17: =(F13+F16)/2 -> 1141 | G17: =(G13+G16)/2 -> 1131.5 | H17: =(H13+H16)/2 -> 1121 | I17: =(I13+I16)/2 -> 1092.5 | J17: =(J13+J16)/2 -> 1053.5 | K17: =(K13+K16)/2 -> 1029 | ... N17: =(N13+N16)/2 -> 990
B18: Domestic Store Count
B19: Beginning Store Count | D19: ='Industry Metrics'!G13 -> 1009 | E19: ='Industry Metrics'!F13 -> 991 | F19: ='Industry Metrics'!E13 -> 984 | G19: ='Industry Metrics'!D13 -> 978 | H19: ='Industry Metrics'!C13 -> 965 | I19: ='Industry Metrics'!B13 -> 957 | J19: =I22 -> 926 | K19: =J22 -> 912 | L19: =K22 -> 900 | M19: =L22 -> 890 | N19: =M22 -> 883
B20: Stores Opened | D20: ='Industry Metrics'!G21 -> 3 | E20: ='Industry Metrics'!F21 -> 13 | F20: ='Industry Metrics'!E21 -> 9 | G20: ='Industry Metrics'!D21 -> 14 | H20: ='Industry Metrics'!C21 -> 0 | I20: ='Industry Metrics'!B21 -> 0 | J20: 6 | K20: 6 | L20: 5 | M20: 5 | N20: 5
B21: Stores Closed | D21: ='Industry Metrics'!G24 -> 21 | E21: ='Industry Metrics'!F24 -> 20 | F21: ='Industry Metrics'!E24 -> 15 | G21: ='Industry Metrics'!D24 -> 27 | H21: ='Industry Metrics'!C24 -> 8 | I21: ='Industry Metrics'!B24 -> 31 | J21: 20 | K21: 18 | L21: 15 | M21: 12 | N21: 10
B22: Ending Store Count | D22: =D19+D20-D21 -> 991 | E22: =E19+E20-E21 -> 984 | F22: =F19+F20-F21 -> 978 | G22: =G19+G20-G21 -> 965 | H22: =H19+H20-H21 -> 957 | I22: =I19+I20-I21 -> 926 | J22: =J19+J20-J21 -> 912 | K22: =K19+K20-K21 -> 900 | ... N22: =N19+N20-N21 -> 878
B23: Average Store Count | D23: =(D19+D22)/2 -> 1000 | E23: =(E19+E22)/2 -> 987.5 | F23: =(F19+F22)/2 -> 981 | G23: =(G19+G22)/2 -> 971.5 | H23: =(H19+H22)/2 -> 961 | I23: =(I19+I22)/2 -> 941.5 | J23: =(J19+J22)/2 -> 919 | K23: =(K19+K22)/2 -> 906 | ... N23: =(N19+N22)/2 -> 880.5
B24: International Store Count
B25: Beginning Store Count | D25: ='Industry Metrics'!G14 -> 222 | E25: ='Industry Metrics'!F14 -> 168 | F25: ='Industry Metrics'!E14 -> 160 | G25: ='Industry Metrics'!D14 -> 160 | H25: ='Industry Metrics'!C14 -> 160 | I25: ='Industry Metrics'!B14 -> 160 | J25: =I28 -> 142 | K25: =J28 -> 127 | L25: =K28 -> 119 | M25: =L28 -> 114 | N25: =M28 -> 111
B26: Stores Opened | D26: ='Industry Metrics'!G22 -> 0 | E26: ='Industry Metrics'!F22 -> 0 | F26: ='Industry Metrics'!E25 -> 0 | G26: ='Industry Metrics'!D25 -> 1 | H26: ='Industry Metrics'!C25 -> 0 | I26: ='Industry Metrics'!B22 -> 0 | J26: 0 | K26: 0 | L26: 0 | M26: 0 | N26: 0
B27: Stores Closed | D27: ='Industry Metrics'!G25 -> 54 | E27: ='Industry Metrics'!F25 -> 8 | F27: ='Industry Metrics'!E25 -> 0 | G27: ='Industry Metrics'!D25 -> 1 | H27: ='Industry Metrics'!C25 -> 0 | I27: ='Industry Metrics'!B25 -> 18 | J27: 15 | K27: 8 | L27: 5 | M27: 3 | N27: 3
B28: Ending Store Count | D28: =D25+D26-D27 -> 168 | E28: =E25+E26-E27 -> 160 | F28: =F25+F26-F27 -> 160 | G28: =G25+G26-G27 -> 160 | H28: =H25+H26-H27 -> 160 | I28: =I25+I26-I27 -> 142 | J28: =J25+J26-J27 -> 127 | K28: =K25+K26-K27 -> 119 | ... N28: =N25+N26-N27 -> 108
B29: Average Store Count | D29: =(D25+D28)/2 -> 195 | E29: =(E25+E28)/2 -> 164 | F29: =(F25+F28)/2 -> 160 | G29: =(G25+G28)/2 -> 160 | H29: =(H25+H28)/2 -> 160 | I29: =(I25+I28)/2 -> 151 | J29: =(J25+J28)/2 -> 134.5 | K29: =(K25+K28)/2 -> 123 | ... N29: =(N25+N28)/2 -> 109.5
B31: Revenue Per Store
B32: Domestic Rev per Avg. Store | D32: ='Geographic Revenue'!F6/D23 -> 43.293 | E32: ='Geographic Revenue'!G6/E23 -> 48.435443 | F32: ='Geographic Revenue'!H6/F23 -> 43.622834 | G32: ='Geographic Revenue'!I6/G23 -> 41.273289 | H32: ='Geographic Revenue'!J6/H23 -> 39.789802 | I32: ='Geographic Revenue'!K6/I23 -> 40.656399 | J32: =J45/J23 -> 42.20236 | K32: =K45/K23 -> 43.59187 | L32: =L45/L23 -> 45.134389 | M32: =M45/M23 -> 46.608321 | N32: =N45/N23 -> 47.999425
B33: Y/Y Growth Domestic Rev per Store | E33: =E32/D32-1 -> 0.11878232 | F33: =F32/E32-1 -> -0.099361313 | G33: =G32/F32-1 -> -0.053860442 | H33: =H32/G32-1 -> -0.035943015 | I33: =I32/H32-1 -> 0.021779376 | J33: =J32/I32-1 -> 0.038025027 | K33: =K32/J32-1 -> 0.032924945 | L33: =L32/K32-1 -> 0.035385475 | ... N33: =N32/M32-1 -> 0.029846678
B34: International Rev per Avg. Store | D34: =SUM('Geographic Revenue'!F7:F9)/D29 -> 22.246154 | E34: =SUM('Geographic Revenue'!G7:G9)/E29 -> 24.091463 | F34: =SUM('Geographic Revenue'!H7:H9)/F29 -> 21.9 | G34: =SUM('Geographic Revenue'!I7:I9)/G29 -> 20.96875 | H34: =SUM('Geographic Revenue'!J7:J9)/H29 -> 20.5625 | I34: =SUM('Geographic Revenue'!K7:K9)/I29 -> 22.602649 | J34: =J54/J29 -> 25.629219 | K34: =K54/K29 -> 28.445829 | L34: =L54/L29 -> 30.633594 | M34: =M54/M29 -> 32.357244 | N34: =N54/N29 -> 33.908619
B35: Y/Y Growth International Rev per Store | E35: =E34/D34-1 -> 0.0829496 | F35: =F34/E34-1 -> -0.090964313 | G35: =G34/F34-1 -> -0.042522831 | H35: =H34/G34-1 -> -0.019374069 | I35: =I34/H34-1 -> 0.099216973 | J35: =J34/I34-1 -> 0.13390335 | K35: =K34/J34-1 -> 0.10989837 | L35: =L34/K34-1 -> 0.076909871 | ... N35: =N34/M34-1 -> 0.047945205
B37: Domestic Revenue Build
B38: Comparable Store Rev
B39: Prior Year Domestic Revenue | D39: ='Geographic Revenue'!E6 -> 40114 | E39: ='Geographic Revenue'!F6 -> 43293 | F39: ='Geographic Revenue'!G6 -> 47830 | G39: ='Geographic Revenue'!H6 -> 42794 | H39: ='Geographic Revenue'!I6 -> 40097 | I39: ='Geographic Revenue'!J6 -> 38238 | J39: ='Geographic Revenue'!K6 -> 38278 | K39: =J45 -> 38783.969 | L39: =K45 -> 39494.235 | M39: =L45 -> 40395.279 | N39: =M45 -> 41318.277
B40: Comp Store Base Rev | D40: =D39*(1+D7) -> 43804.488 | E40: =E39*(1+E7) -> 48055.23 | F40: =F39*(1+F7) -> 42903.51 | G40: =G39*(1+G7) -> 39755.626 | H40: =H39*(1+H7) -> 39094.575 | I40: =I39*(1+I7) -> 38390.952 | J40: =J39*(1+J7) -> 38660.78 | K40: =K39*(1+K7) -> 39365.728 | ... N40: =N39*(1+N7) -> 42144.642
B41: New Store Rev
B42: Stores Opened during year | D42: ='Industry Metrics'!G19 -> 3 | E42: ='Industry Metrics'!F19 -> 13 | F42: ='Industry Metrics'!E19 -> 9 | G42: ='Industry Metrics'!D19 -> 15 | H42: ='Industry Metrics'!C19 -> 0 | I42: ='Industry Metrics'!B20 -> 0 | J42: =J20 -> 6 | K42: =K20 -> 6 | L42: =L20 -> 5 | M42: =M20 -> 5 | N42: =N20 -> 5
B43: Rev per New Store | D43: ='Geographic Revenue'!F6/'Revenue Build - Draft'!D23*50% -> 21.6465 | E43: ='Geographic Revenue'!G6/'Revenue Build - Draft'!E23*50% -> 24.217722 | F43: ='Geographic Revenue'!H6/'Revenue Build - Draft'!F23*50% -> 21.811417 | G43: ='Geographic Revenue'!I6/'Revenue Build - Draft'!G23*50% -> 20.636644 | H43: ='Geographic Revenue'!J6/'Revenue Build - Draft'!H23*50% -> 19.894901 | I43: ='Geographic Revenue'!K6/'Revenue Build - Draft'!I23*50% -> 20.3282 | J43: ='Geographic Revenue'!K6/I23*(1+J7)*50% -> 20.531482 | K43: =J45/J23*(1+K7)*50% -> 21.417698 | L43: =K45/K23*(1+L7)*50% -> 22.231854 | M43: =L45/L23*(1+M7)*50% -> 23.018539 | N43: =M45/M23*(1+N7)*50% -> 23.770244 | O43: New store rev = (prior yr rev/avg stores) × (1 + comp growth) × 50% ramp factor (new stores earn half-year revenue in opening year)
B44: Total new Store Rev | D44: =D42*D43 -> 64.9395 | E44: =E42*E43 -> 314.83038 | F44: =F42*F43 -> 196.30275 | G44: =G42*G43 -> 309.54967 | H44: =H42*H43 -> 0 | I44: =I42*I43 -> 0 | J44: =J42*J43 -> 123.18889 | K44: =K42*K43 -> 128.50619 | ... N44: =N42*N43 -> 118.85122
B45: Total Domestic Rev | D45: =D44+D40 -> 43869.428 | E45: =E44+E40 -> 48370.06 | F45: =F44+F40 -> 43099.813 | G45: =G44+G40 -> 40065.176 | H45: =H44+H40 -> 39094.575 | I45: =I44+I40 -> 38390.952 | J45: =J44+J40 -> 38783.969 | K45: =K44+K40 -> 39494.235 | ... N45: =N44+N40 -> 42263.494
B47: International Rev Build
...

Sheet Historical Data ==>
A1: Historical Data

Sheet Geographic Revenue
A1: BBY-US
A2: Sales
B3: JAN '17 | C3: JAN '18 | D3: JAN '19 | E3: JAN '20 | F3: JAN '21 | G3: JAN '22 | H3: JAN '23 | I3: JAN '24 | J3: JAN '25 | K3: JAN '26
B4: 364 Days | C4: 371 Days | D4: 364 Days | E4: 364 Days | F4: 364 Days | G4: 364 Days | H4: 364 Days | I4: 371 Days | J4: 364 Days | K4: 364 Days
A5: Total | B5: =SUM(B6:B8) -> 39403 | C5: =SUM(C6:C8) -> 42151 | D5: =SUM(D6:D8) -> 42879 | E5: =SUM(E6:E8) -> 43638 | F5: =SUM(F6:F8) -> 47262 | G5: =SUM(G6:G8) -> 51761 | H5: =SUM(H6:H8) -> 46298 | I5: =SUM(I6:I8) -> 43452 | ... K5: =SUM(K6:K8) -> 41691
A6: United States | B6: 36248 | C6: 38662 | D6: 39304 | E6: 40114 | F6: 43293 | G6: 47830 | H6: 42794 | I6: 40097 | J6: 38238 | K6: 38278
A7: Canada | B7: 2899 | C7: 3187 | D7: 3214 | E7: 3125 | F7: 3600 | G7: 3911 | H7: 3504 | I7: 3355 | J7: 3290 | K7: 3413
A8: Historical Segments | B8: 256 | C8: 302 | D8: 361 | E8: 399 | F8: 369 | G8: 20 | H8: - | I8: - | J8: - | K8: -
A9: Other | B9: 256 | C9: 302 | D9: 361 | E9: 399 | F9: 369 | G9: 20 | H9: - | I9: - | J9: - | K9: -
A10: All figures in millions of U.S. Dollar
A12: Percent of Total (%)
B13: JAN '17 | C13: JAN '18 | D13: JAN '19 | E13: JAN '20 | F13: JAN '21 | G13: JAN '22 | H13: JAN '23 | I13: JAN '24 | J13: JAN '25 | K13: JAN '26
A14: Total | B14: 100 | C14: 99.999994 | D14: 99.999997 | E14: 100 | F14: 100 | G14: 100 | H14: 100 | I14: 100 | J14: 100 | K14: 100
A15: United States | B15: 91.992996 | C15: 91.72261 | D15: 91.662582 | E15: 91.924469 | F15: 91.602135 | G15: 92.405479 | H15: 92.431641 | I15: 92.278839 | J15: 92.077637 | K15: 91.813583
A16: Canada | B16: 7.357307 | C16: 7.560912 | D16: 7.495511 | E16: 7.16119 | F16: 7.617113 | G16: 7.555882 | H16: 7.568362 | I16: 7.721163 | J16: 7.922366 | K16: 8.186419
A17: Historical Segments | B17: 0.649697 | C17: 0.716472 | D17: 0.841904 | E17: 0.914341 | F17: 0.780754 | G17: 0.038639 | H17: - | I17: - | J17: - | K17: -
A18: Other | B18: 0.649697 | C18: 0.716472 | D18: 0.841904 | E18: 0.914341 | F18: 0.780754 | G18: 0.038639 | H18: - | I18: - | J18: - | K18: -
A20: Growth (%)
B21: JAN '17 | C21: JAN '18 | D21: JAN '19 | E21: JAN '20 | F21: JAN '21 | G21: JAN '22 | H21: JAN '23 | I21: JAN '24 | J21: JAN '25 | K21: JAN '26
A22: Total | B22: -0.316232 | C22: 6.97409 | D22: 1.72712 | E22: 1.7701 | F22: 8.30469 | G22: 9.51928 | H22: -10.5543 | I22: -6.14713 | J22: -4.42787 | K22: 0.392506
A23: United States | B23: -0.321738 | C23: 6.659678 | D23: 1.660545 | E23: 2.060859 | F23: 7.924914 | G23: 10.479754 | H23: -10.528956 | I23: -6.302285 | J23: -4.636257 | K23: 0.104608
A24: Canada | B24: -0.617072 | C24: 9.93446 | D24: 0.847192 | E24: -2.769135 | F24: 15.2 | G24: 8.638889 | H24: -10.406546 | I24: -4.252283 | J24: -1.937407 | K24: 3.738602
A25: Historical Segments | B25: 4.06504 | C25: 17.9688 | D25: 19.5364 | E25: 10.5263 | F25: -7.5188 | G25: -94.5799 | H25: - | I25: - | J25: - | K25: -
A26: Other | B26: 4.065041 | C26: 17.96875 | D26: 19.536425 | E26: 10.526316 | F26: -7.518797 | G26: -94.579948 | H26: - | I26: - | J26: - | K26: -

Sheet Revenue Build - Top Down
B1: Revenue forecast - using top down approach
B3: Description | C3: Units | D3: 2021A | E3: 2022A | F3: 2023A | G3: 2024A | H3: 2025A | I3: 2026A | J3: 2027E | K3: 2028E | L3: 2029E | M3: 2030E | N3: 2031E
B4: Key Revenue Drivers Based on Assumptions
B5: Store Sales
B6: Total Comparable Sales Growth | C6: % | D6: ='Industry Metrics'!G3 -> 0.097 | E6: ='Industry Metrics'!F3 -> 0.104 | F6: ='Industry Metrics'!E3 -> -0.099 | G6: ='Industry Metrics'!D3 -> -0.068 | H6: ='Industry Metrics'!C3 -> -0.023 | I6: ='Industry Metrics'!B3 -> 0.005 | J6: =Assumptions!B6 -> 0.01 | K6: =Assumptions!C6 -> 0.015 | L6: =Assumptions!D6 -> 0.02 | M6: =Assumptions!E6 -> 0.02 | N6: =Assumptions!F6 -> 0.02
B7: Domestic Comparable Sales Growth | C7: % | D7: ='Industry Metrics'!G4 -> 0.092 | E7: ='Industry Metrics'!F4 -> 0.11 | F7: ='Industry Metrics'!E4 -> -0.103 | G7: ='Industry Metrics'!D4 -> -0.071 | H7: ='Industry Metrics'!C4 -> -0.025 | I7: ='Industry Metrics'!B4 -> 0.004 | J7: =Assumptions!B7 -> 0.01 | K7: =Assumptions!C7 -> 0.015 | L7: =Assumptions!D7 -> 0.02 | M7: =Assumptions!E7 -> 0.02 | N7: =Assumptions!F7 -> 0.02
B8: International Comparable Sales Growth | C8: % | D8: ='Industry Metrics'!G5 -> 0.15 | E8: ='Industry Metrics'!F5 -> 0.033 | F8: ='Industry Metrics'!E5 -> -0.054 | G8: ='Industry Metrics'!D5 -> -0.032 | H8: ='Industry Metrics'!C5 -> -0.005 | I8: ='Industry Metrics'!B5 -> 0.023 | J8: =Assumptions!B8 -> 0.01 | K8: =Assumptions!C8 -> 0.015 | L8: =Assumptions!D8 -> 0.02 | M8: =Assumptions!E8 -> 0.02 | N8: =Assumptions!F8 -> 0.02
B9: Online Revenue as % of Domestic Rev | C9: % | D9: ='Industry Metrics'!G9 -> 0.33 | E9: ='Industry Metrics'!F9 -> 0.36 | F9: ='Industry Metrics'!E9 -> 0.34 | G9: ='Industry Metrics'!D9 -> 0.38 | H9: ='Industry Metrics'!C9 -> 0.395 | I9: ='Industry Metrics'!B9 -> 0.39 | J9: =Assumptions!B9 -> 0.4 | K9: =Assumptions!C9 -> 0.41 | L9: =Assumptions!D9 -> 0.42 | M9: =Assumptions!E9 -> 0.43 | N9: =Assumptions!F9 -> 0.44
B10: Total Store Count
B11: Beginning Store Count | C11: # | D11: ='Industry Metrics'!G12 -> 1231 | E11: ='Industry Metrics'!F12 -> 1159 | F11: ='Industry Metrics'!E12 -> 1144 | G11: ='Industry Metrics'!D12 -> 1138 | H11: ='Industry Metrics'!C12 -> 1125 | I11: ='Industry Metrics'!B12 -> 1117 | J11: =I14 -> 1068 | K11: =J14 -> 1056 | L11: =K14 -> 1044 | M11: =L14 -> 1033 | N11: =M14 -> 1023
B12: Stores Opened | C12: # | D12: ='Industry Metrics'!G19 -> 3 | E12: ='Industry Metrics'!F19 -> 13 | F12: ='Industry Metrics'!E19 -> 9 | G12: ='Industry Metrics'!D20 -> 15 | H12: ='Industry Metrics'!C19 -> 0 | I12: ='Industry Metrics'!B20 -> 0 | J12: =Assumptions!B11 -> 6 | K12: =Assumptions!C11 -> 6 | L12: =Assumptions!D11 -> 5 | M12: =Assumptions!E11 -> 5 | N12: =Assumptions!F11 -> 5
B13: Stores Closed | C13: # | D13: ='Industry Metrics'!G23 -> 75 | E13: ='Industry Metrics'!F23 -> 28 | F13: ='Industry Metrics'!E23 -> 15 | G13: ='Industry Metrics'!D23 -> 28 | H13: ='Industry Metrics'!C23 -> 8 | I13: ='Industry Metrics'!B23 -> 49 | J13: =Assumptions!B12 -> 18 | K13: =Assumptions!C12 -> 18 | L13: =Assumptions!D12 -> 16 | M13: =Assumptions!E12 -> 15 | N13: =Assumptions!F12 -> 15
B14: Ending Store Count | C14: # | D14: =D11+D12-D13 -> 1159 | E14: =E11+E12-E13 -> 1144 | F14: =F11+F12-F13 -> 1138 | G14: =G11+G12-G13 -> 1125 | H14: =H11+H12-H13 -> 1117 | I14: =I11+I12-I13 -> 1068 | J14: =J11+J12-J13 -> 1056 | K14: =K11+K12-K13 -> 1044 | ... N14: =N11+N12-N13 -> 1013
B15: Average Store Count | C15: # | D15: =(D11+D14)/2 -> 1195 | E15: =(E11+E14)/2 -> 1151.5 | F15: =(F11+F14)/2 -> 1141 | G15: =(G11+G14)/2 -> 1131.5 | H15: =(H11+H14)/2 -> 1121 | I15: =(I11+I14)/2 -> 1092.5 | J15: =(J11+J14)/2 -> 1062 | K15: =(K11+K14)/2 -> 1050 | ... N15: =(N11+N14)/2 -> 1018
B16: Domestic Store Count | C16: #
B17: Beginning Store Count | C17: # | D17: ='Industry Metrics'!G13 -> 1009 | E17: ='Industry Metrics'!F13 -> 991 | F17: ='Industry Metrics'!E13 -> 984 | G17: ='Industry Metrics'!D13 -> 978 | H17: ='Industry Metrics'!C13 -> 965 | I17: ='Industry Metrics'!B13 -> 957 | J17: =I20 -> 926 | K17: =J20 -> 917 | L17: =K20 -> 908 | M17: =L20 -> 899 | N17: =M20 -> 891
B18: Stores Opened | C18: # | D18: ='Industry Metrics'!G21 -> 3 | E18: ='Industry Metrics'!F21 -> 13 | F18: ='Industry Metrics'!E21 -> 9 | G18: ='Industry Metrics'!D21 -> 14 | H18: ='Industry Metrics'!C21 -> 0 | I18: ='Industry Metrics'!B21 -> 0 | J18: =Assumptions!B13 -> 6 | K18: =Assumptions!C13 -> 6 | L18: =Assumptions!D13 -> 5 | M18: =Assumptions!E13 -> 5 | N18: =Assumptions!F13 -> 5
B19: Stores Closed | C19: # | D19: ='Industry Metrics'!G24 -> 21 | E19: ='Industry Metrics'!F24 -> 20 | F19: ='Industry Metrics'!E24 -> 15 | G19: ='Industry Metrics'!D24 -> 27 | H19: ='Industry Metrics'!C24 -> 8 | I19: ='Industry Metrics'!B24 -> 31 | J19: =Assumptions!B14 -> 15 | K19: =Assumptions!C14 -> 15 | L19: =Assumptions!D14 -> 14 | M19: =Assumptions!E14 -> 13 | N19: =Assumptions!F14 -> 13
B20: Ending Store Count | C20: # | D20: =D17+D18-D19 -> 991 | E20: =E17+E18-E19 -> 984 | F20: =F17+F18-F19 -> 978 | G20: =G17+G18-G19 -> 965 | H20: =H17+H18-H19 -> 957 | I20: =I17+I18-I19 -> 926 | J20: =J17+J18-J19 -> 917 | K20: =K17+K18-K19 -> 908 | ... N20: =N17+N18-N19 -> 883
B21: Average Store Count | C21: # | D21: =(D17+D20)/2 -> 1000 | E21: =(E17+E20)/2 -> 987.5 | F21: =(F17+F20)/2 -> 981 | G21: =(G17+G20)/2 -> 971.5 | H21: =(H17+H20)/2 -> 961 | I21: =(I17+I20)/2 -> 941.5 | J21: =(J17+J20)/2 -> 921.5 | K21: =(K17+K20)/2 -> 912.5 | ... N21: =(N17+N20)/2 -> 887
B22: International Store Count | C22: #
B23: Beginning Store Count | C23: # | D23: ='Industry Metrics'!G14 -> 222 | E23: ='Industry Metrics'!F14 -> 168 | F23: ='Industry Metrics'!E14 -> 160 | G23: ='Industry Metrics'!D14 -> 160 | H23: ='Industry Metrics'!C14 -> 160 | I23: ='Industry Metrics'!B14 -> 160 | J23: =I26 -> 142 | K23: =J26 -> 139 | L23: =K26 -> 136 | M23: =L26 -> 134 | N23: =M26 -> 132
B24: Stores Opened | C24: # | D24: ='Industry Metrics'!G22 -> 0 | E24: ='Industry Metrics'!F22 -> 0 | F24: ='Industry Metrics'!E25 -> 0 | G24: ='Industry Metrics'!D25 -> 1 | H24: ='Industry Metrics'!C25 -> 0 | I24: ='Industry Metrics'!B22 -> 0 | J24: =Assumptions!B15 -> 0 | K24: =Assumptions!C15 -> 0 | L24: =Assumptions!D15 -> 0 | M24: =Assumptions!E15 -> 0 | N24: =Assumptions!F15 -> 0
B25: Stores Closed | C25: # | D25: ='Industry Metrics'!G25 -> 54 | E25: ='Industry Metrics'!F25 -> 8 | F25: ='Industry Metrics'!E25 -> 0 | G25: ='Industry Metrics'!D25 -> 1 | H25: ='Industry Metrics'!C25 -> 0 | I25: ='Industry Metrics'!B25 -> 18 | J25: =Assumptions!B16 -> 3 | K25: =Assumptions!C16 -> 3 | L25: =Assumptions!D16 -> 2 | M25: =Assumptions!E16 -> 2 | N25: =Assumptions!F16 -> 2
B26: Ending Store Count | C26: # | D26: =D23+D24-D25 -> 168 | E26: =E23+E24-E25 -> 160 | F26: =F23+F24-F25 -> 160 | G26: =G23+G24-G25 -> 160 | H26: =H23+H24-H25 -> 160 | I26: =I23+I24-I25 -> 142 | J26: =J23+J24-J25 -> 139 | K26: =K23+K24-K25 -> 136 | ... N26: =N23+N24-N25 -> 130
B27: Average Store Count | C27: # | D27: =(D23+D26)/2 -> 195 | E27: =(E23+E26)/2 -> 164 | F27: =(F23+F26)/2 -> 160 | G27: =(G23+G26)/2 -> 160 | H27: =(H23+H26)/2 -> 160 | I27: =(I23+I26)/2 -> 151 | J27: =(J23+J26)/2 -> 140.5 | K27: =(K23+K26)/2 -> 137.5 | ... N27: =(N23+N26)/2 -> 131
B28: Revenue Per Store
B29: Domestic Rev per Avg. Store (in millions USD) | C29: $ | D29: ='Geographic Revenue'!F6/D21 -> 43.293 | E29: ='Geographic Revenue'!G6/E21 -> 48.435443 | F29: ='Geographic Revenue'!H6/F21 -> 43.622834 | G29: ='Geographic Revenue'!I6/G21 -> 41.273289 | H29: ='Geographic Revenue'!J6/H21 -> 39.789802 | I29: ='Geographic Revenue'!K6/I21 -> 40.656399 | J29: =J43/J21 -> 42.087866 | K29: =K43/K21 -> 43.280971 | L29: =L43/L21 -> 44.7085 | M29: =M43/M21 -> 46.16315 | N29: =N43/N21 -> 47.643806
B30: Y/Y Growth Domestic Rev per Store | C30: % | E30: =E29/D29-1 -> 0.11878232 | F30: =F29/E29-1 -> -0.099361313 | G30: =G29/F29-1 -> -0.053860442 | H30: =H29/G29-1 -> -0.035943015 | I30: =I29/H29-1 -> 0.021779376 | J30: =J29/I29-1 -> 0.035208899 | K30: =K29/J29-1 -> 0.028347945 | L30: =L29/K29-1 -> 0.032982844 | ... N30: =N29/M29-1 -> 0.032074408
B31: International Rev per Avg. Store (in millions USD) | C31: $ | D31: =SUM('Geographic Revenue'!F7:F9)/D27 -> 22.246154 | E31: =SUM('Geographic Revenue'!G7:G9)/E27 -> 24.091463 | F31: =SUM('Geographic Revenue'!H7:H9)/F27 -> 21.9 | G31: =SUM('Geographic Revenue'!I7:I9)/G27 -> 20.96875 | H31: =SUM('Geographic Revenue'!J7:J9)/H27 -> 20.5625 | I31: =SUM('Geographic Revenue'!K7:K9)/I27 -> 22.602649 | J31: =J51/J27 -> 24.534733 | K31: =K51/K27 -> 25.446087 | L31: =L51/L27 -> 26.435657 | M31: =M51/M27 -> 27.369849 | N31: =N51/N27 -> 28.343464
B32: Y/Y Growth International Rev per Store | C32: % | E32: =E31/D31-1 -> 0.0829496 | F32: =F31/E31-1 -> -0.090964313 | G32: =G31/F31-1 -> -0.042522831 | H32: =H31/G31-1 -> -0.019374069 | I32: =I31/H31-1 -> 0.099216973 | J32: =J31/I31-1 -> 0.085480427 | K32: =K31/J31-1 -> 0.037145455 | L32: =L31/K31-1 -> 0.038888889 | ... N32: =N31/M31-1 -> 0.035572519
B34: Revenue Build
B35: Domestic Revenue Build (in millions USD)
B36: Comparable Store Rev
B37: Prior Year Domestic Revenue | C37: $ | D37: ='Geographic Revenue'!E6 -> 40114 | E37: ='Geographic Revenue'!F6 -> 43293 | F37: ='Geographic Revenue'!G6 -> 47830 | G37: ='Geographic Revenue'!H6 -> 42794 | H37: ='Geographic Revenue'!I6 -> 40097 | I37: ='Geographic Revenue'!J6 -> 38238 | J37: ='Geographic Revenue'!K6 -> 38278 | K37: =J43 -> 38783.969 | L37: =K43 -> 39493.886 | M37: =L43 -> 40394.13 | N37: =M43 -> 41316.019
B38: Comp Store Base Rev | C38: $ | D38: =D37*(1+D7) -> 43804.488 | E38: =E37*(1+E7) -> 48055.23 | F38: =F37*(1+F7) -> 42903.51 | G38: =G37*(1+G7) -> 39755.626 | H38: =H37*(1+H7) -> 39094.575 | I38: =I37*(1+I7) -> 38390.952 | J38: =J37*(1+J7) -> 38660.78 | K38: =K37*(1+K7) -> 39365.728 | ... N38: =N37*(1+N7) -> 42142.34
B39: New Store Rev
B40: Stores Opened during year | C40: # | D40: ='Industry Metrics'!G19 -> 3 | E40: ='Industry Metrics'!F19 -> 13 | F40: ='Industry Metrics'!E19 -> 9 | G40: ='Industry Metrics'!D19 -> 15 | H40: ='Industry Metrics'!C19 -> 0 | I40: ='Industry Metrics'!B20 -> 0 | J40: =J18 -> 6 | K40: =K18 -> 6 | L40: =L18 -> 5 | M40: =M18 -> 5 | N40: =N18 -> 5
B41: Rev per New Store | C41: # | D41: ='Geographic Revenue'!F6/'Revenue Build - Top Down'!D21*50% -> 21.6465 | E41: ='Geographic Revenue'!G6/'Revenue Build - Top Down'!E21*50% -> 24.217722 | F41: ='Geographic Revenue'!H6/'Revenue Build - Top Down'!F21*50% -> 21.811417 | G41: ='Geographic Revenue'!I6/'Revenue Build - Top Down'!G21*50% -> 20.636644 | H41: ='Geographic Revenue'!J6/'Revenue Build - Top Down'!H21*50% -> 19.894901 | I41: ='Geographic Revenue'!K6/'Revenue Build - Top Down'!I21*50% -> 20.3282 | J41: ='Geographic Revenue'!K6/I21*(1+J7)*50% -> 20.531482 | K41: =J43/J21*(1+K7)*50% -> 21.359592 | L41: =K43/K21*(1+L7)*50% -> 22.073295 | M41: =L43/L21*(1+M7)*50% -> 22.801335 | N41: =M43/M21*(1+N7)*50% -> 23.543207
B42: Total new Store Rev | C42: # | D42: =D40*D41 -> 64.9395 | E42: =E40*E41 -> 314.83038 | F42: =F40*F41 -> 196.30275 | G42: =G40*G41 -> 309.54967 | H42: =H40*H41 -> 0 | I42: =I40*I41 -> 0 | J42: =J40*J41 -> 123.18889 | K42: =K40*K41 -> 128.15755 | ... N42: =N40*N41 -> 117.71603
...

Sheet Business Segment Revenue
A1: Sales
B2: JAN '17 | C2: JAN '18 | D2: JAN '19 | E2: JAN '20 | F2: JAN '21 | G2: JAN '22 | H2: JAN '23 | I2: JAN '24 | J2: JAN '25 | K2: JAN '26
B3: 364 Days | C3: 371 Days | D3: 364 Days | E3: 364 Days | F3: 364 Days | G3: 364 Days | H3: 364 Days | I3: 371 Days | J3: 364 Days | K3: 364 Days
A4: Total | B4: 39403 | C4: 42151 | D4: 42879 | E4: 43638 | F4: 47262 | G4: 51761 | H4: 46298 | I4: 43452 | J4: 41528 | K4: 41691
A5: Computing & Mobile Phones | B5: 17826 | C5: 19002.84 | D5: 19064 | E5: 19399 | F5: 21653 | G5: 22478 | H5: 19766 | I5: 18482 | J5: 18681 | K5: 19714
A6: Consumer Electronics | B6: 13302.37 | C6: 13874.94 | D6: 14062 | E6: 14292 | F6: 14211 | G6: 16203 | H6: 14094 | I6: 12969 | J6: 12065 | K6: 11460
A7: Appliances | B7: 3451.62 | C7: 4145.32 | D7: 4344 | E7: 4810 | F7: 5873 | G7: 7167 | H7: 6736 | I7: 5804 | J7: 4910 | K7: 4469
A8: Entertainment | B8: 2758.21 | C8: 3337.19 | D8: 3210 | E8: 2597 | F8: 3079 | G8: 3275 | H8: 3053 | I8: 3363 | J8: 2908 | K8: 3092
A9: Services | B9: 2033.25 | C9: 1720.93 | D9: 1967 | E9: 2325 | F9: 2252 | G9: 2380 | H9: 2332 | I9: 2530 | J9: 2631 | K9: 2656
A10: Other | B10: 31.55 | C10: 69.78 | D10: 232 | E10: 215 | F10: 194 | G10: 258 | H10: 317 | I10: 304 | J10: 333 | K10: 300
A11: All figures in millions of U.S. Dollar
A14: Percent of Total (%)
B15: JAN '17 | C15: JAN '18 | D15: JAN '19 | E15: JAN '20 | F15: JAN '21 | G15: JAN '22 | H15: JAN '23 | I15: JAN '24 | J15: JAN '25 | K15: JAN '26
A16: Total | B16: 100 | C16: 100 | D16: 99.999995 | E16: 100 | F16: 100 | G16: 99.999999 | H16: 99.999999 | I16: 99.999999 | J16: 100 | K16: 100
A17: Computing & Mobile Phones | B17: 45.240211 | C17: 45.082775 | D17: 44.459991 | E17: 44.454376 | F17: 45.814819 | G17: 43.426517 | H17: 42.692989 | I17: 42.53429 | J17: 44.984108 | K17: 47.285988
A18: Consumer Electronics | B18: 33.759792 | C18: 32.917229 | D18: 32.794605 | E18: 32.75127 | F18: 30.068556 | G18: 31.303492 | H18: 30.441919 | I18: 29.846727 | J18: 29.052687 | K18: 27.487946
A19: Appliances | B19: 8.759789 | C19: 9.834452 | D19: 10.130833 | E19: 11.022504 | F19: 12.426474 | G19: 13.846332 | H19: 14.549224 | I19: 13.357268 | J19: 11.823348 | K19: 10.719339
A20: Entertainment | B20: 7 | C20: 7.917226 | D20: 7.486182 | E20: 5.951235 | F20: 6.514748 | G20: 6.327157 | H20: 6.594238 | I20: 7.739574 | J20: 7.002504 | K20: 7.416469
A21: Services | B21: 5.16014 | C21: 4.082774 | D21: 4.587327 | E21: 5.327925 | F21: 4.764927 | G21: 4.598056 | H21: 5.036934 | I21: 5.822517 | J21: 6.335484 | K21: 6.370679
A22: Other | B22: 0.08007 | C22: 0.165548 | D22: 0.541057 | E22: 0.49269 | F22: 0.410478 | G22: 0.498445 | H22: 0.684695 | I22: 0.699623 | J22: 0.801869 | K22: 0.71958
A25: Growth (%)
B26: JAN '17 | C26: JAN '18 | D26: JAN '19 | E26: JAN '20 | F26: JAN '21 | G26: JAN '22 | H26: JAN '23 | I26: JAN '24 | J26: JAN '25 | K26: JAN '26
A27: Total | B27: -0.316232 | C27: 6.97409 | D27: 1.72712 | E27: 1.7701 | F27: 8.30469 | G27: 9.51928 | H27: -10.5543 | I27: -6.14713 | J27: -4.42787 | K27: 0.392506
A28: Computing & Mobile Phones | B28: -2.302628 | C28: 6.601817 | D28: 0.321847 | E28: 1.757239 | F28: 11.619156 | G28: 3.810096 | H28: -12.06513 | I28: -6.496003 | J28: 1.076723 | K28: 5.529683
A29: Consumer Electronics | B29: 5.429358 | C29: 4.304273 | D29: 1.348183 | E29: 1.635614 | F29: -0.566751 | G29: 14.01731 | H29: -13.016109 | I29: -7.98212 | J29: -6.970468 | K29: -5.014505
A30: Appliances | B30: 12.527752 | C30: 20.097801 | D30: 4.792879 | E30: 10.72744 | F30: 22.099792 | G30: 22.033033 | H30: -6.013674 | I30: -13.836104 | J30: -15.403171 | K30: -8.98167
A31: Entertainment | B31: -13.640511 | C31: 20.99115 | D31: -3.811289 | E31: -19.096573 | F31: 18.559877 | G31: 6.365703 | H31: -6.778626 | I31: 10.153947 | J31: -13.529587 | K31: 6.327373
A32: Services | B32: 1.255956 | C32: -15.360626 | D32: 14.29866 | E32: 18.200306 | F32: -3.139785 | G32: 5.683836 | H32: -2.016807 | I32: 8.490566 | J32: 3.992095 | K32: 0.950209
A33: Other | B33: -92.018318 | C33: 121.17275 | D33: 232.4735 | E33: -7.327586 | F33: -9.767442 | G33: 32.989689 | H33: 22.868217 | I33: -4.100946 | J33: 9.539474 | K33: -9.90991

Sheet Industry Metrics
A1: Industry
B2: JAN '26 | C2: JAN '25 | D2: JAN '24 | E2: JAN '23 | F2: JAN '22 | G2: JAN '21
A3: Same Store Sales - Total (%) | B3: 0.005 | C3: -0.023 | D3: -0.068 | E3: -0.099 | F3: 0.104 | G3: 0.097
A4: Same Store Sales - Domestic (%) | B4: 0.004 | C4: -0.025 | D4: -0.071 | E4: -0.103 | F4: 0.11 | G4: 0.092
A5: Same Store Sales - International (%) | B5: 0.023 | C5: -0.005 | D5: -0.032 | E5: -0.054 | F5: 0.033 | G5: 0.15
A6: Floor Area Sq. Ft. (000) | B6: 39529 | C6: 40142 | D6: 40394 | E6: 41009 | F6: 41310 | G6: 42108
A7: Domestic (000) | B7: 35954 | C7: 36539 | D7: 36771 | E7: 37388 | F7: 37705 | G7: 38186
A8: International (000) | B8: 3575 | C8: 3603 | D8: 3623 | E8: 3621 | F8: 3605 | G8: 3922
A9: Online Revenue as % of Domestic Revenue | B9: 0.39 | C9: 0.395 | D9: 0.38 | E9: 0.34 | F9: 0.36 | G9: 0.33
B11: JAN '26 | C11: JAN '25 | D11: JAN '24 | E11: JAN '23 | F11: JAN '22 | G11: JAN '21
A12: # Beginning Stores | B12: 1117 | C12: 1125 | D12: 1138 | E12: 1144 | F12: 1159 | G12: 1231
A13: Domestic | B13: 957 | C13: 965 | D13: 978 | E13: 984 | F13: 991 | G13: 1009
A14: International | B14: 160 | C14: 160 | D14: 160 | E14: 160 | F14: 168 | G14: 222
A15: # Ending Stores | B15: 1068 | C15: 1117 | D15: 1125 | E15: 1138 | F15: 1144 | G15: 1159
A16: Domestic | B16: 926 | C16: 957 | D16: 965 | E16: 978 | F16: 984 | G16: 991
A17: International | B17: 142 | C17: 160 | D17: 160 | E17: 160 | F17: 160 | G17: 168
A18: # Net Additions | B18: -49 | C18: -8 | D18: -13 | E18: -6 | F18: -15 | G18: -72
A19: # New Stores | D19: 15 | E19: 9 | F19: 13 | G19: 3
A20: # Opened | D20: 15 | E20: 9 | F20: 13 | G20: 3
A21: Domestic | D21: 14 | E21: 9 | F21: 13 | G21: 3
A22: International | D22: 1
A23: # Closed Stores | B23: 49 | C23: 8 | D23: 28 | E23: 15 | F23: 28 | G23: 75
A24: Domestic | B24: 31 | C24: 8 | D24: 27 | E24: 15 | F24: 20 | G24: 21
A25: International | B25: 18 | D25: 1 | F25: 8 | G25: 54
A26: # Owned Stores | B26: 26 | C26: 27 | D26: 26 | E26: 27 | F26: 27 | G26: 27
A27: # Leased Stores | B27: 1006 | C27: 1054 | D27: 1063 | E27: 1075 | F27: 1080 | G27: 1099
A28: # Ground Leased Stores | B28: 36 | C28: 36 | D28: 36 | E28: 36 | F28: 37 | G28: 33
A29: All figures without specified units (e.g. Revenue, Net Income, Capex and Sustaining Capex) in U.S. Dollar. All figures for Sales Volume, Production, Reserves and Resources in of respective weight units. All figures for Realized Price and Unit Costs are in $ per weight unit.
B31: JAN '26 | C31: JAN '25 | D31: JAN '24 | E31: JAN '23 | F31: JAN '22 | G31: JAN '21
A32: Retail Industry Metrics
A33: Merchandise Margin (%) | B33: 22.5 | C33: 22.6 | D33: 22.1 | E33: 21.4 | F33: 22.5 | G33: 22.4
A34: EBITDAR | B34: 3584 | C34: 3594 | D34: 3644 | E34: 3849 | F34: 4861 | G34: 4420
A35: # Stores (actual) | B35: 1068 | C35: 1117 | D35: 1125 | E35: 1138 | F35: 1144 | G35: 1159
A36: # Stores Closed During Period (actual) | D36: 28 | E36: 15 | F36: 28 | G36: 75
A37: # Stores Opened During Period (actual) | D37: 15 | E37: 9 | F37: 13 | G37: 3

Sheet Historical Balance Sheet
A1: Best Buy Co., Inc. (NYSE:BBY) > Financials > Balance Sheet
A3: In Millions of the reported currency, except per share items. | B3: Template: | C3: Standard | E3: Restatement: | F3: Latest Filings
B4: Period Type: | C4: Annual | E4: Order: | F4: Latest on Right
B5: Currency: | C5: Reported Currency | E5: Conversion: | F5: Historical
B6: Units: | C6: S&P Capital IQ (Default) | E6: Decimals: | F6: Capital IQ (Default)
B7: Source: | C7: Capital IQ & Proprietary Data
A10: Balance Sheet
A11: Balance Sheet as of: | B11: 44226 | C11: 44590 | D11: 44954 | E11: 45325 | F11: 45689 | G11: 46053
A12: Currency | B12: USD | C12: USD | D12: USD | E12: USD | F12: USD | G12: USD
A13: ASSETS
A14: Cash And Equivalents | B14: 5494 | C14: 2936 | D14: 1874 | E14: 1447 | F14: 1578 | G14: 1738
A15: Short Term Investments | B15: 65 | C15: - | D15: 178 | E15: - | F15: 190 | G15: 153
A16: Total Cash & ST Investments | B16: 5559 | C16: 2936 | D16: 2052 | E16: 1447 | F16: 1768 | G16: 1891
A18: Accounts Receivable | B18: 1061 | C18: 1042 | D18: 1141 | E18: 939 | F18: 1044 | G18: 1043
A19: Total Receivables | B19: 1061 | C19: 1042 | D19: 1141 | E19: 939 | F19: 1044 | G19: 1043
A21: Inventory | B21: 5612 | C21: 5965 | D21: 5140 | E21: 4958 | F21: 5085 | G21: 5230
A22: Restricted Cash | B22: 131 | C22: 269 | D22: 379 | E22: - | F22: 290 | G22: 285
A23: Other Current Assets | B23: 177 | C23: 327 | D23: 90 | E23: 553 | F23: 37 | G23: 55
A24: Total Current Assets | B24: 12540 | C24: 10539 | D24: 8802 | E24: 7897 | F24: 8224 | G24: 8504
A26: Gross Property, Plant & Equipment | B26: 11868 | C26: 10995 | D26: 9722 | E26: 9834 | F26: 9885 | G26: 9810
A27: Accumulated Depreciation | B27: -6996 | C27: -6091 | D27: -4624 | E27: -4816 | F27: -4930 | G27: -4955
A28: Net Property, Plant & Equipment | B28: 4872 | C28: 4904 | D28: 5098 | E28: 5018 | F28: 4955 | G28: 4855
A30: Long-term Investments | B30: 91 | C30: 50 | D30: - | E30: - | F30: - | G30: -
A31: Goodwill | B31: 986 | C31: 1384 | D31: 1383 | E31: 1383 | F31: 908 | G31: 790
A32: Other Intangibles | B32: 301 | C32: 275 | D32: 189 | E32: 128 | F32: 91 | G32: 5
A33: Deferred Tax Assets, LT | B33: 17 | C33: 25 | D33: 4 | E33: 167 | F33: 223 | G33: 164
A34: Other Long-Term Assets | B34: 260 | C34: 327 | D34: 327 | E34: 374 | F34: 381 | G34: 352
A35: Total Assets | B35: 19067 | C35: 17504 | D35: 15803 | E35: 14967 | F35: 14782 | G35: 14670
A37: LIABILITIES
A38: Accounts Payable | B38: 6979 | C38: 6803 | D38: 5687 | E38: 4637 | F38: 4980 | G38: 4745
A39: Accrued Exp. | B39: 1626 | C39: 1708 | D39: 1182 | E39: 1335 | F39: 1155 | G39: 1108
A40: Short-term Borrowings | B40: 110 | C40: - | D40: - | E40: - | F40: - | G40: -
A41: Curr. Port. of Leases | B41: 707 | C41: 661 | D41: 654 | E41: 631 | F41: 627 | G41: 634
A42: Unearned Revenue, Current | B42: 1099 | C42: 1502 | D42: 1456 | E42: 1306 | F42: 1254 | G42: 1192
A43: Other Current Liabilities | B43: - | C43: - | D43: - | E43: - | F43: - | G43: -
A44: Total Current Liabilities | B44: 10521 | C44: 10674 | D44: 8979 | E44: 7909 | F44: 8016 | G44: 7679
A46: Long-Term Debt | B46: 1229 | C46: 1189 | D46: 1134 | E46: 1142 | F46: 1143 | G46: 1145
A47: Long-Term Leases | B47: 2036 | C47: 2088 | D47: 2190 | E47: 2220 | F47: 2297 | G47: 2355
A48: Unearned Revenue, Non-Current | B48: - | C48: 6 | D48: 265 | E48: 245 | F48: 229 | G48: 205
A49: Def. Tax Liability, Non-Curr. | B49: - | C49: 22 | D49: 51 | E49: - | F49: - | G49: -
...

Sheet Historical Income Statement
A1: Best Buy Co., Inc. (NYSE:BBY) > Financials > Income Statement
A3: In Millions of the reported currency, except per share items. | B3: Template: | C3: Standard | E3: Restatement: | F3: Latest Filings
B4: Period Type: | C4: Annual | E4: Order: | F4: Latest on Right
B5: Currency: | C5: Reported Currency | E5: Conversion: | F5: Historical
B6: Units: | C6: S&P Capital IQ (Default) | E6: Decimals: | F6: Capital IQ (Default)
B7: Source: | C7: Capital IQ & Proprietary Data
A10: Income Statement
A11: For the Fiscal Period Ending | B11: Reclassified 12 months Jan-30-2021 | C11: Reclassified 12 months Jan-29-2022 | D11: 12 months Jan-28-2023 | E11: Reclassified 12 months Feb-03-2024 | F11: Reclassified 12 months Feb-01-2025 | G11: 12 months Jan-31-2026
A12: Currency | B12: USD | D12: USD | E12: USD | F12: USD | G12: USD
A14: Revenue | B14: 47262 | C14: 51761 | D14: 46298 | E14: 43452 | F14: 41528 | G14: 41691
A15: Other Revenue | B15: - | C15: - | D15: - | E15: - | F15: - | G15: -
A16: Total Revenue | B16: 47262 | C16: 51761 | D16: 46298 | E16: 43452 | F16: 41528 | G16: 41691
A18: Cost Of Goods Sold | B18: 36666 | C18: 40127 | D18: 36386 | E18: 33849 | F18: 32143 | G18: 32318
A19: Gross Profit | B19: 10596 | C19: 11634 | D19: 9912 | E19: 9603 | F19: 9385 | G19: 9373
A21: Selling General & Admin Exp. | B21: 7848 | C21: 8542 | D21: 7884 | E21: 7813 | F21: 7628 | G21: 7588
A22: R & D Exp. | B22: - | C22: - | D22: - | E22: - | F22: - | G22: -
A23: Depreciation & Amort. | B23: - | C23: - | D23: - | E23: - | F23: - | G23: -
A24: Amort. of Goodwill and Intangibles | B24: 80 | C24: 82 | D24: 86 | E24: 61 | F24: 21 | G24: 14
A25: Other Operating Expense/(Income) | B25: - | C25: - | D25: - | E25: - | F25: - | G25: -
A27: Other Operating Exp., Total | B27: 7928 | C27: 8624 | D27: 7970 | E27: 7874 | F27: 7649 | G27: 7602
A29: Operating Income | B29: 2668 | C29: 3010 | D29: 1942 | E29: 1729 | F29: 1736 | G29: 1771
A31: Interest Expense | B31: -52 | C31: -25 | D31: -35 | E31: -52 | F31: -51 | G31: -47
A32: Interest and Invest. Income | B32: 38 | C32: 10 | D32: 28 | E32: 78 | F32: 84 | G32: 68
A33: Net Interest Exp. | B33: -14 | C33: -15 | D33: -7 | E33: 26 | F33: 33 | G33: 21
A35: Income/(Loss) from Affiliates | B35: - | C35: 4 | D35: 1 | E35: 1 | F35: 4 | G35: 2
A36: Other Non-Operating Inc. (Exp.) | B36: - | C36: - | D36: - | E36: - | F36: - | G36: -
A37: EBT Excl. Unusual Items | B37: 2654 | C37: 2999 | D37: 1936 | E37: 1756 | F37: 1773 | G37: 1794
A39: Restructuring Charges | B39: -277 | C39: 40 | D39: -147 | E39: -153 | F39: 3 | G39: -190
A40: Merger & Related Restruct. Charges | B40: - | C40: -11 | D40: - | E40: - | F40: - | G40: -
A41: Impairment of Goodwill | B41: - | C41: - | D41: - | E41: - | F41: -475 | G41: -118
A42: Gain (Loss) On Sale Of Assets | B42: - | C42: - | D42: - | E42: 21 | F42: - | G42: -6
A43: Asset Writedown | B43: - | C43: - | D43: - | E43: -2 | F43: -2 | G43: -74
A44: Other Unusual Items | B44: - | C44: - | D44: - | E44: - | F44: - | G44: -
A45: EBT Incl. Unusual Items | B45: 2377 | C45: 3028 | D45: 1789 | E45: 1622 | F45: 1299 | G45: 1406
A47: Income Tax Expense | B47: 579 | C47: 574 | D47: 370 | E47: 381 | F47: 372 | G47: 337
A48: Earnings from Cont. Ops. | B48: 1798 | C48: 2454 | D48: 1419 | E48: 1241 | F48: 927 | G48: 1069
A50: Earnings of Discontinued Ops. | B50: - | C50: - | D50: - | E50: - | F50: - | G50: -
A51: Extraord. Item & Account. Change | B51: - | C51: - | D51: - | E51: - | F51: - | G51: -
A52: Net Income to Company | B52: 1798 | C52: 2454 | D52: 1419 | E52: 1241 | F52: 927 | G52: 1069
A54: Minority Int. in Earnings | B54: - | C54: - | D54: - | E54: - | F54: - | G54: -
...

Sheet Historical Cash Flow
A1: Best Buy Co., Inc. (NYSE:BBY) > Financials > Cash Flow
A3: In Millions of the reported currency, except per share items. | B3: Template: | C3: Standard | E3: Restatement: | F3: Latest Filings
B4: Period Type: | C4: Annual | E4: Order: | F4: Latest on Right
B5: Currency: | C5: Reported Currency | E5: Conversion: | F5: Historical
B6: Units: | C6: S&P Capital IQ (Default) | E6: Decimals: | F6: Capital IQ (Default)
B7: Source: | C7: Capital IQ & Proprietary Data
A10: Cash Flow
A11: For the Fiscal Period Ending | B11: 12 months Jan-30-2021 | C11: 12 months Jan-29-2022 | D11: 12 months Jan-28-2023 | E11: 12 months Feb-03-2024 | F11: 12 months Feb-01-2025 | G11: 12 months Jan-31-2026
A12: Currency | B12: USD | C12: USD | D12: USD | E12: USD | F12: USD | G12: USD
A14: Net Income | B14: 1798 | C14: 2454 | D14: 1419 | E14: 1241 | F14: 927 | G14: 1069
A15: Depreciation & Amort. | B15: 759 | C15: 787 | D15: 832 | E15: 862 | F15: 845 | G15: 817
A16: Amort. of Goodwill and Intangibles | B16: 80 | C16: 82 | D16: 86 | E16: 61 | F16: 21 | G16: 14
A17: Depreciation & Amort., Total | B17: 839 | C17: 869 | D17: 918 | E17: 923 | F17: 866 | G17: 831
A19: (Gain) Loss From Sale Of Assets | B19: - | C19: - | D19: - | E19: -21 | F19: - | G19: 6
A20: Asset Writedown & Restructuring Costs | B20: 254 | C20: -34 | D20: 147 | E20: 155 | F20: 474 | G20: 382
A21: Stock-Based Compensation | B21: 135 | C21: 141 | D21: 138 | E21: 145 | F21: 139 | G21: 139
A22: Other Operating Activities | B22: -33 | C22: 25 | D22: 63 | E22: -190 | F22: -49 | G22: 74
A23: Change in Acc. Receivable | B23: 73 | C23: 17 | D23: -103 | E23: 204 | F23: -111 | G23: -3
A24: Change In Inventories | B24: -435 | C24: -328 | D24: 809 | E24: 178 | F24: -155 | G24: -126
A25: Change in Acc. Payable | B25: 1676 | C25: -201 | D25: -1099 | E25: -1025 | F25: 358 | G25: -238
A26: Change in Inc. Taxes | B26: 173 | C26: -156 | D26: 36 | E26: 52 | F26: -212 | G26: -7
A27: Change in Other Net Operating Assets | B27: 447 | C27: 465 | D27: -504 | E27: -192 | F27: -139 | G27: -165
A28: Cash from Ops. | B28: 4927 | C28: 3252 | D28: 1824 | E28: 1470 | F28: 2098 | G28: 1962
A30: Capital Expenditure | B30: -713 | C30: -737 | D30: -930 | E30: -795 | F30: -706 | G30: -704
A31: Cash Acquisitions | B31: - | C31: -468 | D31: - | E31: - | F31: - | G31: -
A32: Divestitures | B32: - | C32: - | D32: - | E32: 14 | F32: - | G32: -27
A33: Invest. in Marketable & Equity Securt. | B33: -74 | C33: -167 | D33: -39 | E33: -2 | F33: -6 | G33: -1
A34: Net (Inc.) Dec. in Loans Originated/Sold | B34: - | C34: - | D34: - | E34: - | F34: - | G34: -
A35: Other Investing Activities | B35: -1 | C35: - | D35: 7 | E35: 2 | F35: 8 | G35: 2
A36: Cash from Investing | B36: -788 | C36: -1372 | D36: -962 | E36: -781 | F36: -704 | G36: -730
A38: Short Term Debt Issued | B38: - | C38: - | D38: - | E38: - | F38: - | G38: -
A39: Long-Term Debt Issued | B39: 1892 | C39: - | D39: - | E39: - | F39: - | G39: -
A40: Total Debt Issued | B40: 1892 | C40: - | D40: - | E40: - | F40: - | G40: -
A41: Short Term Debt Repaid | B41: - | C41: - | D41: - | E41: - | F41: - | G41: -
A42: Long-Term Debt Repaid | B42: -1916 | C42: -133 | D42: -19 | E42: -19 | F42: -17 | G42: -13
A43: Total Debt Repaid | B43: -1916 | C43: -133 | D43: -19 | E43: -19 | F43: -17 | G43: -13
A45: Issuance of Common Stock | B45: 28 | C45: 29 | D45: 16 | E45: 19 | F45: 17 | G45: 5
A46: Repurchase of Common Stock | B46: -312 | C46: -3502 | D46: -1014 | E46: -340 | F46: -500 | G46: -273
A48: Common Dividends Paid | B48: -568 | C48: -688 | D48: -789 | E48: -801 | F48: -807 | G48: -801
A49: Total Dividends Paid | B49: -568 | C49: -688 | D49: -789 | E49: -801 | F49: -807 | G49: -801
...

Sheet Historical Capitalization
A1: Best Buy Co., Inc. (NYSE:BBY) > Financials > Historical Capitalization
A3: In Millions of the trading currency, except per share items. | B3: Frequency: | C3: Quarterly | E3: Order: | F3: Latest on Right
B4: Currency: | C4: Trading Currency | E4: Conversion: | F4: Historical
B5: Units: | C5: S&P Capital IQ (Default) | E5: Decimals: | F5: Capital IQ (Default)
B6: Dilution: | C6: Basic
A9: Historical Capitalization
A10: Balance Sheet as of: | B10: 45598 | C10: 45689 | D10: 45780 | E10: 45871 | F10: 45962 | G10: 46053
A11: Pricing as of* | B11: 45632 | C11: 45735 | D11: 45814 | E11: 45905 | F11: 45996 | G11: 46099
A12: Currency | B12: USD | C12: USD | D12: USD | E12: USD | F12: USD | G12: USD
A13: Capitalization Detail
A14: Share Price | B14: 88.17 | C14: 73.79 | D14: 73.02 | E14: 76.17 | F14: 74.17 | G14: 62.87
A15: Shares Out. | B15: 213.7956 | C15: 211.36966 | D15: 211.34669 | E15: 210.10127 | F15: 209.5351 | G15: 209.11258
A17: Market Capitalization | B17: 18850.358 | C17: 15596.967 | D17: 15432.536 | E17: 16003.413 | F17: 15541.219 | G17: 13146.908
A18: - Cash & Short Term Investments | B18: 832 | C18: 1768 | D18: 1339 | E18: 1619 | F18: 1085 | G18: 1891
A19: + Total Debt | B19: 4081 | C19: 4067 | D19: 4059 | E19: 4076 | F19: 4100 | G19: 4134
A20: + Pref. Equity | B20: - | C20: - | D20: - | E20: - | F20: - | G20: -
A21: + Total Minority Interest | B21: - | C21: - | D21: - | E21: - | F21: - | G21: -
