Workbook

Sheet Overview
A4: Valuation on : Deckers Outdoor (DECK): Initiating Coverage - BUY recommendation
A5: Presented by: Felipe Schmidt, Faisal Hidayah, Shaira Katuwal, Vaishnavi Ramesh
A7: This model is a comprehensive valuation of Deckers Outdoor Corporation, focusing on its financial health, growth prospects, and intrinsic value. We'll present our investment recommendation based on a detailed DCF analysis, highlighting key assumptions and sensitivity insights.

Sheet Balance Sheet
D1: DECKERS OUTDOOR CORPORATION AND SUBSIDIARIES
D2: CONSOLIDATED BALANCE SHEETS
D3: (amounts in thousands, except par value, As of March 31)
B4: Historical | D4: Historical | J4: Projected
B5: 2018 | C5: 2019 | D5: 2020 | E5: 2021 | F5: 2022 | G5: 2023 | H5: 2024 | I5: 2025 | J5: 2026 | K5: 2027 | L5: 2028 | M5: 2029 | N5: 2030 | O5: 2031 | P5: 2032 | Q5: 2033 | R5: 2034 | S5: 2035
A6: ASSETS
A7: Cash and cash equivalents | B7: 429970 | C7: 589692 | D7: 649436 | E7: 1089361 | F7: 843527 | G7: 981795 | H7: 1502051 | I7: 1889188 | J7: ='Balanced Proforma'!C21 -> 2131469.5 | K7: =Proforma!D18 -> 2335668.7 | L7: =Proforma!E18 -> 2768891.9 | M7: =Proforma!F18 -> 3282469.9 | N7: =Proforma!G18 -> 3891307 | O7: =Proforma!H18 -> 4613072.1 | P7: =Proforma!I18 -> 5468711.3 | Q7: =Proforma!J18 -> 6483055.6 | R7: =Proforma!K18 -> 7685541.9 | S7: =Proforma!L18 -> 9111067.1
A8: Trade accounts receivable, net of allowances | B8: 143704 | C8: 178602 | D8: 185596 | E8: 215718 | F8: 302688 | G8: 301511 | H8: 296565 | I8: 332872 | J8: =Proforma!C19 -> 971564.44 | K8: =Proforma!D19 -> 1151771.6 | L8: =Proforma!E19 -> 1365403.8 | M8: =Proforma!F19 -> 1618660.8 | N8: =Proforma!G19 -> 1918892.3 | O8: =Proforma!H19 -> 2274811.2 | P8: =Proforma!I19 -> 2696746.4 | Q8: =Proforma!J19 -> 3196942.7 | ... S8: =Proforma!L19 -> 4492875.2
A9: Inventories | B9: 299602 | C9: 278842 | D9: 311620 | E9: 278242 | F9: 506796 | G9: 532852 | H9: 474311 | I9: 495226 | J9: =Proforma!C20 -> 603246.02 | K9: =Proforma!D20 -> 715136.94 | L9: =Proforma!E20 -> 847781.55 | M9: =Proforma!F20 -> 1005029.3 | N9: =Proforma!G20 -> 1191443.5 | O9: =Proforma!H20 -> 1412434.1 | P9: =Proforma!I20 -> 1674414.4 | Q9: =Proforma!J20 -> 1984987.2 | ... S9: =Proforma!L20 -> 2789633.9
A10: Prepaid expenses | B10: 17639 | C10: 19901 | D10: 17760 | E10: 16924 | F10: 25610 | G10: 33788 | H10: 34284 | I10: 39294 | J10: =Proforma!C21 -> 142160.56 | K10: =Proforma!D21 -> 168528.7 | L10: =Proforma!E21 -> 199787.64 | M10: =Proforma!F21 -> 236844.53 | N10: =Proforma!G21 -> 280774.79 | O10: =Proforma!H21 -> 332853.3 | P10: =Proforma!I21 -> 394591.4 | Q10: =Proforma!J21 -> 467780.77 | ... S10: =Proforma!L21 -> 657403.28
A11: Other current assets | B11: 17599 | C11: 26028 | D11: 21548 | E11: 44244 | F11: 55264 | G11: 55523 | H11: 92713 | I11: 67282
A12: Income tax receivable | B12: 2176 | C12: 2340 | D12: 8151 | E12: 6310 | F12: 18243 | G12: 4784 | H12: 43559 | I12: 36613 | J12: 0 | K12: 0 | L12: 0 | M12: 0 | N12: 0 | O12: 0 | P12: 0 | Q12: 0 | R12: 0 | S12: 0
A13: Total current assets | B13: =SUM(B7:B12) -> 910690 | C13: =SUM(C7:C12) -> 1095405 | D13: =SUM(D7:D12) -> 1194111 | E13: =SUM(E7:E12) -> 1650799 | F13: =SUM(F7:F12) -> 1752128 | G13: =SUM(G7:G12) -> 1910253 | H13: =SUM(H7:H12) -> 2443483 | I13: =SUM(I7:I12) -> 2860475 | J13: =Proforma!C23 -> 3687199.1 | K13: =Proforma!D23 -> 4371106 | L13: =Proforma!E23 -> 5181864.9 | M13: =Proforma!F23 -> 6143004.5 | N13: =Proforma!G23 -> 7282417.7 | O13: =Proforma!H23 -> 8633170.8 | P13: =Proforma!I23 -> 10234464 | Q13: =Proforma!J23 -> 12132766 | ... S13: =Proforma!L23 -> 17050979
A14: PPE gross | D14: =D15+D16 -> 444976 | E14: =E15+E16 -> 473115 | F14: =F15+F16 -> 505020 | G14: =G15+G16 -> 584187 | H14: =H15+H16 -> 651260 | I14: =I15+I16 -> 728563 | J14: =Proforma!C24 -> 998730.72 | K14: =Proforma!D24 -> 1183976.7 | L14: =Proforma!E24 -> 1403582.4 | M14: =Proforma!F24 -> 1663920.8 | N14: =Proforma!G24 -> 1972547.2 | O14: =Proforma!H24 -> 2338418.1 | P14: =Proforma!I24 -> 2772151.1 | Q14: =Proforma!J24 -> 3286333.7 | ... S14: =Proforma!L24 -> 4618502.2
A15: Depreciation | D15: 235939 | E15: 266905 | F15: 282571 | G15: 317508 | H15: 349138 | I15: 402964 | J15: =Proforma!C25 -> 547069.98 | K15: =Proforma!D25 -> 648541.29 | L15: =Proforma!E25 -> 768833.65 | M15: =Proforma!F25 -> 911438 | N15: =Proforma!G25 -> 1080492.8 | O15: =Proforma!H25 -> 1280904.1 | P15: =Proforma!I25 -> 1518488.1 | Q15: =Proforma!J25 -> 1800139.4 | ... S15: =Proforma!L25 -> 2529855
A16: PPE net | D16: 209037 | E16: 206210 | F16: 222449 | G16: 266679 | H16: 302122 | I16: 325599 | J16: Assumption: Already calculated in PPE Gross. Derived from PPE gross minus accumulated depreciation.
A17: Operating lease assets | B17: 0 | C17: 0 | D17: 243522 | E17: 186991 | F17: 182459 | G17: 213302 | H17: 225669 | I17: 237352 | J17: =Proforma!C27 -> 214882.5 | K17: =Proforma!D27 -> 214882.5 | L17: =Proforma!E27 -> 214882.5 | M17: =Proforma!F27 -> 214882.5 | N17: =Proforma!G27 -> 214882.5 | O17: =Proforma!H27 -> 214882.5 | P17: =Proforma!I27 -> 214882.5 | Q17: =Proforma!J27 -> 214882.5 | ... S17: =Proforma!L27 -> 214882.5
A18: Goodwill | B18: 13990 | C18: 13990 | D18: 13990 | E18: 13990 | F18: 13990 | G18: 13990 | H18: 13990 | I18: 13990 | J18: =Proforma!C28 -> 13990 | K18: =Proforma!D28 -> 13990 | L18: =Proforma!E28 -> 13990 | M18: =Proforma!F28 -> 13990 | N18: =Proforma!G28 -> 13990 | O18: =Proforma!H28 -> 13990 | P18: =Proforma!I28 -> 13990 | Q18: =Proforma!J28 -> 13990 | ... S18: =Proforma!L28 -> 13990
A19: Other intangible assets, net of accumulated amortization | B19: 57850 | C19: 51494 | D19: 48016 | E19: 41945 | F19: 39688 | G19: 37457 | H19: 27083 | I19: 15699 | J19: =Proforma!C29 -> 34981.333 | K19: =Proforma!D29 -> 34981.333 | L19: =Proforma!E29 -> 34981.333 | M19: =Proforma!F29 -> 34981.333 | N19: =Proforma!G29 -> 34981.333 | O19: =Proforma!H29 -> 34981.333 | P19: =Proforma!I29 -> 34981.333 | Q19: =Proforma!J29 -> 34981.333 | ... S19: =Proforma!L29 -> 34981.333
A20: Deferred tax assets, net | B20: 38381 | C20: 30870 | D20: 28233 | E20: 37194 | F20: 64217 | G20: 72592 | H20: 72584 | I20: 77591 | J20: Assumption: Non-operating; timing difference in taxes. Often excluded in operating asset base for ROIC/valuation.
A21: Other non-current assets | B21: 23306 | C21: 21651 | D21: 28209 | E21: 30576 | F21: 57319 | G21: 41930 | H21: 50648 | I21: 39546 | J21: =Proforma!C31 -> 73619.803 | K21: 87274.908 | L21: 103462.78 | M21: 122653.2 | N21: 145403.09 | O21: 172372.67 | P21: 204344.59 | Q21: 242246.71 | R21: 287178.98 | S21: 340445.34
A22: Total Non-current Assets | D22: =SUM(D14:D21) -> 1251922 | E22: =SUM(E14:E21) -> 1256926 | F22: =SUM(F14:F21) -> 1367713 | G22: =SUM(G14:G21) -> 1547645 | H22: =SUM(H14:H21) -> 1692494 | I22: =SUM(I14:I21) -> 1841304 | J22: =Proforma!C32 -> 789134.38 | K22: =Proforma!D32 -> 886564.16 | L22: =Proforma!E32 -> 1002065.3 | M22: =Proforma!F32 -> 1138989.9 | N22: =Proforma!G32 -> 1301311.3 | O22: =Proforma!H32 -> 1493740.4 | P22: =Proforma!I32 -> 1721861.5 | Q22: =Proforma!J32 -> 1992294.8 | ... S22: =Proforma!L32 -> 2692946.4
A23: Total assets | B23: =SUM(B14:B21)+B13 -> 1044217 | C23: =SUM(C14:C21)+C13 -> 1213410 | D23: =SUM(D16:D21)+D13 -> 1765118 | E23: =SUM(E16:E21)+E13 -> 2167705 | F23: =SUM(F16:F21)+F13 -> 2332250 | G23: =SUM(G16:G21)+G13 -> 2556203 | H23: =SUM(H16:H21)+H13 -> 3135579 | I23: =SUM(I16:I21)+I13 -> 3570252 | J23: =Proforma!C33 -> 4476333.5 | K23: =Proforma!D33 -> 5257670.1 | L23: =Proforma!E33 -> 6183930.2 | M23: =Proforma!F33 -> 7281994.4 | N23: =Proforma!G33 -> 8583729 | O23: =Proforma!H33 -> 10126911 | P23: =Proforma!I33 -> 11956325 | Q23: =Proforma!J33 -> 14125061 | ... S23: =Proforma!L33 -> 19743926
A24: LIABILITIES AND STOCKHOLDERS' EQUITY
A25: Short-term borrowings | B25: 578 | C25: 603 | D25: 638 | E25: 0 | F25: 0 | G25: 0 | H25: 0 | I25: 0 | J25: 0 | K25: 0 | L25: 0 | M25: 0 | N25: 0 | O25: 0 | P25: 0 | Q25: 0 | R25: 0 | S25: 0
A26: Trade accounts payable | B26: 93939 | C26: 124974 | D26: 147892 | E26: 231632 | F26: 327487 | G26: 265605 | H26: 378503 | I26: 417955 | J26: =Proforma!C35 -> 504182.66 | K26: =Proforma!D35 -> 597699.17 | L26: =Proforma!E35 -> 708561.26 | M26: =Proforma!F35 -> 839986.2 | N26: =Proforma!G35 -> 995788.03 | O26: =Proforma!H35 -> 1180488.2 | P26: =Proforma!I35 -> 1399446.8 | Q26: =Proforma!J35 -> 1659018.2 | ... S26: =Proforma!L35 -> 2331528.1
A27: Accrued payroll | B27: 55695 | C27: 54462 | D27: 42309 | E27: 79152 | F27: 67553 | G27: 63781 | H27: 123653 | I27: 125417 | J27: =Proforma!C36 -> 143389.27 | K27: =Proforma!D36 -> 169985.31 | L27: =Proforma!E36 -> 201514.43 | M27: =Proforma!F36 -> 238891.61 | N27: =Proforma!G36 -> 283201.57 | O27: =Proforma!H36 -> 335730.19 | P27: =Proforma!I36 -> 398001.9 | Q27: =Proforma!J36 -> 471823.86 | ... S27: =Proforma!L36 -> 663085.3
A28: Operating lease liabilities | B28: 0 | C28: 0 | D28: 49091 | E28: 46768 | F28: 50098 | G28: 50765 | H28: 53581 | I28: 54453 | J28: =Proforma!C37 -> 93291.11 | K28: =Proforma!D37 -> 110594.88 | L28: =Proforma!E37 -> 131108.17 | M28: =Proforma!F37 -> 155426.3 | N28: =Proforma!G37 -> 184254.99 | O28: =Proforma!H37 -> 218430.87 | P28: =Proforma!I37 -> 258945.73 | Q28: =Proforma!J37 -> 306975.35 | ... S28: =Proforma!L37 -> 431412.78
A29: Other accrued expenses | B29: 24446 | C29: 47963 | D29: 46281 | E29: 68995 | F29: 81400 | G29: 86753 | H29: 106785 | I29: 142120 | J29: =Proforma!C38 -> 150729.21 | K29: =Proforma!D38 -> 178686.68 | L29: =Proforma!E38 -> 211829.74 | M29: =Proforma!F38 -> 251120.22 | N29: =Proforma!G38 -> 297698.35 | O29: =Proforma!H38 -> 352915.86 | P29: =Proforma!I38 -> 418375.2 | Q29: =Proforma!J38 -> 495976.02 | ... S29: =Proforma!L38 -> 697027.93
A30: Income tax payable | B30: 11006 | C30: 19283 | D30: 11104 | E30: 36920 | F30: 12426 | G30: 17322 | H30: 52338 | I30: 23299 | J30: 0 | K30: 0 | L30: 0 | M30: 0 | N30: 0 | O30: 0 | P30: 0 | Q30: 0 | R30: 0 | S30: 0
A31: Value added tax payable | B31: 3502 | C31: 3239 | D31: 3631 | E31: 4901 | F31: 2720 | G31: 13154 | H31: 5133 | I31: 6697 | J31: 0 | K31: 0 | L31: 0 | M31: 0 | N31: 0 | O31: 0 | P31: 0 | Q31: 0 | R31: 0 | S31: 0
A32: Total current liabilities | B32: =SUM(B25:B31) -> 189166 | C32: =SUM(C25:C31) -> 250524 | D32: =SUM(D25:D31) -> 300946 | E32: =SUM(E25:E31) -> 468368 | F32: =SUM(F25:F31) -> 541684 | G32: =SUM(G25:G31) -> 497380 | H32: =SUM(H25:H31) -> 719993 | I32: =SUM(I25:I31) -> 769941 | J32: =Proforma!C41 -> 891592.25 | K32: =Proforma!D41 -> 1056966 | L32: =Proforma!E41 -> 1253013.6 | M32: =Proforma!F41 -> 1485424.3 | N32: =Proforma!G41 -> 1760942.9 | O32: =Proforma!H41 -> 2087565.1 | P32: =Proforma!I41 -> 2474769.7 | Q32: =Proforma!J41 -> 2933793.4 | ... S32: =Proforma!L41 -> 4123054.1
A33: Long-term operating lease liabilities | B33: 0 | C33: 0 | D33: 215724 | E33: 176274 | F33: 171972 | G33: 195723 | H33: 213298 | I33: 222522 | J33: =Proforma!C42 -> 204296 | K33: =Proforma!D42 -> 204296 | L33: =Proforma!E42 -> 204296 | M33: =Proforma!F42 -> 204296 | N33: =Proforma!G42 -> 204296 | O33: =Proforma!H42 -> 204296 | P33: =Proforma!I42 -> 204296 | Q33: =Proforma!J42 -> 204296 | ... S33: =Proforma!L42 -> 204296
A34: Mortgage Payable | B34: 31504 | C34: 30901 | D34: 30263 | E34: 0 | F34: 0 | G34: 0 | H34: 0 | I34: 0 | J34: 0 | K34: 0 | L34: 0 | M34: 0 | N34: 0 | O34: 0 | P34: 0 | Q34: 0 | R34: 0 | S34: 0
A35: Income tax liability | B35: 64735 | C35: 60616 | D35: 63547 | E35: 60094 | F35: 54259 | G35: 62032 | H35: 52470 | I35: 13587 | J35: Assumption: Non-operating; timing difference.
A36: Deferred rent obligations | B36: 22499 | C36: 21107 | D36: 0 | E36: 0 | F36: 0 | G36: 0 | H36: 0 | I36: 0 | J36: Assumption: Obsolete under ASC 842 unless separate.
A37: Other long-term liabilities | B37: 15696 | C37: 18928 | D37: 14518 | E37: 18744 | F37: 25510 | G37: 35335 | H37: 42350 | I37: 51189 | J37: =Proforma!C45 -> 51785.507 | K37: =Proforma!D45 -> 61390.756 | L37: =Proforma!E45 -> 72777.6 | M37: =Proforma!F45 -> 86276.492 | N37: =Proforma!G45 -> 102279.18 | O37: =Proforma!H45 -> 121250.06 | P37: =Proforma!I45 -> 143739.7 | Q37: =Proforma!J45 -> 170400.74 | ... S37: =Proforma!L45 -> 239475.44
A38: Total liabilities | B38: =SUM(B33:B37) +B32 -> 323600 | C38: =SUM(C33:C37) +C32 -> 382076 | D38: =SUM(D33:D37) +D32 -> 624998 | E38: =SUM(E33:E37) +E32 -> 723480 | F38: =SUM(F33:F37) +F32 -> 793425 | G38: =SUM(G33:G37) +G32 -> 790470 | H38: =SUM(H33:H37) +H32 -> 1028111 | I38: =SUM(I33:I37)+I32 -> 1057239 | J38: =Proforma!C46 -> 256081.51 | K38: =Proforma!D46 -> 265686.76 | L38: =Proforma!E46 -> 277073.6 | M38: =Proforma!F46 -> 290572.49 | N38: =Proforma!G46 -> 306575.18 | O38: =Proforma!H46 -> 325546.06 | P38: =Proforma!I46 -> 348035.7 | Q38: =Proforma!J46 -> 374696.74 | ... S38: =Proforma!L46 -> 443771.44
A39: Common stock ($0.01 par value; 125,000 shares authorized) | B39: 304 | C39: 291 | D39: 280 | E39: 279 | F39: 270 | G39: 262 | H39: 1536 | I39: 1502 | J39: =Proforma!C47 -> 32455.309 | K39: =Proforma!D47 -> -391877.23 | L39: =Proforma!E47 -> -894915.57 | M39: =Proforma!F47 -> -894915.57 | N39: =Proforma!G47 -> -894915.57 | O39: =Proforma!H47 -> -894915.57 | P39: =Proforma!I47 -> -894915.57 | Q39: =Proforma!J47 -> -894915.57 | ... S39: =Proforma!L47 -> -894915.57
A40: Additional paid-in capital | B40: 167587 | C40: 178227 | D40: 191451 | E40: 203310 | F40: 210825 | G40: 232932 | H40: 243050 | I40: 253466 | J40: =Proforma!C48 -> 253466 | K40: =Proforma!D48 -> 253466 | L40: =Proforma!E48 -> 253466 | M40: =Proforma!F48 -> 253466 | N40: =Proforma!G48 -> 253466 | O40: =Proforma!H48 -> 253466 | P40: =Proforma!I48 -> 253466 | Q40: =Proforma!J48 -> 253466 | ... S40: =Proforma!L48 -> 253466
...

Sheet Income Statement
D1: DECKERS OUTDOOR CORPORATION AND SUBSIDIARIES
D2: CONSOLIDATED STATEMENTS OF COMPREHENSIVE INCOME
D3: (dollar and share data amounts in thousands, except per share data)
B4: Historical | D4: Historical | J4: Projected
A5: Year | B5: 2018 | C5: 2019 | D5: 2020 | E5: 2021 | F5: 2022 | G5: 2023 | H5: 2024 | I5: 2025 | J5: 2026 | K5: 2027 | L5: 2028 | M5: 2029 | N5: 2030 | O5: 2031 | P5: 2032 | Q5: 2033 | R5: 2034 | S5: 2035
A6: Net sales | B6: 1903339 | C6: 2020437 | D6: 2132689 | E6: 2545641 | F6: 3150339 | G6: 3627286 | H6: 4287763 | I6: 4985612 | J6: =Proforma!C3 -> 5910350.4 | K6: =Proforma!D3 -> 7006610.5 | L6: =Proforma!E3 -> 8306206.5 | M6: =Proforma!F3 -> 9846853.5 | N6: =Proforma!G3 -> 11673262 | O6: =Proforma!H3 -> 13838435 | P6: =Proforma!I3 -> 16405207 | Q6: =Proforma!J3 -> 19448068 | ... S6: =Proforma!L3 -> 27331658
A7: Cost of Sales | B7: 971697 | C7: 980187 | D7: 1029016 | E7: 1171551 | F7: 1542788 | G7: 1801916 | H7: 1902275 | I7: 2099949 | J7: =Proforma!C4 -> 2752309.9 | K7: =Proforma!D4 -> 3262812.3 | L7: =Proforma!E4 -> 3868003.3 | M7: =Proforma!F4 -> 4585446 | N7: =Proforma!G4 -> 5435961.1 | O7: =Proforma!H4 -> 6444230.8 | P7: =Proforma!I4 -> 7639515.8 | Q7: =Proforma!J4 -> 9056504.1 | ... S7: =Proforma!L4 -> 12727705
A8: Gross Profit | B8: =B6-B7 -> 931642 | C8: =C6-C7 -> 1040250 | D8: =D6-D7 -> 1103673 | E8: =E6-E7 -> 1374090 | F8: =F6-F7 -> 1607551 | G8: =G6-G7 -> 1825370 | H8: =H6-H7 -> 2385488 | I8: =I6-I7 -> 2885663 | J8: =Proforma!C5 -> 3158040.4 | K8: =Proforma!D5 -> 3743798.2 | L8: =Proforma!E5 -> 4438203.2 | M8: =Proforma!F5 -> 5261407.4 | N8: =Proforma!G5 -> 6237300.7 | O8: =Proforma!H5 -> 7394204.1 | P8: =Proforma!I5 -> 8765691.5 | Q8: =Proforma!J5 -> 10391564 | ... S8: =Proforma!L5 -> 14603953
A9: Selling, general, and administrative expenses | B9: 709058 | C9: 712930 | D9: 765538 | E9: 869885 | F9: 1042844 | G9: 1172619 | H9: 1457974 | I9: 1706571 | J9: =Proforma!C6 -> 2006863.1 | K9: =Proforma!D6 -> 2379098.9 | L9: =Proforma!E6 -> 2820377.5 | M9: =Proforma!F6 -> 3343505.1 | N9: =Proforma!G6 -> 3963663.1 | O9: =Proforma!H6 -> 4698849 | P9: =Proforma!I6 -> 5570398.1 | Q9: =Proforma!J6 -> 6603603.4 | ... S9: =Proforma!L6 -> 9280481
A10: EBIT, Income from operations | B10: =B8-B9 -> 222584 | C10: =C8-C9 -> 327320 | D10: =D8-D9 -> 338135 | E10: =E8-E9 -> 504205 | F10: =F8-F9 -> 564707 | G10: =G8-G9 -> 652751 | H10: =H8-H9 -> 927514 | I10: =I8-I9 -> 1179092 | J10: =Proforma!B7 -> 1179092 | K10: =Proforma!C7 -> 1151177.4 | L10: =Proforma!D7 -> 1364699.4 | M10: =Proforma!E7 -> 1617825.7 | N10: =Proforma!F7 -> 1917902.3 | O10: =Proforma!G7 -> 2273637.6 | P10: =Proforma!H7 -> 2695355.1 | Q10: =Proforma!I7 -> 3195293.4 | ... S10: =Proforma!K7 -> 4490557.2
A11: Interest income | B11: -3057 | C11: -6028 | D11: -7261 | E11: -2637 | F11: -1901 | G11: -15563 | H11: -52208 | I11: -68389 | J11: Assumption: Other income, net is excluded from the pro forma projections because it consists primarily of non-operating and non-recurring items (e.g., foreign currency gains/losses, asset sale gains/losses). These items are not reflective of the company’s ongoing operations and are immaterial relative to total EBIT.
A12: Interest expense | B12: 4585 | C12: 4661 | D12: 5046 | E12: 6028 | F12: 2083 | G12: 3442 | H12: 2564 | I12: 3517 | J12: =Proforma!B9 -> 3517 | K12: =Proforma!C9 -> 7533.2585 | L12: =Proforma!D9 -> 8930.5379 | M12: =Proforma!E9 -> 10586.987 | N12: =Proforma!F9 -> 12550.676 | O12: =Proforma!G9 -> 14878.593 | P12: =Proforma!H9 -> 17638.296 | Q12: =Proforma!I9 -> 20909.872 | ... S12: =Proforma!K9 -> 29386.026
A13: Other income, net | B13: 360 | C13: -247 | D13: -516 | E13: -700 | F13: -113 | G13: -1210 | H13: -1783 | I13: 665 | J13: Assumption: Other income excluded due to immateriality and non-recurring nature.
A14: Total other (income) expense, net | B14: 1888 | C14: =SUM(C11:C13) -> -1614 | D14: =SUM(D11:D13) -> -2731 | E14: =SUM(E11:E13) -> 2691 | F14: =SUM(F11:F13) -> 69 | G14: =SUM(G11:G13) -> -13331 | H14: =SUM(H11:H13) -> -51427 | I14: =SUM(I11:I13) -> -64207
A15: EBT, Income before income taxes | B15: =B10-B14 -> 220696 | C15: =C10-C14 -> 328934 | D15: =D10-D14 -> 340866 | E15: =E10-E14 -> 501514 | F15: =F10-F14 -> 564638 | G15: =G10-G14 -> 666082 | H15: =H10-H14 -> 978941 | I15: =I10-I14 -> 1243299 | J15: =Proforma!C11 -> 1143644.1 | K15: =Proforma!D11 -> 1355768.8 | L15: =Proforma!E11 -> 1607238.7 | M15: =Proforma!F11 -> 1905351.7 | N15: =Proforma!G11 -> 2258759 | O15: =Proforma!H11 -> 2677716.8 | P15: =Proforma!I11 -> 3174383.5 | Q15: =Proforma!J11 -> 3763172.6 | ... S15: =Proforma!L11 -> 5288635.6
A16: Income tax expense | B16: 106302 | C16: 64626 | D16: 64724 | E16: 118939 | F16: 112689 | G16: 149260 | H16: 219378 | I16: 277208 | J16: =Proforma!C12 -> 247363.32 | K16: =Proforma!D12 -> 293244.62 | L16: =Proforma!E12 -> 347636.05 | M16: =Proforma!F12 -> 412116.07 | N16: =Proforma!G12 -> 488555.95 | O16: =Proforma!H12 -> 579174 | P16: =Proforma!I12 -> 686600.01 | Q16: =Proforma!J12 -> 813951.55 | ... S16: =Proforma!L12 -> 1143900
A17: Net Income | B17: =B15-B16 -> 114394 | C17: =C15-C16 -> 264308 | D17: =D15-D16 -> 276142 | E17: =E15-E16 -> 382575 | F17: =F15-F16 -> 451949 | G17: =G15-G16 -> 516822 | H17: 759563 | I17: 966091 | J17: =Proforma!C13 -> 896280.78 | K17: =Proforma!D13 -> 1062524.2 | L17: =Proforma!E13 -> 1259602.7 | M17: =Proforma!F13 -> 1493235.6 | N17: =Proforma!G13 -> 1770203 | O17: =Proforma!H13 -> 2098542.8 | P17: =Proforma!I13 -> 2487783.5 | Q17: =Proforma!J13 -> 2949221.1 | ... S17: =Proforma!L13 -> 4144735.6
A18: Other comprehensive (loss) income, net of tax
A19: Unrealized loss on cash flow hedges | B19: -613 | C19: -243 | D19: 0 | E19: 0 | F19: 0 | G19: 0 | H19: 0 | I19: 1584
A20: Foreign currency translation (loss) gain | B20: 14081 | C20: -9428 | D20: -2905 | E20: 8816 | F20: -8212 | G20: -14080 | H20: -11698 | I20: -505
A21: Total other comprehensive (loss) income, net of tax | B21: =B20+B19 -> 13468 | C21: =C20+C19 -> -9671 | D21: =D20+D19 -> -2905 | E21: =E20+E19 -> 8816 | F21: =F20+F19 -> -8212 | G21: =G20+G19 -> -14080 | H21: =H20+H19 -> -11698 | I21: =I20+I19 -> 1079
A22: Comprehensive income | B22: =B17+B21 -> 127862 | C22: =C17+C21 -> 254637 | D22: =D17+D21 -> 273237 | E22: =E17+E21 -> 391391 | F22: =F17+F21 -> 443737 | G22: =G17+G21 -> 502742 | H22: =H17+H21 -> 747865 | I22: =I17+I21 -> 967170
A23: Net income per share
A24: Basic | B24: 3.6 | C24: 8.92 | D24: 9.73 | E24: 13.64 | F24: 16.43 | G24: 19.5 | H24: 4.89 | I24: 6.36
A25: Diluted | B25: 3.58 | C25: 8.84 | D25: 9.62 | E25: 13.47 | F25: 16.26 | G25: 19.37 | H25: 4.86 | I25: 6.33
A26: Weighted-average common shares outstanding
A27: Basic | B27: 31758 | C27: 29641 | D27: 28385 | E27: 28055 | F27: 27508 | G27: 26504 | H27: 155225 | I27: 151992
A28: Diluted | B28: 31996 | C28: 29903 | D28: 28694 | E28: 28406 | F28: 27789 | G28: 26686 | H28: 156285 | I28: 152670
A31: Income Statement Drivers | D31: Historical | J31: Historical Average | K31: Projected | P31: Commentary
A32: Year | D32: 2020 | E32: 2021 | F32: 2022 | G32: 2023 | H32: 2024 | I32: 2025 | K32: =N5+1 -> 2031 | L32: =O5+1 -> 2032 | M32: =P5+1 -> 2033 | N32: =Q5+1 -> 2034 | O32: =R5+1 -> 2035
A33: Sales Growth | E33: =E6/D6-1 -> 0.19362973 | F33: =F6/E6-1 -> 0.23754253 | G33: =G6/F6-1 -> 0.15139545 | H33: =H6/G6-1 -> 0.18208572 | I33: =I6/H6-1 -> 0.16275363 | J33: =AVERAGE(D33:I33) -> 0.18548141 | K33: =10% -> 0.1 | L33: 0.08 | M33: 0.07 | N33: 0.05 | O33: 0.05 | P33: We are making the assumption that growth rate will stablize to 5% at the end of of our projection for ease of TV calculations
A34: COGS Growth | E34: =E7/D7-1 -> 0.13851582 | F34: =F7/E7-1 -> 0.31687652 | G34: =G7/F7-1 -> 0.16796086 | H34: =H7/G7-1 -> 0.055695715 | I34: =I7/H7-1 -> 0.10391452 | J34: =AVERAGE(D34:I34) -> 0.15659269
A35: SGA Growth | E35: =E9/D9-1 -> 0.13630545 | F35: =F9/E9-1 -> 0.19882973 | G35: =G9/F9-1 -> 0.12444335 | H35: =H9/G9-1 -> 0.24334844 | I35: =I9/H9-1 -> 0.17050853 | J35: =AVERAGE(D35:I35) -> 0.1746871
A36: COGS (% of Sales) | D36: =D7/D6 -> 0.48249698 | E36: =E7/E6 -> 0.46021847 | F36: =F7/F6 -> 0.48972126 | G36: =G7/G6 -> 0.496767 | H36: =H7/H6 -> 0.44365209 | I36: =I7/I6 -> 0.42120185 | J36: =AVERAGE(D36:I36) -> 0.46567628
A37: SG&A (% of Sales) | D37: =D9/D6 -> 0.35895435 | E37: =E9/E6 -> 0.34171551 | F37: =F9/F6 -> 0.33102596 | G37: =G9/G6 -> 0.32327724 | H37: =H9/H6 -> 0.34003139 | I37: =I9/I6 -> 0.3422992 | J37: =AVERAGE(D37:I37) -> 0.33955061
A38: Tax Rate | D38: =D16/D15 -> 0.18988107 | E38: =E16/E15 -> 0.23715988 | F38: =F16/F15 -> 0.19957743 | G38: =G16/G15 -> 0.22408652 | H38: =H16/H15 -> 0.22409726 | I38: =I16/I15 -> 0.22296165 | J38: =AVERAGE(D38:I38) -> 0.21629397
A39: Net Income (% of Sales) | D39: =D17/D6 -> 0.12948067 | E39: =E17/E6 -> 0.15028631 | F39: =F17/F6 -> 0.14346043 | G39: =G17/G6 -> 0.14248173 | H39: =H17/H6 -> 0.17714668 | I39: =I17/I6 -> 0.19377581 | J39: =AVERAGE(D39:I39) -> 0.15610527
A40: Interest Expense (% of Sales) | D40: =D12/D6 -> 0.0023660271 | E40: =E12/E6 -> 0.0023679694 | F40: =F12/F6 -> 0.00066119868 | G40: =G12/G6 -> 0.00094891883 | H40: =H12/H6 -> 0.00059798081 | I40: =I12/I6 -> 0.00070542995 | J40: =AVERAGE(D40:I40) -> 0.0012745875
A41: Operating Income (% of Sales) | D41: =D10/D6 -> 0.15854867 | E41: =E10/E6 -> 0.19806603 | F41: =F10/F6 -> 0.17925277 | G41: =G10/G6 -> 0.17995576 | H41: =H10/H6 -> 0.21631653 | I41: =I10/I6 -> 0.23649895 | J41: =AVERAGE(D41:I41) -> 0.19477312
A42: Gross Profit (% of Sales) | D42: =D8/D6 -> 0.51750302 | E42: =E8/E6 -> 0.53978153 | F42: =F8/F6 -> 0.51027874 | G42: =G8/G6 -> 0.503233 | H42: =H8/H6 -> 0.55634791 | I42: =I8/I6 -> 0.57879815 | J42: =AVERAGE(D42:I42) -> 0.53432372
...

Sheet Cash Flows
A1: DECKERS OUTDOOR CORPORATION AND SUBSIDIARIES
A2: CONSOLIDATED STATEMENTS OF CASH FLOWS
A3: (dollar and share data amounts in thousands)
B4: Historical
A5: Year | B5: 2018 | C5: 2019 | D5: 2020 | E5: 2021 | F5: 2022 | G5: 2023 | H5: 2024 | I5: 2025
A6: OPERATING ACTIVITIES
A7: Net income | C7: 264308 | D7: 276142 | E7: 382575 | F7: 451949 | G7: 516822 | H7: 759563 | I7: 966091
A8: Reconciliation of net income to net cash provided by (used in) operating activities:
A9: Depreciation, amortization, and accretion | C9: 44941 | D9: 38912 | E9: 40530 | F9: 42878 | G9: 47858 | H9: 57587 | I9: 69353
A10: Amortization on cloud computing arrangements | D10: - | E10: 737 | F10: 1552 | G10: 2149 | H10: 2075 | I10: 2380
A11: Loss on extinguishment of debt | G11: 226
A12: Bad debt expense (benefit) | D12: 3498 | E12: 3053 | F12: -342 | G12: 1983 | H12: 789 | I12: 5032
A13: Deferred tax benefit | D13: 2934 | E13: -8171 | F13: -27796 | G13: -9719 | H13: -1510 | I13: -5545
A14: Stock-based compensation | D14: 14477 | E14: 22701 | F14: 26816 | G14: 26897 | H14: 37288 | I14: 37943
A15: Excess tax benefit from stock based compensation | C15: -546 | D15: -1953 | E15: -586
A16: Loss on disposal of long-lived assets | C16: 277 | D16: 698 | E16: 1019 | F16: 107 | G16: 2691 | H16: 407 | I16: 3183
A17: Impairment of intangible assets | E17: 3522 | H17: 8164
A18: Impairment of operating lease and other long-lived assets | C18: 180 | D18: 1365 | E18: 14084 | F18: 3186 | G18: 2817 | H18: 1015 | I18: 4290
A19: Gain on settlement of asset retirement obligations | D19: -705 | E19: -207
A20: Changes in operating assets and liabilities:
A21: Trade accounts receivable, net | C21: -16157 | D21: -10493 | E21: -33173 | F21: -86627 | G21: -806 | H21: 4157 | I21: 41339
A22: Inventories | C22: 8827 | D22: -32777 | E22: 33378 | F22: -228554 | G22: -26056 | H22: 58541 | I22: -24344
A23: Prepaid expenses and other current assets | C23: -515 | D23: 2477 | E23: -22128 | F23: -19095 | G23: -5609 | H23: -38490 | I23: 20946
A24: Income tax receivable | C24: -165 | D24: -5811 | E24: 1842 | F24: -11933 | G24: 13459 | H24: -38775 | I24: 6945
A25: Net operating lease assets and lease liabilities | D25: -3264 | E25: 250 | F25: 3189 | G25: -8308 | H25: -567 | I25: -2583
A26: Other assets | D26: -6558 | E26: -3103 | F26: -28296 | G26: 13240 | H26: -9989 | I26: 6566
A27: Trade accounts payable | D27: 23312 | E27: 79176 | F27: 89184 | G27: -74247 | H27: 119601 | I27: 35636
A28: Other accrued expenses | D28: -11112 | E28: 53785 | F28: -20370 | G28: 11528 | H28: 43534 | I28: 22222
A29: Income tax payable | D29: -6226 | E29: 25817 | F29: -24494 | G29: 4897 | H29: 35016 | I29: -29039
A30: Other long-term liabilities | D30: 1418 | E30: 530 | F30: 999 | G30: 17600 | H30: -5222 | I30: -33214
A31: Net cash provided by operating activities | D31: 286334 | E31: 596217 | F31: 172353 | G31: 537422 | H31: 1033184 | I31: 1044523
A33: INVESTING ACTIVITIES
A34: Purchases of property and equipment | D34: -32455 | E34: -32218 | F34: -51017 | G34: -81025 | H34: -89365 | I34: -86171
A35: Proceeds from sales of property and equipment | D35: 491 | E35: 49 | F35: 8 | G35: 12 | H35: 34 | I35: 11168
A36: Net cash used in investing activities | D36: -31964 | E36: -32169 | F36: -51009 | G36: -81013 | H36: -89331 | I36: -75003
A38: FINANCING ACTIVITIES
A39: Proceeds from short-term borrowings | D39: 69336 | E39: 9100
A40: Repayments of short-term borrowings | D40: 69197 | E40: -9478
A41: Loan origination costs on revolving credit facilities | G41: -1537
A42: Proceeds from issuance of stock | D42: 1288 | E42: 1502 | F42: 1991 | G42: 2170 | H42: 2444 | I42: 3804
...

Sheet Proforma
A1: Income Statement (in thousands of dollars)
A2: Year | B2: 2025 | C2: 2026 | D2: 2027 | E2: 2028 | F2: 2029 | G2: 2030 | H2: 2031 | I2: 2032 | J2: 2033 | K2: 2034 | L2: 2035
A3: Net sales | B3: 4985612 | C3: =B3*(1+'Income Statement'!$J$33) -> 5910350.4 | D3: =C3*(1+'Income Statement'!$J$33) -> 7006610.5 | E3: =D3*(1+'Income Statement'!$J$33) -> 8306206.5 | F3: =E3*(1+'Income Statement'!$J$33) -> 9846853.5 | G3: =F3*(1+'Income Statement'!$J$33) -> 11673262 | H3: =G3*(1+'Income Statement'!$J$33) -> 13838435 | I3: =H3*(1+'Income Statement'!$J$33) -> 16405207 | J3: =I3*(1+'Income Statement'!$J$33) -> 19448068 | ... L3: =K3*(1+'Income Statement'!$J$33) -> 27331658
A4: Cost of Sales | B4: 2099949 | C4: ='Income Statement'!$J$36*Proforma!C3 -> 2752309.9 | D4: ='Income Statement'!$J$36*Proforma!D3 -> 3262812.3 | E4: ='Income Statement'!$J$36*Proforma!E3 -> 3868003.3 | F4: ='Income Statement'!$J$36*Proforma!F3 -> 4585446 | G4: ='Income Statement'!$J$36*Proforma!G3 -> 5435961.1 | H4: ='Income Statement'!$J$36*Proforma!H3 -> 6444230.8 | I4: ='Income Statement'!$J$36*Proforma!I3 -> 7639515.8 | J4: ='Income Statement'!$J$36*Proforma!J3 -> 9056504.1 | ... L4: ='Income Statement'!$J$36*Proforma!L3 -> 12727705
A5: Gross Profit | B5: =B3-B4 -> 2885663 | C5: =C3-C4 -> 3158040.4 | D5: =D3-D4 -> 3743798.2 | E5: =E3-E4 -> 4438203.2 | F5: =F3-F4 -> 5261407.4 | G5: =G3-G4 -> 6237300.7 | H5: =H3-H4 -> 7394204.1 | I5: =I3-I4 -> 8765691.5 | ... L5: =L3-L4 -> 14603953
A6: Selling, general, and administrative expenses | B6: 1706571 | C6: =C3*'Income Statement'!$J$37 -> 2006863.1 | D6: =D3*'Income Statement'!$J$37 -> 2379098.9 | E6: =E3*'Income Statement'!$J$37 -> 2820377.5 | F6: =F3*'Income Statement'!$J$37 -> 3343505.1 | G6: =G3*'Income Statement'!$J$37 -> 3963663.1 | H6: =H3*'Income Statement'!$J$37 -> 4698849 | I6: =I3*'Income Statement'!$J$37 -> 5570398.1 | J6: =J3*'Income Statement'!$J$37 -> 6603603.4 | ... L6: =L3*'Income Statement'!$J$37 -> 9280481
A7: EBIT, Earnings before interest & taxes | B7: =B5-B6 -> 1179092 | C7: =C5-C6 -> 1151177.4 | D7: =D5-D6 -> 1364699.4 | E7: =E5-E6 -> 1617825.7 | F7: =F5-F6 -> 1917902.3 | G7: =G5-G6 -> 2273637.6 | H7: =H5-H6 -> 2695355.1 | I7: =I5-I6 -> 3195293.4 | ... L7: =L5-L6 -> 5323472.1
A8: Interest income | B8: Assumption: Other income, net is excluded from the pro forma projections because it consists primarily of non-operating and non-recurring items (e.g., foreign currency gains/losses, asset sale gains/losses). These items are not reflective of the company’s ongoing operations and are immaterial relative to total EBIT.
A9: Interest expense | B9: 3517 | C9: =C3*'Income Statement'!$J$40 -> 7533.2585 | D9: =D3*'Income Statement'!$J$40 -> 8930.5379 | E9: =E3*'Income Statement'!$J$40 -> 10586.987 | F9: =F3*'Income Statement'!$J$40 -> 12550.676 | G9: =G3*'Income Statement'!$J$40 -> 14878.593 | H9: =H3*'Income Statement'!$J$40 -> 17638.296 | I9: =I3*'Income Statement'!$J$40 -> 20909.872 | J9: =J3*'Income Statement'!$J$40 -> 24788.264 | ... L9: =L3*'Income Statement'!$J$40 -> 34836.588
A10: Other income, net | B10: Assumption: Other income excluded due to immateriality and non-recurring nature.
A11: EBT, Income before income taxes | B11: =B7-B9 -> 1175575 | C11: =C7-C9 -> 1143644.1 | D11: =D7-D9 -> 1355768.8 | E11: =E7-E9 -> 1607238.7 | F11: =F7-F9 -> 1905351.7 | G11: =G7-G9 -> 2258759 | H11: =H7-H9 -> 2677716.8 | I11: =I7-I9 -> 3174383.5 | ... L11: =L7-L9 -> 5288635.6
A12: Income tax expense | B12: 277208 | C12: =C11*'Income Statement'!$J$38 -> 247363.32 | D12: =D11*'Income Statement'!$J$38 -> 293244.62 | E12: =E11*'Income Statement'!$J$38 -> 347636.05 | F12: =F11*'Income Statement'!$J$38 -> 412116.07 | G12: =G11*'Income Statement'!$J$38 -> 488555.95 | H12: =H11*'Income Statement'!$J$38 -> 579174 | I12: =I11*'Income Statement'!$J$38 -> 686600.01 | J12: =J11*'Income Statement'!$J$38 -> 813951.55 | ... L12: =L11*'Income Statement'!$J$38 -> 1143900
A13: Net Income | B13: =B11-B12 -> 898367 | C13: =C11-C12 -> 896280.78 | D13: =D11-D12 -> 1062524.2 | E13: =E11-E12 -> 1259602.7 | F13: =F11-F12 -> 1493235.6 | G13: =G11-G12 -> 1770203 | H13: =H11-H12 -> 2098542.8 | I13: =I11-I12 -> 2487783.5 | ... L13: =L11-L12 -> 4144735.6
A15: Balance Sheet (in thousands of dollars)
A16: Year | B16: 2025 | C16: 2026 | D16: 2027 | E16: 2028 | F16: 2029 | G16: 2030 | H16: 2031 | I16: 2032 | J16: 2033 | K16: 2034 | L16: 2035
A17: ASSETS
A18: Cash and cash equivalents | B18: 1889188 | C18: ='Income Statement'!$J$43*Proforma!C3 -> 1970228.1 | D18: ='Income Statement'!$J$43*Proforma!D3 -> 2335668.7 | E18: ='Income Statement'!$J$43*Proforma!E3 -> 2768891.9 | F18: ='Income Statement'!$J$43*Proforma!F3 -> 3282469.9 | G18: ='Income Statement'!$J$43*Proforma!G3 -> 3891307 | H18: ='Income Statement'!$J$43*Proforma!H3 -> 4613072.1 | I18: ='Income Statement'!$J$43*Proforma!I3 -> 5468711.3 | J18: ='Income Statement'!$J$43*Proforma!J3 -> 6483055.6 | ... L18: ='Income Statement'!$J$43*Proforma!L3 -> 9111067.1
A19: Trade accounts receivable, net of allowances | B19: 332872 | C19: =C3*('Balance Sheet'!$J$51/365) -> 971564.44 | D19: =D3*('Balance Sheet'!$J$51/365) -> 1151771.6 | E19: =E3*('Balance Sheet'!$J$51/365) -> 1365403.8 | F19: =F3*('Balance Sheet'!$J$51/365) -> 1618660.8 | G19: =G3*('Balance Sheet'!$J$51/365) -> 1918892.3 | H19: =H3*('Balance Sheet'!$J$51/365) -> 2274811.2 | I19: =I3*('Balance Sheet'!$J$51/365) -> 2696746.4 | J19: =J3*('Balance Sheet'!$J$51/365) -> 3196942.7 | ... L19: =L3*('Balance Sheet'!$J$51/365) -> 4492875.2
A20: Inventories | B20: 495226 | C20: =C4 * ('Balance Sheet'!$J$52/365) -> 603246.02 | D20: =D4 * ('Balance Sheet'!$J$52/365) -> 715136.94 | E20: =E4 * ('Balance Sheet'!$J$52/365) -> 847781.55 | F20: =F4 * ('Balance Sheet'!$J$52/365) -> 1005029.3 | G20: =G4 * ('Balance Sheet'!$J$52/365) -> 1191443.5 | H20: =H4 * ('Balance Sheet'!$J$52/365) -> 1412434.1 | I20: =I4 * ('Balance Sheet'!$J$52/365) -> 1674414.4 | J20: =J4 * ('Balance Sheet'!$J$52/365) -> 1984987.2 | ... L20: =L4 * ('Balance Sheet'!$J$52/365) -> 2789633.9
A21: Prepaid expenses & Other Current Assets | B21: 106576 | C21: ='Balance Sheet'!$J$53*Proforma!C4 -> 142160.56 | D21: ='Balance Sheet'!$J$53*Proforma!D4 -> 168528.7 | E21: ='Balance Sheet'!$J$53*Proforma!E4 -> 199787.64 | F21: ='Balance Sheet'!$J$53*Proforma!F4 -> 236844.53 | G21: ='Balance Sheet'!$J$53*Proforma!G4 -> 280774.79 | H21: ='Balance Sheet'!$J$53*Proforma!H4 -> 332853.3 | I21: ='Balance Sheet'!$J$53*Proforma!I4 -> 394591.4 | J21: ='Balance Sheet'!$J$53*Proforma!J4 -> 467780.77 | ... L21: ='Balance Sheet'!$J$53*Proforma!L4 -> 657403.28
A22: Income tax receivable | B22: Non-operating; reflects timing of tax refunds, not a recurring operating driver. Including it complicates projections without improving accuracy.
A23: Total current assets | B23: =SUM(B18:B21) -> 2823862 | C23: =SUM(C18:C21) -> 3687199.1 | D23: =SUM(D18:D21) -> 4371106 | E23: =SUM(E18:E21) -> 5181864.9 | F23: =SUM(F18:F21) -> 6143004.5 | G23: =SUM(G18:G21) -> 7282417.7 | H23: =SUM(H18:H21) -> 8633170.8 | I23: =SUM(I18:I21) -> 10234464 | ... L23: =SUM(L18:L21) -> 17050979
A24: PPE gross | B24: 728563 | C24: =C3*'Balance Sheet'!$J$58 -> 998730.72 | D24: =D3*'Balance Sheet'!$J$58 -> 1183976.7 | E24: =E3*'Balance Sheet'!$J$58 -> 1403582.4 | F24: =F3*'Balance Sheet'!$J$58 -> 1663920.8 | G24: =G3*'Balance Sheet'!$J$58 -> 1972547.2 | H24: =H3*'Balance Sheet'!$J$58 -> 2338418.1 | I24: =I3*'Balance Sheet'!$J$58 -> 2772151.1 | J24: =J3*'Balance Sheet'!$J$58 -> 3286333.7 | ... L24: =L3*'Balance Sheet'!$J$58 -> 4618502.2
A25: Depreciation | B25: 402964 | C25: ='Balance Sheet'!$J$57*Proforma!C24 -> 547069.98 | D25: ='Balance Sheet'!$J$57*Proforma!D24 -> 648541.29 | E25: ='Balance Sheet'!$J$57*Proforma!E24 -> 768833.65 | F25: ='Balance Sheet'!$J$57*Proforma!F24 -> 911438 | G25: ='Balance Sheet'!$J$57*Proforma!G24 -> 1080492.8 | H25: ='Balance Sheet'!$J$57*Proforma!H24 -> 1280904.1 | I25: ='Balance Sheet'!$J$57*Proforma!I24 -> 1518488.1 | J25: ='Balance Sheet'!$J$57*Proforma!J24 -> 1800139.4 | ... L25: ='Balance Sheet'!$J$57*Proforma!L24 -> 2529855
A26: PPE net
A27: Operating lease assets | B27: 237352 | C27: ='Balance Sheet'!$J$54 -> 214882.5 | D27: ='Balance Sheet'!$J$54 -> 214882.5 | E27: ='Balance Sheet'!$J$54 -> 214882.5 | F27: ='Balance Sheet'!$J$54 -> 214882.5 | G27: ='Balance Sheet'!$J$54 -> 214882.5 | H27: ='Balance Sheet'!$J$54 -> 214882.5 | I27: ='Balance Sheet'!$J$54 -> 214882.5 | J27: ='Balance Sheet'!$J$54 -> 214882.5 | ... L27: ='Balance Sheet'!$J$54 -> 214882.5
A28: Goodwill | B28: 13990 | C28: ='Balance Sheet'!$J$55 -> 13990 | D28: ='Balance Sheet'!$J$55 -> 13990 | E28: ='Balance Sheet'!$J$55 -> 13990 | F28: ='Balance Sheet'!$J$55 -> 13990 | G28: ='Balance Sheet'!$J$55 -> 13990 | H28: ='Balance Sheet'!$J$55 -> 13990 | I28: ='Balance Sheet'!$J$55 -> 13990 | J28: ='Balance Sheet'!$J$55 -> 13990 | ... L28: ='Balance Sheet'!$J$55 -> 13990
A29: Other intangible assets, net of accumulated amortization | B29: 15699 | C29: ='Balance Sheet'!$J$59 -> 34981.333 | D29: ='Balance Sheet'!$J$59 -> 34981.333 | E29: ='Balance Sheet'!$J$59 -> 34981.333 | F29: ='Balance Sheet'!$J$59 -> 34981.333 | G29: ='Balance Sheet'!$J$59 -> 34981.333 | H29: ='Balance Sheet'!$J$59 -> 34981.333 | I29: ='Balance Sheet'!$J$59 -> 34981.333 | J29: ='Balance Sheet'!$J$59 -> 34981.333 | ... L29: ='Balance Sheet'!$J$59 -> 34981.333
A30: Deferred tax assets, net | B30: Non-operating; timing difference in taxes. Often excluded in operating asset base for ROIC/valuation.
A31: Other non-current assets | B31: 39546 | C31: =C3*'Balance Sheet'!$J$56 -> 73619.803 | D31: =D3*'Balance Sheet'!$J$56 -> 87274.908 | E31: =E3*'Balance Sheet'!$J$56 -> 103462.78 | F31: =F3*'Balance Sheet'!$J$56 -> 122653.2 | G31: =G3*'Balance Sheet'!$J$56 -> 145403.09 | H31: =H3*'Balance Sheet'!$J$56 -> 172372.67 | I31: =I3*'Balance Sheet'!$J$56 -> 204344.59 | J31: =J3*'Balance Sheet'!$J$56 -> 242246.71 | ... L31: =L3*'Balance Sheet'!$J$56 -> 340445.34
A32: Total Non-current Assets | B32: =B24-B25+B27+B28+B29+B31 -> 632186 | C32: =C24-C25+C27+C28+C29+C31 -> 789134.38 | D32: =D24-D25+D27+D28+D29+D31 -> 886564.16 | E32: =E24-E25+E27+E28+E29+E31 -> 1002065.3 | F32: =F24-F25+F27+F28+F29+F31 -> 1138989.9 | G32: =G24-G25+G27+G28+G29+G31 -> 1301311.3 | H32: =H24-H25+H27+H28+H29+H31 -> 1493740.4 | I32: =I24-I25+I27+I28+I29+I31 -> 1721861.5 | ... L32: =L24-L25+L27+L28+L29+L31 -> 2692946.4
A33: Total assets | B33: =B23+B32 -> 3456048 | C33: =C23+C32 -> 4476333.5 | D33: =D23+D32 -> 5257670.1 | E33: =E23+E32 -> 6183930.2 | F33: =F23+F32 -> 7281994.4 | G33: =G23+G32 -> 8583729 | H33: =H23+H32 -> 10126911 | I33: =I23+I32 -> 11956325 | ... L33: =L23+L32 -> 19743926
A34: LIABILITIES AND STOCKHOLDERS' EQUITY
A35: Trade accounts payable | B35: 417955 | C35: =C4*('Balance Sheet'!$J$63/365) -> 504182.66 | D35: =D4*('Balance Sheet'!$J$63/365) -> 597699.17 | E35: =E4*('Balance Sheet'!$J$63/365) -> 708561.26 | F35: =F4*('Balance Sheet'!$J$63/365) -> 839986.2 | G35: =G4*('Balance Sheet'!$J$63/365) -> 995788.03 | H35: =H4*('Balance Sheet'!$J$63/365) -> 1180488.2 | I35: =I4*('Balance Sheet'!$J$63/365) -> 1399446.8 | J35: =J4*('Balance Sheet'!$J$63/365) -> 1659018.2 | ... L35: =L4*('Balance Sheet'!$J$63/365) -> 2331528.1
A36: Accrued payroll | B36: 125417 | C36: =C4*'Balance Sheet'!$J$64 -> 143389.27 | D36: =D4*'Balance Sheet'!$J$64 -> 169985.31 | E36: =E4*'Balance Sheet'!$J$64 -> 201514.43 | F36: =F4*'Balance Sheet'!$J$64 -> 238891.61 | G36: =G4*'Balance Sheet'!$J$64 -> 283201.57 | H36: =H4*'Balance Sheet'!$J$64 -> 335730.19 | I36: =I4*'Balance Sheet'!$J$64 -> 398001.9 | J36: =J4*'Balance Sheet'!$J$64 -> 471823.86 | ... L36: =L4*'Balance Sheet'!$J$64 -> 663085.3
A37: Operating lease liabilities | B37: 54453 | C37: ='Balance Sheet'!$J$67*C3 -> 93291.11 | D37: ='Balance Sheet'!$J$67*D3 -> 110594.88 | E37: ='Balance Sheet'!$J$67*E3 -> 131108.17 | F37: ='Balance Sheet'!$J$67*F3 -> 155426.3 | G37: ='Balance Sheet'!$J$67*G3 -> 184254.99 | H37: ='Balance Sheet'!$J$67*H3 -> 218430.87 | I37: ='Balance Sheet'!$J$67*I3 -> 258945.73 | J37: ='Balance Sheet'!$J$67*J3 -> 306975.35 | ... L37: ='Balance Sheet'!$J$67*L3 -> 431412.78
A38: Other accrued expenses | B38: 142120 | C38: =C4*'Balance Sheet'!$J$65 -> 150729.21 | D38: =D4*'Balance Sheet'!$J$65 -> 178686.68 | E38: =E4*'Balance Sheet'!$J$65 -> 211829.74 | F38: =F4*'Balance Sheet'!$J$65 -> 251120.22 | G38: =G4*'Balance Sheet'!$J$65 -> 297698.35 | H38: =H4*'Balance Sheet'!$J$65 -> 352915.86 | I38: =I4*'Balance Sheet'!$J$65 -> 418375.2 | J38: =J4*'Balance Sheet'!$J$65 -> 495976.02 | ... L38: =L4*'Balance Sheet'!$J$65 -> 697027.93
A39: Income tax payable | B39: Non-operating liability; reflects timing of tax payments.
A40: Value added tax payable | B40: Government tax pass-through, not part of operations profitably.
A41: Total current liabilities | B41: =SUM(B35:B38) -> 739945 | C41: =SUM(C35:C38) -> 891592.25 | D41: =SUM(D35:D38) -> 1056966 | E41: =SUM(E35:E38) -> 1253013.6 | F41: =SUM(F35:F38) -> 1485424.3 | G41: =SUM(G35:G38) -> 1760942.9 | H41: =SUM(H35:H38) -> 2087565.1 | I41: =SUM(I35:I38) -> 2474769.7 | ... L41: =SUM(L35:L38) -> 4123054.1
...

Sheet Balanced Proforma
A1: DECKERS OUTDOOR CORPORATION AND SUBSIDIARIES
A2: CONSOLIDATED PRO FORMA
A3: (dollar and share data amounts in thousands)
A4: Income Statement Projection
A5: Year | B5: 2025 | C5: 2026 | D5: 2027 | E5: 2028 | F5: 2029 | G5: 2030 | H5: 2031 | I5: 2032 | J5: 2033 | K5: 2034 | L5: 2035
A6: Net sales | B6: 4985612 | C6: =B6*(1+'Income Statement'!$J$33) -> 5910350.4 | D6: =C6*(1+'Income Statement'!$J$33) -> 7006610.5 | E6: =D6*(1+'Income Statement'!$J$33) -> 8306206.5 | F6: =E6*(1+'Income Statement'!$J$33) -> 9846853.5 | G6: =F6*(1+'Income Statement'!$J$33) -> 11673262 | H6: =G6*(1+'Income Statement'!$K$33) -> 12840588 | I6: =H6*(1+'Income Statement'!$L$33) -> 13867835 | J6: =I6*(1+'Income Statement'!$M$33) -> 14838583 | K6: =J6*(1+'Income Statement'!$N$33) -> 15580513 | L6: =K6*(1+'Income Statement'!$O$33) -> 16359538
A7: Cost of Sales | B7: 2099949 | C7: ='Income Statement'!$J$36*Proforma!C3 -> 2752309.9 | D7: ='Income Statement'!$J$36*Proforma!D3 -> 3262812.3 | E7: ='Income Statement'!$J$36*Proforma!E3 -> 3868003.3 | F7: ='Income Statement'!$J$36*Proforma!F3 -> 4585446 | G7: ='Income Statement'!$J$36*Proforma!G3 -> 5435961.1 | H7: ='Income Statement'!$J$36*Proforma!H3 -> 6444230.8 | I7: ='Income Statement'!$J$36*Proforma!I3 -> 7639515.8 | J7: ='Income Statement'!$J$36*Proforma!J3 -> 9056504.1 | K7: ='Income Statement'!$J$36*Proforma!K3 -> 10736317 | L7: ='Income Statement'!$J$36*L6 -> 7618248.8
A8: Gross Profit | B8: =B6-B7 -> 2885663 | C8: =C6-C7 -> 3158040.4 | D8: =D6-D7 -> 3743798.2 | E8: =E6-E7 -> 4438203.2 | F8: =F6-F7 -> 5261407.4 | G8: =G6-G7 -> 6237300.7 | H8: =H6-H7 -> 6396357.1 | I8: =I6-I7 -> 6228319.1 | ... L8: =L6-L7 -> 8741289.4
A9: Selling, general, and administrative expenses | B9: 1706571 | C9: =C6*'Income Statement'!$J$37 -> 2006863.1 | D9: =D6*'Income Statement'!$J$37 -> 2379098.9 | E9: =E6*'Income Statement'!$J$37 -> 2820377.5 | F9: =F6*'Income Statement'!$J$37 -> 3343505.1 | G9: =G6*'Income Statement'!$J$37 -> 3963663.1 | H9: =H6*'Income Statement'!$J$37 -> 4360029.4 | I9: =I6*'Income Statement'!$J$37 -> 4708831.8 | J9: =J6*'Income Statement'!$J$37 -> 5038450 | ... L9: =L6*'Income Statement'!$J$37 -> 5554891.1
A10: EBIT, Earnings before interest & taxes | B10: =B8-B9 -> 1179092 | C10: =C8-C9 -> 1151177.4 | D10: =D8-D9 -> 1364699.4 | E10: =E8-E9 -> 1617825.7 | F10: =F8-F9 -> 1917902.3 | G10: =G8-G9 -> 2273637.6 | H10: =H8-H9 -> 2036327.7 | I10: =I8-I9 -> 1519487.3 | ... L10: =L8-L9 -> 3186398.3
A11: Interest income | B11: Assumption: Other income, net is excluded from the pro forma projections because it consists primarily of non-operating and non-recurring items (e.g., foreign currency gains/losses, asset sale gains/losses). These items are not reflective of the company’s ongoing operations and are immaterial relative to total EBIT.
A12: Interest expense | B12: 3517 | C12: =C6*'Income Statement'!$J$40 -> 7533.2585 | D12: =D6*'Income Statement'!$J$40 -> 8930.5379 | E12: =E6*'Income Statement'!$J$40 -> 10586.987 | F12: =F6*'Income Statement'!$J$40 -> 12550.676 | G12: =G6*'Income Statement'!$J$40 -> 14878.593 | H12: =H6*'Income Statement'!$J$40 -> 16366.452 | I12: =I6*'Income Statement'!$J$40 -> 17675.769 | J12: =J6*'Income Statement'!$J$40 -> 18913.072 | ... L12: =L6*'Income Statement'!$J$40 -> 20851.662
A13: Other income, net | B13: Assumption: Other income excluded due to immateriality and non-recurring nature.
A14: EBT, Income before income taxes | B14: =B10-B12 -> 1175575 | C14: =C10-C12 -> 1143644.1 | D14: =D10-D12 -> 1355768.8 | E14: =E10-E12 -> 1607238.7 | F14: =F10-F12 -> 1905351.7 | G14: =G10-G12 -> 2258759 | H14: =H10-H12 -> 2019961.2 | I14: =I10-I12 -> 1501811.6 | ... L14: =L10-L12 -> 3165546.6
A15: Income tax expense | B15: 277208 | C15: =C14*'Income Statement'!$J$38 -> 247363.32 | D15: =D14*'Income Statement'!$J$38 -> 293244.62 | E15: =E14*'Income Statement'!$J$38 -> 347636.05 | F15: =F14*'Income Statement'!$J$38 -> 412116.07 | G15: =G14*'Income Statement'!$J$38 -> 488555.95 | H15: =H14*'Income Statement'!$J$38 -> 436905.44 | I15: =I14*'Income Statement'!$J$38 -> 324832.79 | J15: =J14*'Income Statement'!$J$38 -> 156751.76 | ... L15: =L14*'Income Statement'!$J$38 -> 684688.64
A16: Net Income | B16: =B14-B15 -> 898367 | C16: =C14-C15 -> 896280.78 | D16: =D14-D15 -> 1062524.2 | E16: =E14-E15 -> 1259602.7 | F16: =F14-F15 -> 1493235.6 | G16: =G14-G15 -> 1770203 | H16: =H14-H15 -> 1583055.8 | I16: =I14-I15 -> 1176978.8 | ... L16: =L14-L15 -> 2480858
A18: Balance Sheet Projection
A19: Year | B19: 2025 | C19: 2026 | D19: 2027 | E19: 2028 | F19: 2029 | G19: 2030 | H19: 2031 | I19: 2032 | J19: 2033 | K19: 2034 | L19: 2035
A20: ASSETS
A21: Cash and cash equivalents | B21: =B55-B22-B23-B24-B35 -> 2009463 | C21: =C55-C22-C23-C24-C35 -> 2131469.5 | D21: =D55-D22-D23-D24-D35 -> 2528744.2 | E21: =E55-E22-E23-E24-E35 -> 2999706 | F21: =F55-F22-F23-F24-F35 -> 4154365 | G21: =G55-G22-G23-G24-G35 -> 5523191.9 | H21: =H55-H22-H23-H24-H35 -> 6959748.3 | I21: =I55-I22-I23-I24-I35 -> 8080744.2 | ... L21: =L55-L22-L23-L24-L35 -> 10688629
A22: Trade accounts receivable, net of allowances | B22: 332872 | C22: =C6*('Balance Sheet'!$J$51/365) -> 971564.44 | D22: =D6*('Balance Sheet'!$J$51/365) -> 1151771.6 | E22: =E6*('Balance Sheet'!$J$51/365) -> 1365403.8 | F22: =F6*('Balance Sheet'!$J$51/365) -> 1618660.8 | G22: =G6*('Balance Sheet'!$J$51/365) -> 1918892.3 | H22: =H6*('Balance Sheet'!$J$51/365) -> 2110781.6 | I22: =I6*('Balance Sheet'!$J$51/365) -> 2279644.1 | J22: =J6*('Balance Sheet'!$J$51/365) -> 2439219.2 | ... L22: =L6*('Balance Sheet'!$J$51/365) -> 2689239.2
A23: Inventories | B23: 495226 | C23: =C7 * ('Balance Sheet'!$J$52/365) -> 603246.02 | D23: =D7 * ('Balance Sheet'!$J$52/365) -> 715136.94 | E23: =E7 * ('Balance Sheet'!$J$52/365) -> 847781.55 | F23: =F7 * ('Balance Sheet'!$J$52/365) -> 1005029.3 | G23: =G7 * ('Balance Sheet'!$J$52/365) -> 1191443.5 | H23: =H7 * ('Balance Sheet'!$J$52/365) -> 1412434.1 | I23: =I7 * ('Balance Sheet'!$J$52/365) -> 1674414.4 | J23: =J7 * ('Balance Sheet'!$J$52/365) -> 1984987.2 | ... L23: =L7 * ('Balance Sheet'!$J$52/365) -> 1669753.2
A24: Prepaid expenses & Other Current Assets | B24: 106576 | C24: ='Balance Sheet'!$J$53*Proforma!C4 -> 142160.56 | D24: ='Balance Sheet'!$J$53*Proforma!D4 -> 168528.7 | E24: ='Balance Sheet'!$J$53*Proforma!E4 -> 199787.64 | F24: ='Balance Sheet'!$J$53*Proforma!F4 -> 236844.53 | G24: ='Balance Sheet'!$J$53*Proforma!G4 -> 280774.79 | H24: ='Balance Sheet'!$J$53*Proforma!H4 -> 332853.3 | I24: ='Balance Sheet'!$J$53*Proforma!I4 -> 394591.4 | J24: ='Balance Sheet'!$J$53*Proforma!J4 -> 467780.77 | ... L24: ='Balance Sheet'!$J$53*Proforma!L4 -> 657403.28
A25: Income tax receivable | B25: Assumption: Non-operating; reflects timing of tax refunds, not a recurring operating driver. Including it complicates projections without improving accuracy.
A26: Total current assets | B26: =SUM(B21:B24) -> 2944137 | C26: =SUM(C21:C24) -> 3848440.5 | D26: =SUM(D21:D24) -> 4564181.4 | E26: =SUM(E21:E24) -> 5412679 | F26: =SUM(F21:F24) -> 7014899.7 | G26: =SUM(G21:G24) -> 8914302.5 | H26: =SUM(H21:H24) -> 10815817 | I26: =SUM(I21:I24) -> 12429394 | ... L26: =SUM(L21:L24) -> 15705025
A27: PPE gross | B27: 728563 | C27: =C6*'Balance Sheet'!$J$58 -> 998730.72 | D27: =D6*'Balance Sheet'!$J$58 -> 1183976.7 | E27: =E6*'Balance Sheet'!$J$58 -> 1403582.4 | F27: =F6*'Balance Sheet'!$J$58 -> 1663920.8 | G27: =G6*'Balance Sheet'!$J$58 -> 1972547.2 | H27: =H6*'Balance Sheet'!$J$58 -> 2169801.9 | I27: =I6*'Balance Sheet'!$J$58 -> 2343386.1 | J27: =J6*'Balance Sheet'!$J$58 -> 2507423.1 | ... L27: =L6*'Balance Sheet'!$J$58 -> 2764434
A28: Depreciation | B28: 402964 | C28: ='Balance Sheet'!$J$57*Proforma!C24 -> 547069.98 | D28: ='Balance Sheet'!$J$57*Proforma!D24 -> 648541.29 | E28: ='Balance Sheet'!$J$57*Proforma!E24 -> 768833.65 | F28: ='Balance Sheet'!$J$57*Proforma!F24 -> 911438 | G28: ='Balance Sheet'!$J$57*Proforma!G24 -> 1080492.8 | H28: ='Balance Sheet'!$J$57*Proforma!H24 -> 1280904.1 | I28: ='Balance Sheet'!$J$57*Proforma!I24 -> 1518488.1 | J28: ='Balance Sheet'!$J$57*Proforma!J24 -> 1800139.4 | ... L28: ='Balance Sheet'!$J$57*Proforma!L24 -> 2529855
A29: PPE net | B29: Assumption: Already calculated in PPE Gross. Derived from PPE gross minus accumulated depreciation.
A30: Operating lease assets | B30: 237352 | C30: ='Balance Sheet'!$J$54 -> 214882.5 | D30: ='Balance Sheet'!$J$54 -> 214882.5 | E30: ='Balance Sheet'!$J$54 -> 214882.5 | F30: ='Balance Sheet'!$J$54 -> 214882.5 | G30: ='Balance Sheet'!$J$54 -> 214882.5 | H30: ='Balance Sheet'!$J$54 -> 214882.5 | I30: ='Balance Sheet'!$J$54 -> 214882.5 | J30: ='Balance Sheet'!$J$54 -> 214882.5 | ... L30: ='Balance Sheet'!$J$54 -> 214882.5
A31: Goodwill | B31: 13990 | C31: ='Balance Sheet'!$J$55 -> 13990 | D31: ='Balance Sheet'!$J$55 -> 13990 | E31: ='Balance Sheet'!$J$55 -> 13990 | F31: ='Balance Sheet'!$J$55 -> 13990 | G31: ='Balance Sheet'!$J$55 -> 13990 | H31: ='Balance Sheet'!$J$55 -> 13990 | I31: ='Balance Sheet'!$J$55 -> 13990 | J31: ='Balance Sheet'!$J$55 -> 13990 | ... L31: ='Balance Sheet'!$J$55 -> 13990
A32: Other intangible assets, net of accumulated amortization | B32: 15699 | C32: ='Balance Sheet'!$J$59 -> 34981.333 | D32: ='Balance Sheet'!$J$59 -> 34981.333 | E32: ='Balance Sheet'!$J$59 -> 34981.333 | F32: ='Balance Sheet'!$J$59 -> 34981.333 | G32: ='Balance Sheet'!$J$59 -> 34981.333 | H32: ='Balance Sheet'!$J$59 -> 34981.333 | I32: ='Balance Sheet'!$J$59 -> 34981.333 | J32: ='Balance Sheet'!$J$59 -> 34981.333 | ... L32: ='Balance Sheet'!$J$59 -> 34981.333
A33: Deferred tax assets, net | B33: Assumption: Non-operating; timing difference in taxes. Often excluded in operating asset base for ROIC/valuation.
A34: Other non-current assets | B34: 39546 | C34: =C6*'Balance Sheet'!$J$56 -> 73619.803 | D34: =D6*'Balance Sheet'!$J$56 -> 87274.908 | E34: =E6*'Balance Sheet'!$J$56 -> 103462.78 | F34: =F6*'Balance Sheet'!$J$56 -> 122653.2 | G34: =G6*'Balance Sheet'!$J$56 -> 145403.09 | H34: =H6*'Balance Sheet'!$J$56 -> 159943.4 | I34: =I6*'Balance Sheet'!$J$56 -> 172738.88 | J34: =J6*'Balance Sheet'!$J$56 -> 184830.6 | ... L34: =L6*'Balance Sheet'!$J$56 -> 203775.73
A35: Total Non-current Assets | B35: =B27-B28+B30+B31+B32+B34 -> 632186 | C35: =C27-C28+C30+C31+C32+C34 -> 789134.38 | D35: =D27-D28+D30+D31+D32+D34 -> 886564.16 | E35: =E27-E28+E30+E31+E32+E34 -> 1002065.3 | F35: =F27-F28+F30+F31+F32+F34 -> 1138989.9 | G35: =G27-G28+G30+G31+G32+G34 -> 1301311.3 | H35: =H27-H28+H30+H31+H32+H34 -> 1312695 | I35: =I27-I28+I30+I31+I32+I34 -> 1261490.7 | ... L35: =L27-L28+L30+L31+L32+L34 -> 702208.56
A36: Total assets | B36: =B26+B35 -> 3576323 | C36: =C26+C35 -> 4637574.8 | D36: =D26+D35 -> 5450745.6 | E36: =E26+E35 -> 6414744.3 | F36: =F26+F35 -> 8153889.5 | G36: =G26+G35 -> 10215614 | H36: =H26+H35 -> 12128512 | I36: =I26+I35 -> 13690885 | ... L36: =L26+L35 -> 16407234
A37: LIABILITIES AND STOCKHOLDERS' EQUITY
A38: Trade accounts payable | B38: 417955 | C38: =C7*('Balance Sheet'!$J$63/365) -> 504182.66 | D38: =D7*('Balance Sheet'!$J$63/365) -> 597699.17 | E38: =E7*('Balance Sheet'!$J$63/365) -> 708561.26 | F38: =F7*('Balance Sheet'!$J$63/365) -> 839986.2 | G38: =G7*('Balance Sheet'!$J$63/365) -> 995788.03 | H38: =H7*('Balance Sheet'!$J$63/365) -> 1180488.2 | I38: =I7*('Balance Sheet'!$J$63/365) -> 1399446.8 | J38: =J7*('Balance Sheet'!$J$63/365) -> 1659018.2 | ... L38: =L7*('Balance Sheet'!$J$63/365) -> 1395551
A39: Accrued payroll | B39: 125417 | C39: =C7*'Balance Sheet'!$J$64 -> 143389.27 | D39: =D7*'Balance Sheet'!$J$64 -> 169985.31 | E39: =E7*'Balance Sheet'!$J$64 -> 201514.43 | F39: =F7*'Balance Sheet'!$J$64 -> 238891.61 | G39: =G7*'Balance Sheet'!$J$64 -> 283201.57 | H39: =H7*'Balance Sheet'!$J$64 -> 335730.19 | I39: =I7*'Balance Sheet'!$J$64 -> 398001.9 | J39: =J7*'Balance Sheet'!$J$64 -> 471823.86 | ... L39: =L7*'Balance Sheet'!$J$64 -> 396893.94
A40: Operating lease liabilities | B40: 54453 | C40: ='Balance Sheet'!$J$67*C6 -> 93291.11 | D40: ='Balance Sheet'!$J$67*D6 -> 110594.88 | E40: ='Balance Sheet'!$J$67*E6 -> 131108.17 | F40: ='Balance Sheet'!$J$67*F6 -> 155426.3 | G40: ='Balance Sheet'!$J$67*G6 -> 184254.99 | H40: ='Balance Sheet'!$J$67*H6 -> 202680.49 | I40: ='Balance Sheet'!$J$67*I6 -> 218894.93 | J40: ='Balance Sheet'!$J$67*J6 -> 234217.57 | ... L40: ='Balance Sheet'!$J$67*L6 -> 258224.87
A41: Other accrued expenses | B41: 142120 | C41: =C7*'Balance Sheet'!$J$65 -> 150729.21 | D41: =D7*'Balance Sheet'!$J$65 -> 178686.68 | E41: =E7*'Balance Sheet'!$J$65 -> 211829.74 | F41: =F7*'Balance Sheet'!$J$65 -> 251120.22 | G41: =G7*'Balance Sheet'!$J$65 -> 297698.35 | H41: =H7*'Balance Sheet'!$J$65 -> 352915.86 | I41: =I7*'Balance Sheet'!$J$65 -> 418375.2 | J41: =J7*'Balance Sheet'!$J$65 -> 495976.02 | ... L41: =L7*'Balance Sheet'!$J$65 -> 417210.52
...

Sheet Sheet1
A1: Income Statement (in thousands of dollars)
A2: Year | B2: 2025 | C2: 2026 | D2: 2027 | E2: 2028 | F2: 2029 | G2: 2030 | H2: 2031 | I2: 2032 | J2: 2033 | K2: 2034 | L2: 2035
A3: Net sales | B3: 4985612 | C3: =B3*(1+'Income Statement'!$J$33) -> 5910350.4 | D3: =C3*(1+'Income Statement'!$J$33) -> 7006610.5 | E3: =D3*(1+'Income Statement'!$J$33) -> 8306206.5 | F3: =E3*(1+'Income Statement'!$J$33) -> 9846853.5 | G3: =F3*(1+'Income Statement'!$J$33) -> 11673262 | H3: =G3*(1+'Income Statement'!$J$33) -> 13838435 | I3: =H3*(1+'Income Statement'!$J$33) -> 16405207 | J3: =I3*(1+'Income Statement'!$J$33) -> 19448068 | ... L3: =K3*(1+'Income Statement'!$J$33) -> 27331658
A4: Cost of Sales | B4: 2099949 | C4: ='Income Statement'!$J$36*Proforma!C3 -> 2752309.9 | D4: ='Income Statement'!$J$36*Proforma!D3 -> 3262812.3 | E4: ='Income Statement'!$J$36*Proforma!E3 -> 3868003.3 | F4: ='Income Statement'!$J$36*Proforma!F3 -> 4585446 | G4: ='Income Statement'!$J$36*Proforma!G3 -> 5435961.1 | H4: ='Income Statement'!$J$36*Proforma!H3 -> 6444230.8 | I4: ='Income Statement'!$J$36*Proforma!I3 -> 7639515.8 | J4: ='Income Statement'!$J$36*Proforma!J3 -> 9056504.1 | ... L4: ='Income Statement'!$J$36*Proforma!L3 -> 12727705
A5: Gross Profit | B5: =B3-B4 -> 2885663 | C5: =C3-C4 -> 3158040.4 | D5: =D3-D4 -> 3743798.2 | E5: =E3-E4 -> 4438203.2 | F5: =F3-F4 -> 5261407.4 | G5: =G3-G4 -> 6237300.7 | H5: =H3-H4 -> 7394204.1 | I5: =I3-I4 -> 8765691.5 | ... L5: =L3-L4 -> 14603953
A6: Selling, general, and administrative expenses | B6: 1706571 | C6: =C3*'Income Statement'!$J$37 -> 2006863.1 | D6: =D3*'Income Statement'!$J$37 -> 2379098.9 | E6: =E3*'Income Statement'!$J$37 -> 2820377.5 | F6: =F3*'Income Statement'!$J$37 -> 3343505.1 | G6: =G3*'Income Statement'!$J$37 -> 3963663.1 | H6: =H3*'Income Statement'!$J$37 -> 4698849 | I6: =I3*'Income Statement'!$J$37 -> 5570398.1 | J6: =J3*'Income Statement'!$J$37 -> 6603603.4 | ... L6: =L3*'Income Statement'!$J$37 -> 9280481
A7: EBIT, Earnings before interest & taxes | B7: =B5-B6 -> 1179092 | C7: =C5-C6 -> 1151177.4 | D7: =D5-D6 -> 1364699.4 | E7: =E5-E6 -> 1617825.7 | F7: =F5-F6 -> 1917902.3 | G7: =G5-G6 -> 2273637.6 | H7: =H5-H6 -> 2695355.1 | I7: =I5-I6 -> 3195293.4 | ... L7: =L5-L6 -> 5323472.1
A8: Interest income | B8: Assumption: Other income, net is excluded from the pro forma projections because it consists primarily of non-operating and non-recurring items (e.g., foreign currency gains/losses, asset sale gains/losses). These items are not reflective of the company’s ongoing operations and are immaterial relative to total EBIT.
A9: Interest expense | B9: 3517 | C9: =C3*'Income Statement'!$J$40 -> 7533.2585 | D9: =D3*'Income Statement'!$J$40 -> 8930.5379 | E9: =E3*'Income Statement'!$J$40 -> 10586.987 | F9: =F3*'Income Statement'!$J$40 -> 12550.676 | G9: =G3*'Income Statement'!$J$40 -> 14878.593 | H9: =H3*'Income Statement'!$J$40 -> 17638.296 | I9: =I3*'Income Statement'!$J$40 -> 20909.872 | J9: =J3*'Income Statement'!$J$40 -> 24788.264 | ... L9: =L3*'Income Statement'!$J$40 -> 34836.588
A10: Other income, net | B10: Assumption: Other income excluded due to immateriality and non-recurring nature.
A11: EBT, Income before income taxes | B11: =B7-B9 -> 1175575 | C11: =C7-C9 -> 1143644.1 | D11: =D7-D9 -> 1355768.8 | E11: =E7-E9 -> 1607238.7 | F11: =F7-F9 -> 1905351.7 | G11: =G7-G9 -> 2258759 | H11: =H7-H9 -> 2677716.8 | I11: =I7-I9 -> 3174383.5 | ... L11: =L7-L9 -> 5288635.6
A12: Income tax expense | B12: 277208 | C12: =C11*'Income Statement'!$J$38 -> 247363.32 | D12: =D11*'Income Statement'!$J$38 -> 293244.62 | E12: =E11*'Income Statement'!$J$38 -> 347636.05 | F12: =F11*'Income Statement'!$J$38 -> 412116.07 | G12: =G11*'Income Statement'!$J$38 -> 488555.95 | H12: =H11*'Income Statement'!$J$38 -> 579174 | I12: =I11*'Income Statement'!$J$38 -> 686600.01 | J12: =J11*'Income Statement'!$J$38 -> 813951.55 | ... L12: =L11*'Income Statement'!$J$38 -> 1143900
A13: Net Income | B13: =B11-B12 -> 898367 | C13: =C11-C12 -> 896280.78 | D13: =D11-D12 -> 1062524.2 | E13: =E11-E12 -> 1259602.7 | F13: =F11-F12 -> 1493235.6 | G13: =G11-G12 -> 1770203 | H13: =H11-H12 -> 2098542.8 | I13: =I11-I12 -> 2487783.5 | ... L13: =L11-L12 -> 4144735.6
A15: Balance Sheet (in thousands of dollars)
A16: Year | B16: 2025 | C16: 2026 | D16: 2027 | E16: 2028 | F16: 2029 | G16: 2030 | H16: 2031 | I16: 2032 | J16: 2033 | K16: 2034 | L16: 2035
A17: ASSETS
A18: Cash and cash equivalents | B18: =1889188 -> 1889188 | C18: =I13 -> 2487783.5 | D18: =('Income Statement'!$J$43*Proforma!D3) -> 2335668.7 | E18: =('Income Statement'!$J$43*Proforma!E3) -> 2768891.9 | F18: =('Income Statement'!$J$43*Proforma!F3)+693973 -> 3976442.9 | G18: =('Income Statement'!$J$43*Proforma!G3) -> 3891307 | H18: =('Income Statement'!$J$43*Proforma!H3)+1893949 -> 6507021.1 | I18: =('Income Statement'!$J$43*Proforma!I3) -> 5468711.3 | J18: =('Income Statement'!$J$43*Proforma!J3)+3580353 -> 10063409 | K18: =('Income Statement'!$J$43*Proforma!K3) -> 7685541.9 | L18: =('Income Statement'!$J$43*Proforma!L3)+5950369 -> 15061436
A19: Trade accounts receivable, net of allowances | B19: 332872 | C19: =C3*('Balance Sheet'!$J$51/365) -> 971564.44 | D19: =D3*('Balance Sheet'!$J$51/365) -> 1151771.6 | E19: =E3*('Balance Sheet'!$J$51/365) -> 1365403.8 | F19: =F3*('Balance Sheet'!$J$51/365) -> 1618660.8 | G19: =G3*('Balance Sheet'!$J$51/365) -> 1918892.3 | H19: =H3*('Balance Sheet'!$J$51/365) -> 2274811.2 | I19: =I3*('Balance Sheet'!$J$51/365) -> 2696746.4 | J19: =J3*('Balance Sheet'!$J$51/365) -> 3196942.7 | ... L19: =L3*('Balance Sheet'!$J$51/365) -> 4492875.2
A20: Inventories | B20: 495226 | C20: =C4 * ('Balance Sheet'!$J$52/365) -> 603246.02 | D20: =D4 * ('Balance Sheet'!$J$52/365) -> 715136.94 | E20: =E4 * ('Balance Sheet'!$J$52/365) -> 847781.55 | F20: =F4 * ('Balance Sheet'!$J$52/365) -> 1005029.3 | G20: =G4 * ('Balance Sheet'!$J$52/365) -> 1191443.5 | H20: =H4 * ('Balance Sheet'!$J$52/365) -> 1412434.1 | I20: =I4 * ('Balance Sheet'!$J$52/365) -> 1674414.4 | J20: =J4 * ('Balance Sheet'!$J$52/365) -> 1984987.2 | ... L20: =L4 * ('Balance Sheet'!$J$52/365) -> 2789633.9
A21: Prepaid expenses & Other Current Assets | B21: 106576 | C21: ='Balance Sheet'!$J$53*Proforma!C4 -> 142160.56 | D21: ='Balance Sheet'!$J$53*Proforma!D4 -> 168528.7 | E21: ='Balance Sheet'!$J$53*Proforma!E4 -> 199787.64 | F21: ='Balance Sheet'!$J$53*Proforma!F4 -> 236844.53 | G21: ='Balance Sheet'!$J$53*Proforma!G4 -> 280774.79 | H21: ='Balance Sheet'!$J$53*Proforma!H4 -> 332853.3 | I21: ='Balance Sheet'!$J$53*Proforma!I4 -> 394591.4 | J21: ='Balance Sheet'!$J$53*Proforma!J4 -> 467780.77 | ... L21: ='Balance Sheet'!$J$53*Proforma!L4 -> 657403.28
A22: Income tax receivable | B22: Non-operating; reflects timing of tax refunds, not a recurring operating driver. Including it complicates projections without improving accuracy.
