Workbook
Name IQ_CH: 110000
Name IQ_CQ: 5000
Name IQ_CY: 10000
Name IQ_DAILY: 500000
Name IQ_FH: 100000
Name IQ_FQ: 500
Name IQ_FY: 1000
Name IQ_LTM: 2000
Name IQ_MONTH: 15000
Name IQ_NTM: 6000
Name IQ_WEEK: 50000
Name IQ_YTD: 3000

Sheet Introduction
B2: Student Housing Project
B3: Completed as a collaborative team effort by: | D3: HongAn, Shaira, & Adarsh
B5: Formatting Key:
B6: Inputs
B7: Referenced
B8: Formulas

Sheet Assumptions and Key Inputs
B2: Key case assumptions used
B4: Current Income Statement
B5: Rental Income | C5: USD | D5: 428400
B6: Parking Income | D6: 17550
B7: Potential Gross Income | D7: =SUM(D5:D6) -> 445950
B8: Vacancy Loss | C8: 0.02 | D8: =$C$8*-D7 -> -8919
B9: Credit Loss | C9: 0.01 | D9: =$C$9*-D7 -> -4459.5
B10: Effective Gross Income | D10: =SUM(D7:D9) -> 432571.5
B11: Operating Expenses excl Depr | D11: -161387.96
B12: Net Operating Income | C12: USD | D12: =D10+D11 -> 271183.54
B15: Construction Loan | D15: Inputs | E15: Justification
B16: Building Square footage | C16: sqft | D16: 22950 | E16: Given for Madison
B17: Cost per Square Foot | C17: USD | D17: 109 | E17: Given for the comparable, Juniper Vista
B18: Hard Construction Costs | C18: USD | D18: =D16*D17 -> 2501550
B19: Demolition | C19: USD | D19: 75000
B20: Soft Construction Costs | C20: USD | D20: =3.25%*D18 -> 81300.375
B21: Construction / soft cost period | C21: months | D21: 20 | E21: 1.7 years per slide Jan 2013 to Aug 2014
B23: Housing
B24: Assuming fiscal year operates from 9/1 - 8/31 | E24: Based on school year
B25: Exit Cap | C25: % | D25: 0.065 | E25: Given from the case
B26: Long-Run Rent Growth, NOI | C26: % | D26: 0.03 | E26: Given from the case
B27: CapEx/NOI | C27: % | D27: 0.2 | E27: Given from the case
B28: Discount Rate | C28: % | D28: 0.082 | E28: Given from the case
B29: Risk Free Rate | C29: % | D29: 0.03 | E29: Given from the case
B30: Vacancy Loss | C30: % | D30: 0.02 | E30: Given from the case
B31: Credit Loss | C31: % | D31: 0.01 | E31: Given from the case
B32: Expenses | C32: % | D32: =-D11/D10 -> 0.37308967 | E32: Calculated based of projected EGI
B33: Selling Expense | C33: % | D33: 0.02 | E33: Assuming brokerage cost of 2 to 3% cost. Using 0% will inflate the IRR and BTER
B35: Mortgage
B36: Land Acquisition Cost | C36: USD | D36: =366223*3 -> 1098669 | E36: Calculated as 3x value of comparable properties
B37: Value of Construction Loan at Completion | C37: USD | D37: ='Construction Loan'!E23 -> 2664495 | E37: Calculated in | F37: Construction Loan Sheet
B38: Completed Asset Value | C38: USD | D38: =SUM(D36:D37) -> 3763164
B39: Loan-To-Value | C39: % | D39: 0.75 | E39: Given in case
B40: Principal | C40: USD | D40: =D39*D38 -> 2822373
B41: Current Mortgage Rates | C41: % | D41: 0.04625
B42: Amortization Period | C42: years | D42: 25
B44: Debt Payment | C44: USD | D44: =PMT(D41/12,D42*12,-D40)*12 -> 190663.02
B45: NOI | C45: USD | D45: ='NOI at Completion'!G14 -> 271183.54
B46: DCR | D46: =D45/D44 -> 1.4223185
B47: Minimum DCR | D47: 1.25
...

Sheet 1. Madison Analysis
B2: Benefits: | C2: Costs & Risks:
B3: Demand/Supply Imbalance: Madison is home to the University of Wisconsin-Madison (a major Big Ten school). Large universities often have a chronic shortage of on-campus housing, forcing students into the local market. | C3: Seasonality: The major risk in student housing is the 12-month lease cycle. If you miss the "lease-up" window in August/September, you may face high vacancy for an entire year.
B4: The "Luxury" Niche: As seen in Slater’s Florida success, there is a growing demographic of students (and parents) willing to pay premiums for "luxury" amenities (ensuite bathrooms, gyms, pools) that older stock housing lacks. | C4: Turnover Costs: Student housing requires heavy "turn" costs (cleaning, painting, repairs) every August due to the intense wear and tear compared to conventional multifamily.
B5: Stability: Student housing is often considered recession-resistant. Enrollments often go up during economic downturns, securing the tenant base. | C5: Specific Market Risk: Madison has specific zoning restrictions and a colder climate (impacting construction windows) compared to Florida.
B6: Economic Surge: The city which held a strong presence in government and education affiliations, have noticed a strong representation of high-tech firms. Strong educated work force, with an unemployment rate of only 3.5% in the area. This city is ranked in top 10 for job growth. | C6: Concentration Risk: The asset is entirely dependent on the success and enrollment policies of a single institution (UW Madison). However, this is not an immediate risk with the given housing crisis at the university relying on the UW-Madison Private Housing Connections program.

Sheet 2. Feasibility Test
B3: Given:
B4: Exhibit 15 | C4: Based off city of Madison
C5: # of Units | D5: Bedrooms | E5: Sq ft | F5: Rent/MO/Unit | G5: Rent/Year | H5: Rent/MO/Room/Unit
B6: 2Br/2Ba | C6: 9 | D6: =C6*2 -> 18 | E6: 1150 | F6: 1800 | G6: =F6*12 -> 21600 | H6: 900
B7: 4Br/4Ba | C7: 6 | D7: =C7*4 -> 24 | E7: 1600 | F7: 3250 | G7: =F7*12 -> 39000 | H7: 812.5
B8: Total | C8: =SUM(C6:C7) -> 15 | D8: =SUM(D6:D7) -> 42 | E8: =SUMPRODUCT(C6:C7,E6:E7) -> 19950 | F8: =SUMPRODUCT(F6:F7,C6:C7) -> 35700 | G8: =F8*12 -> 428400 | H8: 850
B10: Parking | C10: 15 | F10: 97.5 | G10: 1170
B11: Total | C11: 15 | F11: 1462.5 | G11: 17550
B13: Available parking space per bedroom | C13: =C11/D8 -> 0.35714286
B15: Our calculation:
B16: Exhibit 15 | C16: Based off city of Madison
C17: # of Units | D17: Bedrooms | E17: Sq ft | F17: Rent/MO | G17: Rent/Year | H17: Rent/MO/Room
B18: 2Br/2Ba | C18: 9 | D18: =C18*2 -> 18 | E18: 1150 | F18: =F6*C18 -> 16200 | G18: =F18*12 -> 194400 | H18: =G18/(12*C18) -> 1800
B19: 4Br/4Ba | C19: 6 | D19: =C19*4 -> 24 | E19: 1600 | F19: =F7*C19 -> 19500 | G19: =F19*12 -> 234000 | H19: 812.5
B20: Total | C20: =SUM(C18:C19) -> 15 | D20: =SUM(D18:D19) -> 42 | E20: =SUMPRODUCT(C18:C19,E18:E19) -> 19950 | F20: =SUM(F18:F19) -> 35700 | G20: =F20*12 -> 428400 | H20: 850
B22: Parking | C22: 15 | F22: 97.5 | G22: 1170
B23: Total | C23: 15 | F23: 1462.5 | G23: 17550
B26: Slater and Lenard’s feasibility analysis gives a quick look at whether their development project might work financially. They used simple calculations based on expected rents, expenses, and loan terms to figure out how much they could spend on buying land. Their numbers suggest the project could be profitable because the estimated land cost is less than what they can afford. This kind of quick estimate is helpful to get a rough idea early on. However, many of their assumptions - like the building being fully rented right away and land prices staying average - are very optimistic and don’t consider real-world challenges.
B31: There are several risks the analysis doesn’t fully address. It assumes the project will generate income immediately, which ignores possible construction delays or problems finding tenants. The loan terms they use are fixed, but in reality, interest rates can change. Also, buying several properties for land might cost more or be harder than expected. Plus, their rent and parking income estimates come from ads, which may not reflect actual deals. Overall, while this analysis is a good first step, it is too simple to rely on alone. A more detailed study that looks at market demand, risks, and different financial scenarios is needed to make a smarter investment decision.

Sheet 3. Yield on Cost
B2: Permenant Debt Financing
B4: NOI at Completion (net of CapEx) | C4: ='4. Pro Forma NPV'!H34+'4. Pro Forma NPV'!H36 -> 230158.89
B5: Yield on Cost | C5: =5.2% -> 0.052
B6: Total Development Cost - Possible | C6: =C4/C5 -> 4426132.6
B8: Land Acquisition Cost | C8: =366223*3 -> 1098669
B9: Value of Construction Loan | C9: ='Construction Loan'!E23 -> 2664495
B10: Total Development Cost - Actual | C10: =SUM(C8:C9) -> 3763164
B12: Therefore, Project is feasible
B14: Merits | G14: Disadvantages
B15: Simple & Clear Measure of Profitability: It shows how much cash flow the project will generate compared to all the money spent building it, helping decide if the project is worth doing | G15: Ignores Time Value of Money: The approach does not discount future cash flows or account for the timing of costs and income, which can overstate the project’s profitability
B18: Focuses on Finished Project Performance: By looking at cash flow after construction, it avoids confusing numbers from the building phase and shows what the property will really earn once it’s running. | G18: Assumes Immediate Stabilization: It assumes the property reaches full occupancy and market rents at completion, ignoring lease-up risks such as vacancies, rent concessions, and market fluctuations.
B21: Standardizes Comparing Projects: Because it gives a simple percentage return, it helps quickly compare different projects to see which ones might make more money. | G21: Excludes Leverage and Financing Effects: Because it is an unlevered metric, it does not consider how debt impacts returns to equity investors, which can distort actual investment performance.

Sheet 4. Pro Forma NPV
B2: Pro Forma | F2: 2012 | G2: =F2+1 -> 2013 | H2: =G2+1 -> 2014 | I2: =H2+1 -> 2015 | J2: =I2+1 -> 2016 | K2: =J2+1 -> 2017 | L2: =K2+1 -> 2018 | M2: =L2+1 -> 2019 | N2: =M2+1 -> 2020 | ... S2: =R2+1 -> 2025
B4: Years | F4: 0 | G4: 1 | H4: 2 | I4: =H4+1 -> 3 | J4: =I4+1 -> 4 | K4: =J4+1 -> 5 | L4: =K4+1 -> 6 | M4: =L4+1 -> 7 | N4: =M4+1 -> 8 | O4: =N4+1 -> 9 | P4: =O4+1 -> 10 | ... S4: =R4+1 -> 13
B5: Adjusting for growth | C5: 0.03 | F5: =1*($C$5)^F4 -> 1 | G5: =F5*(1+$C$5) -> 1.03 | H5: =G5*(1+$C$5) -> 1.0609 | I5: =H5*(1+$C$5) -> 1.092727 | J5: =I5*(1+$C$5) -> 1.1255088 | K5: =J5*(1+$C$5) -> 1.1592741 | L5: =K5*(1+$C$5) -> 1.1940523 | M5: =L5*(1+$C$5) -> 1.2298739 | N5: =M5*(1+$C$5) -> 1.2667701 | ... S5: =R5*(1+$C$5) -> 1.4685337
B7: Land Acquisition Cost | C7: ='Assumptions and Key Inputs'!D36 -> 1098669 | F7: =-C7 -> -1098669
B8: Loan Payoff | C8: ='Assumptions and Key Inputs'!D37 -> 2664495 | H8: =-C8 -> -2664495
B9: Permenant Loan | C9: ='Assumptions and Key Inputs'!D40 -> 2822373 | H9: =C9 -> 2822373
B11: Rental Income | C11: ='Assumptions and Key Inputs'!D5 -> 428400 | F11: =C11 -> 428400 | H11: =$C$11*H5 -> 454489.56 | I11: =$C$11*I5 -> 468124.25 | J11: =$C$11*J5 -> 482167.97 | K11: =$C$11*K5 -> 496633.01 | L11: =$C$11*L5 -> 511532 | M11: =$C$11*M5 -> 526877.96 | N11: =$C$11*N5 -> 542684.3 | O11: =$C$11*O5 -> 558964.83 | ... R11: =$C$11*R5 -> 610795.96
B12: Parking Income | C12: ='Assumptions and Key Inputs'!D6 -> 17550 | F12: =C12 -> 17550 | H12: =$C$12*H5 -> 18618.795 | I12: =$C$12*I5 -> 19177.359 | J12: =$C$12*J5 -> 19752.68 | K12: =$C$12*K5 -> 20345.26 | L12: =$C$12*L5 -> 20955.618 | M12: =$C$12*M5 -> 21584.286 | N12: =$C$12*N5 -> 22231.815 | O12: =$C$12*O5 -> 22898.769 | ... R12: =$C$12*R5 -> 25022.104
B13: Potential Gross Income | F13: =SUM(F11:F12) -> 445950 | H13: =SUM(H11:H12) -> 473108.35 | I13: =SUM(I11:I12) -> 487301.61 | J13: =SUM(J11:J12) -> 501920.65 | K13: =SUM(K11:K12) -> 516978.27 | L13: =SUM(L11:L12) -> 532487.62 | M13: =SUM(M11:M12) -> 548462.25 | N13: =SUM(N11:N12) -> 564916.12 | O13: =SUM(O11:O12) -> 581863.6 | ... R13: =SUM(R11:R12) -> 635818.07
B15: Vacancy Loss | C15: 0.02 | F15: =-(F13*$C$15) -> -8919 | H15: =-(H13*$C$15) -> -9462.1671 | I15: =-(I13*$C$15) -> -9746.0321 | J15: =-(J13*$C$15) -> -10038.413 | K15: =-(K13*$C$15) -> -10339.565 | L15: =-(L13*$C$15) -> -10649.752 | M15: =-(M13*$C$15) -> -10969.245 | N15: =-(N13*$C$15) -> -11298.322 | O15: =-(O13*$C$15) -> -11637.272 | ... R15: =-(R13*$C$15) -> -12716.361
B16: Credit Loss | C16: 0.01 | F16: =-(F13*$C$16) -> -4459.5 | H16: =-(H13*$C$16) -> -4731.0836 | I16: =-(I13*$C$16) -> -4873.0161 | J16: =-(J13*$C$16) -> -5019.2065 | K16: =-(K13*$C$16) -> -5169.7827 | L16: =-(L13*$C$16) -> -5324.8762 | M16: =-(M13*$C$16) -> -5484.6225 | N16: =-(N13*$C$16) -> -5649.1612 | O16: =-(O13*$C$16) -> -5818.636 | ... R16: =-(R13*$C$16) -> -6358.1807
B17: Effective Gross Income | F17: =SUM(F13,F15:F16) -> 432571.5 | H17: =SUM(H13,H15:H16) -> 458915.1 | I17: =SUM(I13,I15:I16) -> 472682.56 | J17: =SUM(J13,J15:J16) -> 486863.03 | K17: =SUM(K13,K15:K16) -> 501468.93 | L17: =SUM(L13,L15:L16) -> 516512.99 | M17: =SUM(M13,M15:M16) -> 532008.38 | N17: =SUM(N13,N15:N16) -> 547968.63 | O17: =SUM(O13,O15:O16) -> 564407.69 | ... R17: =SUM(R13,R15:R16) -> 616743.53
B18: Expenses | C18: ='Assumptions and Key Inputs'!D32 -> 0.37308967 | F18: =-SUM(F19:F33) -> -161387.96 | H18: =-H17*$C$18 -> -171216.49 | I18: =-I17*$C$18 -> -176352.98 | J18: =-J17*$C$18 -> -181643.57 | K18: =-K17*$C$18 -> -187092.88 | L18: =-L17*$C$18 -> -192705.66 | M18: =-M17*$C$18 -> -198486.83 | N18: =-N17*$C$18 -> -204441.44 | O18: =-O17*$C$18 -> -210574.68 | ... R18: =-R17*$C$18 -> -230100.64
B19: Real Estate Tax | F19: 86725.25
B20: Common Area Electric | F20: 3500
B21: Common Area Gas | F21: 2000
B22: Common Area Cleaning | F22: 2600
B23: Landscaping Maintenance | F23: 1800
B24: Landscaping Irrigation | F24: 696.99
B25: Exterminating | F25: 600
B26: Snow Removal | F26: 3000
B27: Garbage Service | F27: 2400
B28: HVAC Service Contract | F28: 2100
B29: General Maintenance | F29: 3000
B30: Unit Turnover Cleaning | F30: 7500
... B33: Security System | F33: 860
B34: Net Operating Income | F34: =SUM(F17,F18) -> 271183.54 | H34: =SUM(H17,H18) -> 287698.62 | I34: =SUM(I17,I18) -> 296329.58 | J34: =SUM(J17,J18) -> 305219.46 | K34: =SUM(K17,K18) -> 314376.05 | L34: =SUM(L17,L18) -> 323807.33 | M34: =SUM(M17,M18) -> 333521.55 | N34: =SUM(N17,N18) -> 343527.2 | O34: =SUM(O17,O18) -> 353833.01 | ... R34: =SUM(R17,R18) -> 386642.88 | S34: =R34*(1+C5) -> 398242.17
B36: Capital Expenditure | C36: ='Assumptions and Key Inputs'!D27 -> 0.2 | F36: =-F34*$C$36 -> -54236.708 | H36: =-H34*$C$36 -> -57539.724 | I36: =-I34*$C$36 -> -59265.915 | J36: =-J34*$C$36 -> -61043.893 | K36: =-K34*$C$36 -> -62875.209 | L36: =-L34*$C$36 -> -64761.466 | M36: =-M34*$C$36 -> -66704.31 | N36: =-N34*$C$36 -> -68705.439 | O36: =-O34*$C$36 -> -70766.602 | ... R36: =-R34*$C$36 -> -77328.577
B37: Debt Service | C37: ='Assumptions and Key Inputs'!D44 -> 190663.02 | F37: =-$C$37 -> -190663.02 | H37: =-$C$37 -> -190663.02 | I37: =-$C$37 -> -190663.02 | J37: =-$C$37 -> -190663.02 | K37: =-$C$37 -> -190663.02 | L37: =-$C$37 -> -190663.02 | M37: =-$C$37 -> -190663.02 | N37: =-$C$37 -> -190663.02 | O37: =-$C$37 -> -190663.02 | ... R37: =-$C$37 -> -190663.02
B38: Before Tax Cash Flow | F38: =SUM(F34:F37) -> 26283.815 | H38: =SUM(H34:H37) -> 39495.877 | I38: =SUM(I34:I37) -> 46400.644 | J38: =SUM(J34:J37) -> 53512.554 | K38: =SUM(K34:K37) -> 60837.821 | L38: =SUM(L34:L37) -> 68382.846 | M38: =SUM(M34:M37) -> 76154.222 | N38: =SUM(N34:N37) -> 84158.739 | O38: =SUM(O34:O37) -> 92403.392 | ... R38: =SUM(R34:R37) -> 118651.29
I39: =(I34-H34)/H34 -> 0.03 | J39: =(J34-I34)/I34 -> 0.03 | K39: =(K34-J34)/J34 -> 0.03 | L39: =(L34-K34)/K34 -> 0.03 | M39: =(M34-L34)/L34 -> 0.03 | N39: =(N34-M34)/M34 -> 0.03 | O39: =(O34-N34)/N34 -> 0.03 | P39: =(P34-O34)/O34 -> 0.03 | ... S39: =(S34-R34)/R34 -> 0.03
B41: Selling Price at year 15 | C41: ='Assumptions and Key Inputs'!D25 -> 0.065 | R41: =S34/C41 -> 6126802.6
B42: Selling expenses | C42: ='Assumptions and Key Inputs'!D33 -> 0.02 | R42: =C42*'4. Pro Forma NPV'!R41 -> 122536.05
B43: Net Sale Proceeds | R43: =R41-R42 -> 6004266.6
B44: Remaining Mortgage Balance | C44: ='Assumptions and Key Inputs'!D41 -> 0.04625 | R44: =PV(C44/12,(25-10)*12,-C37/12) -> 2059715.2
B45: Before Tax Cash Flow | R45: =R43-R44 -> 3944551.4
B47: Total Cash Flow | F47: =F7+F8+F9 -> -1098669 | G47: =G7+G8+G9 -> 0 | H47: =H7+H8+H9+H38+H45 -> 197373.88 | I47: =I7+I8+I9+I38+I45 -> 46400.644 | J47: =J7+J8+J9+J38+J45 -> 53512.554 | K47: =K7+K8+K9+K38+K45 -> 60837.821 | L47: =L7+L8+L9+L38+L45 -> 68382.846 | M47: =M7+M8+M9+M38+M45 -> 76154.222 | N47: =N7+N8+N9+N38+N45 -> 84158.739 | O47: =O7+O8+O9+O38+O45 -> 92403.392 | ... R47: =R7+R8+R9+R38+R45 -> 4063202.7
B48: Present Value (discounted monthly) | C48: ='Assumptions and Key Inputs'!D28 -> 0.082 | F48: =PV($C$48/12,F4*12,,-F47) -> -1098669 | G48: 0 | H48: =PV($C$48/12,H4*12,,-H47) -> 167612.97 | I48: =PV($C$48/12,I4*12,,-I47) -> 36312.064 | J48: =PV($C$48/12,J4*12,,-J47) -> 38591.493 | K48: =PV($C$48/12,K4*12,,-K47) -> 40431.377 | L48: =PV($C$48/12,L4*12,,-L47) -> 41879.456 | M48: =PV($C$48/12,M4*12,,-M47) -> 42979.05 | N48: =PV($C$48/12,N4*12,,-N47) -> 43769.444 | O48: =PV($C$48/12,O4*12,,-O47) -> 44286.228 | ... R48: =PV($C$48/12,R4*12,,-R47) -> 1523969.2
B50: Net Present Value | F50: =SUM(F48:R48) -> 970348.73
B51: IRR | F51: =IRR(F47:R47) -> 0.15662032

Sheet Supporting Documents -->

Sheet Construction Loan
B2: Projection period | G2: 41274 | H2: 41305 | I2: 41333 | J2: 41364 | K2: 41394 | L2: 41425 | M2: 41455 | N2: 41486 | O2: 41517 | P2: 41547 | Q2: 41578 | R2: 41608 | S2: 41639 | T2: 41670 | U2: 41698 | V2: 41729 | W2: 41759 | X2: 41790 | Y2: 41820 | Z2: 41851 | AA2: 41882 | AB2: 41912 | AC2: 41943 | AD2: 41973 | AE2: 42004 | AF2: 42035 | AG2: 42063 | AH2: 42094 | AI2: 42124 | AJ2: 42155 | AK2: 42185 | AL2: 42216 | AM2: 42247 | AN2: 42277 | AO2: 42308 | AP2: 42338 | AQ2: 42369 | AR2: 42400 | AS2: 42429 | AT2: 42460 | AU2: 42490 | AV2: 42521 | AW2: 42551 | AX2: 42582 | AY2: 42613 | AZ2: 42643 | BA2: 42674 | BB2: 42704 | BC2: 42735 | BD2: 42766 | BE2: 42794 | BF2: 42825 | BG2: 42855 | BH2: 42886 | BI2: 42916 | BJ2: 42947 | BK2: 42978 | BL2: 43008 | BM2: 43039 | BN2: 43069 | BO2: 43100 | BP2: 43131 | BQ2: 43159 | BR2: 43190 | BS2: 43220 | BT2: 43251 | BU2: 43281 | BV2: 43312 | BW2: 43343 | BX2: 43373 | BY2: 43404 | BZ2: 43434 | CA2: 43465 | CB2: 43496 | CC2: 43524 | CD2: 43555 | CE2: 43585 | CF2: 43616 | CG2: 43646 | CH2: 43677 | CI2: 43708 | CJ2: 43738 | CK2: 43769 | CL2: 43799 | CM2: 43830 | CN2: 43861 | CO2: 43890 | CP2: 43921 | CQ2: 43951 | CR2: 43982 | CS2: 44012 | CT2: 44043 | CU2: 44074 | CV2: 44104 | CW2: 44135 | CX2: 44165 | CY2: 44196 | CZ2: 44227 | DA2: 44255 | DB2: 44286 | DC2: 44316 | DD2: 44347 | DE2: 44377 | DF2: 44408 | DG2: 44439 | DH2: 44469 | DI2: 44500 | DJ2: 44530 | DK2: 44561 | DL2: 44592 | DM2: 44620 | DN2: 44651 | DO2: 44681 | DP2: 44712 | DQ2: 44742 | DR2: 44773 | DS2: 44804 | DT2: 44834 | DU2: 44865 | DV2: 44895 | DW2: 44926 | DX2: 44957 | DY2: 44985 | DZ2: 45016 | EA2: 45046 | EB2: 45077 | EC2: 45107 | ED2: 45138 | EE2: 45169 | EF2: 45199 | EG2: 45230 | EH2: 45260 | EI2: 45291 | EJ2: 45322 | EK2: 45351 | EL2: 45382 | EM2: 45412 | EN2: 45443 | EO2: 45473 | EP2: 45504 | EQ2: 45535 | ER2: 45565 | ES2: 45596 | ET2: 45626 | EU2: 45657 | EV2: 45688 | EW2: 45716 | EX2: 45747 | EY2: 45777 | EZ2: 45808 | FA2: 45838 | FB2: 45869 | FC2: 45900 | FD2: 45930 | FE2: 45961 | FF2: 45991 | FG2: 46022 | FH2: 46053 | FI2: 46081 | FJ2: 46112 | FK2: 46142 | FL2: 46173 | FM2: 46203 | FN2: 46234 | FO2: 46265 | FP2: 46295 | FQ2: 46326 | FR2: 46356 | FS2: 46387 | FT2: 46418 | FU2: 46446 | FV2: 46477 | FW2: 46507 | FX2: 46538 | FY2: 46568 | FZ2: 46599 | GA2: 46630 | GB2: 46660 | GC2: 46691 | GD2: 46721 | GE2: 46752 | GF2: 46783 | GG2: 46812 | GH2: 46843 | GI2: 46873 | GJ2: 46904 | GK2: 46934 | GL2: 46965 | GM2: 46996 | GN2: 47026 | GO2: 47057 | GP2: 47087 | GQ2: 47118 | GR2: 47149 | GS2: 47177 | GT2: 47208 | GU2: 47238 | GV2: 47269 | GW2: 47299 | GX2: 47330 | GY2: 47361 | GZ2: 47391 | HA2: 47422 | HB2: 47452 | HC2: 47483 | HD2: 47514 | HE2: 47542 | HF2: 47573 | HG2: 47603 | HH2: 47634 | HI2: 47664 | HJ2: 47695 | HK2: 47726 | HL2: 47756 | HM2: 47787 | HN2: 47817 | HO2: 47848 | HP2: 47879 | HQ2: 47907 | HR2: 47938 | HS2: 47968 | HT2: 47999 | HU2: 48029 | HV2: 48060 | HW2: 48091 | HX2: 48121 | HY2: 48152 | HZ2: 48182 | IA2: 48213 | IB2: 48244 | IC2: 48273 | ID2: 48304 | IE2: 48334 | IF2: 48365 | IG2: 48395 | IH2: 48426 | II2: 48457 | IJ2: 48487 | IK2: 48518 | IL2: 48548 | IM2: 48579 | IN2: 48610 | IO2: 48638 | IP2: 48669 | IQ2: 48699 | IR2: 48730 | IS2: 48760 | IT2: 48791 | IU2: 48822 | IV2: 48852 | IW2: 48883 | IX2: 48913 | IY2: 48944 | IZ2: 48975 | JA2: 49003 | JB2: 49034 | JC2: 49064 | JD2: 49095 | JE2: 49125 | JF2: 49156 | JG2: 49187 | JH2: 49217 | JI2: 49248 | JJ2: 49278 | JK2: 49309 | JL2: 49340 | JM2: 49368 | JN2: 49399 | JO2: 49429 | JP2: 49460 | JQ2: 49490 | JR2: 49521 | JS2: 49552 | JT2: 49582 | JU2: 49613 | JV2: 49643 | JW2: 49674 | JX2: 49705 | JY2: 49734 | JZ2: 49765 | KA2: 49795 | KB2: 49826 | KC2: 49856 | KD2: 49887 | KE2: 49918 | KF2: 49948 | KG2: 49979 | KH2: 50009 | KI2: 50040 | KJ2: 50071 | KK2: 50099 | KL2: 50130 | KM2: 50160 | KN2: 50191 | KO2: 50221 | KP2: 50252 | KQ2: 50283 | KR2: 50313 | KS2: 50344 | KT2: 50374 | KU2: 50405 | KV2: 50436 | KW2: 50464
B4: Project Flags
B6: Land Acquisition | C6: 41274 | E6: =SUM(G6:KW6) -> 1 | G6: =(G$2<=$C6)*(H$2>$C6) -> 1 | H6: =(H$2<=$C6)*(I$2>$C6) -> 0 | I6: =(I$2<=$C6)*(J$2>$C6) -> 0 | J6: =(J$2<=$C6)*(K$2>$C6) -> 0 | K6: =(K$2<=$C6)*(L$2>$C6) -> 0 | L6: =(L$2<=$C6)*(M$2>$C6) -> 0 | M6: =(M$2<=$C6)*(N$2>$C6) -> 0 | N6: =(N$2<=$C6)*(O$2>$C6) -> 0 | ... KW6: =(KW$2<=$C6)*(KX$2>$C6) -> 0
B7: Demolition | C7: 41517 | E7: =SUM(G7:KW7) -> 1 | G7: =(G$2<=$C7)*(H$2>$C7) -> 0 | H7: =(H$2<=$C7)*(I$2>$C7) -> 0 | I7: =(I$2<=$C7)*(J$2>$C7) -> 0 | J7: =(J$2<=$C7)*(K$2>$C7) -> 0 | K7: =(K$2<=$C7)*(L$2>$C7) -> 0 | L7: =(L$2<=$C7)*(M$2>$C7) -> 0 | M7: =(M$2<=$C7)*(N$2>$C7) -> 0 | N7: =(N$2<=$C7)*(O$2>$C7) -> 0 | ... KW7: =(KW$2<=$C7)*(KX$2>$C7) -> 0
B8: Hard Construction Drawdown | C8: 41547 | D8: 41882 | E8: =SUM(G8:KW8) -> 12 | G8: =(G$2<=$D8)*(H$2>$C8) -> 0 | H8: =(H$2<=$D8)*(I$2>$C8) -> 0 | I8: =(I$2<=$D8)*(J$2>$C8) -> 0 | J8: =(J$2<=$D8)*(K$2>$C8) -> 0 | K8: =(K$2<=$D8)*(L$2>$C8) -> 0 | L8: =(L$2<=$D8)*(M$2>$C8) -> 0 | M8: =(M$2<=$D8)*(N$2>$C8) -> 0 | N8: =(N$2<=$D8)*(O$2>$C8) -> 0 | ... KW8: =(KW$2<=$D8)*(KX$2>$C8) -> 0
B9: Soft Construction Costs | C9: 41305 | D9: 41882 | E9: =SUM(G9:KW9) -> 20 | G9: =(G$2<=$D9)*(H$2>$C9) -> 0 | H9: =(H$2<=$D9)*(I$2>$C9) -> 1 | I9: =(I$2<=$D9)*(J$2>$C9) -> 1 | J9: =(J$2<=$D9)*(K$2>$C9) -> 1 | K9: =(K$2<=$D9)*(L$2>$C9) -> 1 | L9: =(L$2<=$D9)*(M$2>$C9) -> 1 | M9: =(M$2<=$D9)*(N$2>$C9) -> 1 | N9: =(N$2<=$D9)*(O$2>$C9) -> 1 | ... KW9: =(KW$2<=$D9)*(KX$2>$C9) -> 0
B10: Construction Loan Payoff | C10: 41305 | D10: 41882 | G10: =(G$2<=$D10)*(H$2>$C10) -> 0 | H10: =(H$2<=$D10)*(I$2>$C10) -> 1 | I10: =(I$2<=$D10)*(J$2>$C10) -> 1 | J10: =(J$2<=$D10)*(K$2>$C10) -> 1 | K10: =(K$2<=$D10)*(L$2>$C10) -> 1 | L10: =(L$2<=$D10)*(M$2>$C10) -> 1 | M10: =(M$2<=$D10)*(N$2>$C10) -> 1 | N10: =(N$2<=$D10)*(O$2>$C10) -> 1 | ... KW10: =(KW$2<=$D10)*(KX$2>$C10) -> 0
B12: Construction Loan
B14: Demolition | C14: ='Assumptions and Key Inputs'!D19 -> 75000 | D14: Check | E14: =SUM(G14:KW14) -> 75000 | G14: =G7*($C$14/$E$7) -> 0 | H14: =H7*($C$14/$E$7) -> 0 | I14: =I7*($C$14/$E$7) -> 0 | J14: =J7*($C$14/$E$7) -> 0 | K14: =K7*($C$14/$E$7) -> 0 | L14: =L7*($C$14/$E$7) -> 0 | M14: =M7*($C$14/$E$7) -> 0 | N14: =N7*($C$14/$E$7) -> 0 | ... KW14: =KW7*($C$14/$E$7) -> 0
B15: Hard Construction Costs | C15: ='Assumptions and Key Inputs'!D18 -> 2501550 | D15: Check | E15: =SUM(G15:KW15) -> 2501550 | G15: =G8*($C$15/$E$8) -> 0 | H15: =H8*($C$15/$E$8) -> 0 | I15: =I8*($C$15/$E$8) -> 0 | J15: =J8*($C$15/$E$8) -> 0 | K15: =K8*($C$15/$E$8) -> 0 | L15: =L8*($C$15/$E$8) -> 0 | M15: =M8*($C$15/$E$8) -> 0 | N15: =N8*($C$15/$E$8) -> 0 | ... KW15: =KW8*($C$15/$E$8) -> 0
B16: Soft Construction Costs | C16: ='Assumptions and Key Inputs'!D20 -> 81300.375 | D16: Check | E16: =SUM(G16:KW16) -> 81300.375 | G16: =G9*($C$16/$E$9) -> 0 | H16: =H9*($C$16/$E$9) -> 4065.0188 | I16: =I9*($C$16/$E$9) -> 4065.0188 | J16: =J9*($C$16/$E$9) -> 4065.0188 | K16: =K9*($C$16/$E$9) -> 4065.0188 | L16: =L9*($C$16/$E$9) -> 4065.0188 | M16: =M9*($C$16/$E$9) -> 4065.0188 | N16: =N9*($C$16/$E$9) -> 4065.0188 | ... KW16: =KW9*($C$16/$E$9) -> 0
B17: Drawdown | E17: =SUM(G17:KW17) -> 2657850.4 | G17: =SUM(G14:G16) -> 0 | H17: =SUM(H14:H16) -> 4065.0188 | I17: =SUM(I14:I16) -> 4065.0188 | J17: =SUM(J14:J16) -> 4065.0188 | K17: =SUM(K14:K16) -> 4065.0188 | L17: =SUM(L14:L16) -> 4065.0188 | M17: =SUM(M14:M16) -> 4065.0188 | N17: =SUM(N14:N16) -> 4065.0188 | ... KW17: =SUM(KW14:KW16) -> 0
B19: Interest Expense
B20: Beginning Balance | G20: =G10*F23 -> 0 | H20: =H10*G23 -> 0 | I20: =I10*H23 -> 4075.1813 | J20: =J10*I23 -> 8150.3626 | K20: =K10*J23 -> 12225.544 | L20: =L10*K23 -> 16300.725 | M20: =M10*L23 -> 20375.906 | N20: =N10*M23 -> 24451.088 | ... KW20: =KW10*KV23 -> 0
B21: Drawdown | G21: =G17 -> 0 | H21: =H17 -> 4065.0188 | I21: =I17 -> 4065.0188 | J21: =J17 -> 4065.0188 | K21: =K17 -> 4065.0188 | L21: =L17 -> 4065.0188 | M21: =M17 -> 4065.0188 | N21: =N17 -> 4065.0188 | ... KW21: =KW17 -> 0
B22: Interest Accrued | C22: ='Assumptions and Key Inputs'!D29 -> 0.03 | G22: =$C$22/12*G21 -> 0 | H22: =$C$22/12*H17 -> 10.162547 | I22: =$C$22/12*I17 -> 10.162547 | J22: =$C$22/12*J17 -> 10.162547 | K22: =$C$22/12*K17 -> 10.162547 | L22: =$C$22/12*L17 -> 10.162547 | M22: =$C$22/12*M17 -> 10.162547 | N22: =$C$22/12*N17 -> 10.162547 | O22: =$C$22/12*O17 -> 197.66255 | ... KW22: =$C$22/12*KW17 -> 0
B23: Ending Loan Balance | E23: =MAX(G23:KW23) -> 2664495 | G23: =SUM(G20:G22) -> 0 | H23: =SUM(H20:H22) -> 4075.1813 | I23: =SUM(I20:I22) -> 8150.3626 | J23: =SUM(J20:J22) -> 12225.544 | K23: =SUM(K20:K22) -> 16300.725 | L23: =SUM(L20:L22) -> 20375.906 | M23: =SUM(M20:M22) -> 24451.088 | N23: =SUM(N20:N22) -> 28526.269 | ... KW23: =SUM(KW20:KW22) -> 0

Sheet NOI at Completion
B2: Adjusting for NOI at Completion | G2: 2012 | H2: =G2+1 -> 2013 | I2: =H2+1 -> 2014 | J2: =I2+1 -> 2015 | K2: =J2+1 -> 2016 | L2: =K2+1 -> 2017 | M2: =L2+1 -> 2018 | N2: =M2+1 -> 2019 | O2: =N2+1 -> 2020 | ... AC2: =AB2+1 -> 2034
G3: Current Year | I3: Operations Begin | S3: Holding Period Ends as of Aug 2025
B5: Adjusting for growth | C5: 0.03 | G5: 1 | H5: =G5*(1+$C$5) -> 1.03 | I5: =H5*(1+$C$5) -> 1.0609 | J5: =I5*(1+$C$5) -> 1.092727 | K5: =J5*(1+$C$5) -> 1.1255088 | L5: =K5*(1+$C$5) -> 1.1592741 | M5: =L5*(1+$C$5) -> 1.1940523 | N5: =M5*(1+$C$5) -> 1.2298739 | O5: =N5*(1+$C$5) -> 1.2667701 | ... AB5: =AA5*(1+$C$5) -> 1.8602946
B7: Rental Income | G7: 428400
B8: Parking Income | G8: 17550
B9: Potential Gross Income | G9: =SUM(G7:G8) -> 445950
B10: Vacancy Loss | G10: ='Assumptions and Key Inputs'!$C$8*-G9 -> -8919
B11: Credit Loss | G11: =G9*-'Assumptions and Key Inputs'!$C$9 -> -4459.5
B12: Effective Gross Income | G12: =SUM(G9:G11) -> 432571.5
B13: Operating Expenses excl Depr | G13: -161387.96
B14: Net Operating Income | G14: =G12+G13 -> 271183.54 | I14: =$G$14*I5 -> 287698.62 | J14: =$G$14*J5 -> 296329.58 | K14: =$G$14*K5 -> 305219.46 | L14: =$G$14*L5 -> 314376.05 | M14: =$G$14*M5 -> 323807.33 | N14: =$G$14*N5 -> 333521.55 | O14: =$G$14*O5 -> 343527.2 | P14: =$G$14*P5 -> 353833.01 | ... S14: =$G$14*S5 -> 386642.88
B15: CapEx | C15: 0.2 | I15: =I14*-0.2 -> -57539.724 | J15: =J14*-0.2 -> -59265.915 | K15: =K14*-0.2 -> -61043.893 | L15: =L14*-0.2 -> -62875.209 | M15: =M14*-0.2 -> -64761.466 | N15: =N14*-0.2 -> -66704.31 | O15: =O14*-0.2 -> -68705.439 | P15: =P14*-0.2 -> -70766.602 | ... S15: =S14*-0.2 -> -77328.577
B16: Unlevered BTCF | G16: =SUM(G14:G15) -> 271183.54 | I16: =SUM(I14:I15) -> 230158.89 | J16: =SUM(J14:J15) -> 237063.66 | K16: =SUM(K14:K15) -> 244175.57 | L16: =SUM(L14:L15) -> 251500.84 | M16: =SUM(M14:M15) -> 259045.86 | N16: =SUM(N14:N15) -> 266817.24 | O16: =SUM(O14:O15) -> 274821.76 | P16: =SUM(P14:P15) -> 283066.41 | ... S16: =SUM(S14:S15) -> 309314.31
