Workbook

Sheet Overview
B3: Prepared and presented by: Shaira Katuwal, PE RealEstate Intern at Project Destined

Sheet Assumptions & Cash Flow
C1: Assumptions & Cash Flow
C6: General Assumptions | J6: 0 | K6: =+J6+1 -> 1 | L6: =+K6+1 -> 2 | M6: =+L6+1 -> 3 | N6: =+M6+1 -> 4 | O6: =+N6+1 -> 5 | P6: =+O6+1 -> 6 | Q6: =+P6+1 -> 7 | R6: =+Q6+1 -> 8 | ... U6: =+T6+1 -> 11
D7: Project Name | G7: Project Destined | J7: =+G11 -> 46022 | K7: =EDATE(J7,12) -> 46387 | L7: =EDATE(K7,12) -> 46752 | M7: =EDATE(L7,12) -> 47118 | N7: =EDATE(M7,12) -> 47483 | O7: =EDATE(N7,12) -> 47848 | P7: =EDATE(O7,12) -> 48213 | Q7: =EDATE(P7,12) -> 48579 | R7: =EDATE(Q7,12) -> 48944 | ... U7: =EDATE(T7,12) -> 50040
D8: Underwriter | G8: Shaira Katuwal | I8: Revenues
D9: # of Units | G9: 28 | I9: Gross Potential Rent | K9: ='Rent Roll'!K17 -> 519367.5 | L9: ='Rent Roll'!L17 -> 554220.68 | M9: ='Rent Roll'!M17 -> 594187.01 | N9: ='Rent Roll'!N17 -> 634067.87 | O9: ='Rent Roll'!O17 -> 673458.76 | P9: ='Rent Roll'!P17 -> 698464.17 | Q9: ='Rent Roll'!Q17 -> 724402.14 | R9: ='Rent Roll'!R17 -> 751307.62 | ... U9: ='Rent Roll'!U17 -> 838198.4
D10: Square Footage | G10: 23865 | I10: Vacancy Allowance | K10: ='Rent Roll'!K21 -> -77905.125 | L10: ='Rent Roll'!L21 -> -110844.14 | M10: ='Rent Roll'!M21 -> -89128.051 | N10: ='Rent Roll'!N21 -> -63406.787 | O10: ='Rent Roll'!O21 -> -67345.876 | P10: ='Rent Roll'!P21 -> -34923.208 | Q10: ='Rent Roll'!Q21 -> -21732.064 | R10: ='Rent Roll'!R21 -> -22539.229 | ... U10: ='Rent Roll'!U21 -> -25145.952
D11: Purchase Date | G11: 46022 | I11: Credit Loss | K11: =-$G$22*K9 -> -10387.35 | L11: =-$G$22*L9 -> -11084.414 | M11: =-$G$22*M9 -> -11883.74 | N11: =-$G$22*N9 -> -12681.357 | O11: =-$G$22*O9 -> -13469.175 | P11: =-$G$22*P9 -> -13969.283 | Q11: =-$G$22*Q9 -> -14488.043 | R11: =-$G$22*R9 -> -15026.152 | ... U11: =-$G$22*U9 -> -16763.968
D12: Total Hold Period | G12: 10 | I12: Other Income | K12: =$G$23*$G$9 -> 70000 | L12: =K12*(1+$G$24) -> 71400 | M12: =L12*(1+$G$24) -> 72828 | N12: =M12*(1+$G$24) -> 74284.56 | O12: =N12*(1+$G$24) -> 75770.251 | P12: =O12*(1+$G$24) -> 77285.656 | Q12: =P12*(1+$G$24) -> 78831.369 | R12: =Q12*(1+$G$24) -> 80407.997 | S12: =R12*(1+$G$24) -> 82016.157 | ... U12: =T12*(1+$G$24) -> 85329.609
D13: Sale Date | G13: =EDATE(G11,G12*12)-1 -> 49673 | I13: Effective Gross Income | K13: =SUM(K9:K12) -> 501075.03 | L13: =SUM(L9:L12) -> 503692.13 | M13: =SUM(M9:M12) -> 566003.22 | N13: =SUM(N9:N12) -> 632264.29 | O13: =SUM(O9:O12) -> 668413.96 | P13: =SUM(P9:P12) -> 726857.33 | Q13: =SUM(Q9:Q12) -> 767013.41 | R13: =SUM(R9:R12) -> 794150.24 | ... U13: =SUM(U9:U12) -> 881618.09
D14: Property Purchase Price | G14: 6500000
D15: Closing Costs & Permits (as a % of Purchase Price) | G15: 0.015 | I15: Operating Expenses
D16: Closing Costs & Permits | G16: =G15*G14 -> 97500 | I16: Payroll | K16: =G27 -> 55000 | L16: =K16*(1+$G$36) -> 56650 | M16: =L16*(1+$G$36) -> 58349.5 | N16: =M16*(1+$G$36) -> 60099.985 | O16: =N16*(1+$G$36) -> 61902.985 | P16: =O16*(1+$G$36) -> 63760.074 | Q16: =P16*(1+$G$36) -> 65672.876 | R16: =Q16*(1+$G$36) -> 67643.063 | S16: =R16*(1+$G$36) -> 69672.354 | ... U16: =T16*(1+$G$36) -> 73915.401
D17: Debt Origination Costs (% of Debt) | G17: 0.0125 | I17: Utilities | K17: =G28 -> 34000 | L17: =K17*(1+$G$36) -> 35020 | M17: =L17*(1+$G$36) -> 36070.6 | N17: =M17*(1+$G$36) -> 37152.718 | O17: =N17*(1+$G$36) -> 38267.3 | P17: =O17*(1+$G$36) -> 39415.319 | Q17: =P17*(1+$G$36) -> 40597.778 | R17: =Q17*(1+$G$36) -> 41815.711 | S17: =R17*(1+$G$36) -> 43070.183 | ... U17: =T17*(1+$G$36) -> 45693.157
D18: Debt Origination Costs ($) | G18: =G17*G48 -> 38255.347 | I18: Contracts | K18: =G29 -> 15000 | L18: =K18*(1+$G$36) -> 15450 | M18: =L18*(1+$G$36) -> 15913.5 | N18: =M18*(1+$G$36) -> 16390.905 | O18: =N18*(1+$G$36) -> 16882.632 | P18: =O18*(1+$G$36) -> 17389.111 | Q18: =P18*(1+$G$36) -> 17910.784 | R18: =Q18*(1+$G$36) -> 18448.108 | S18: =R18*(1+$G$36) -> 19001.551 | ... U18: =T18*(1+$G$36) -> 20158.746
D19: Going in Cap Rate | G19: =K27/G14 -> 0.047083504 | I19: Repairs & Maintenance | K19: =G30*G9 -> 14000 | L19: =K19*(1+$G$36) -> 14420 | M19: =L19*(1+$G$36) -> 14852.6 | N19: =M19*(1+$G$36) -> 15298.178 | O19: =N19*(1+$G$36) -> 15757.123 | P19: =O19*(1+$G$36) -> 16229.837 | Q19: =P19*(1+$G$36) -> 16716.732 | R19: =Q19*(1+$G$36) -> 17218.234 | S19: =R19*(1+$G$36) -> 17734.781 | ... U19: =T19*(1+$G$36) -> 18814.829
I20: Administrative/G&A | K20: =G31 -> 10000 | L20: =K20*(1+$G$36) -> 10300 | M20: =L20*(1+$G$36) -> 10609 | N20: =M20*(1+$G$36) -> 10927.27 | O20: =N20*(1+$G$36) -> 11255.088 | P20: =O20*(1+$G$36) -> 11592.741 | Q20: =P20*(1+$G$36) -> 11940.523 | R20: =Q20*(1+$G$36) -> 12298.739 | S20: =R20*(1+$G$36) -> 12667.701 | ... U20: =T20*(1+$G$36) -> 13439.164
C21: Revenue Assumptions | I21: Insurance | K21: =G32 -> 20000 | L21: =K21*(1+$G$36) -> 20600 | M21: =L21*(1+$G$36) -> 21218 | N21: =M21*(1+$G$36) -> 21854.54 | O21: =N21*(1+$G$36) -> 22510.176 | P21: =O21*(1+$G$36) -> 23185.481 | Q21: =P21*(1+$G$36) -> 23881.046 | R21: =Q21*(1+$G$36) -> 24597.477 | S21: =R21*(1+$G$36) -> 25335.402 | ... U21: =T21*(1+$G$36) -> 26878.328
D22: Credit Loss | G22: 0.02 | I22: Management Fee (% of EGI) | K22: =$G$33*K13 -> 15032.251 | L22: =$G$33*L13 -> 15110.764 | M22: =$G$33*M13 -> 16980.097 | N22: =$G$33*N13 -> 18967.929 | O22: =$G$33*O13 -> 20052.419 | P22: =$G$33*P13 -> 21805.72 | Q22: =$G$33*Q13 -> 23010.402 | R22: =$G$33*R13 -> 23824.507 | ... U22: =$G$33*U13 -> 26448.543
D23: Year 1 Other Income (Per Unit Per Year) | G23: 2500 | I23: Real Estate Taxes | K23: =G34 -> 25000 | L23: =K23*(1+$G$37) -> 25937.5 | M23: =L23*(1+$G$37) -> 26910.156 | N23: =M23*(1+$G$37) -> 27919.287 | O23: =N23*(1+$G$37) -> 28966.26 | P23: =O23*(1+$G$37) -> 30052.495 | Q23: =P23*(1+$G$37) -> 31179.464 | R23: =Q23*(1+$G$37) -> 32348.694 | S23: =R23*(1+$G$37) -> 33561.77 | ... U23: =T23*(1+$G$37) -> 36126.099
D24: Other Income Growth | G24: 0.02 | I24: Reserves | K24: =G35*G9 -> 7000 | L24: =K24*(1+$G$36) -> 7210 | M24: =L24*(1+$G$36) -> 7426.3 | N24: =M24*(1+$G$36) -> 7649.089 | O24: =N24*(1+$G$36) -> 7878.5617 | P24: =O24*(1+$G$36) -> 8114.9185 | Q24: =P24*(1+$G$36) -> 8358.3661 | R24: =Q24*(1+$G$36) -> 8609.1171 | S24: =R24*(1+$G$36) -> 8867.3906 | ... U24: =T24*(1+$G$36) -> 9407.4147
I25: Total Operating Expenses | K25: =SUM(K16:K24) -> 195032.25 | L25: =SUM(L16:L24) -> 200698.26 | M25: =SUM(M16:M24) -> 208329.75 | N25: =SUM(N16:N24) -> 216259.9 | O25: =SUM(O16:O24) -> 223472.54 | P25: =SUM(P16:P24) -> 231545.7 | Q25: =SUM(Q16:Q24) -> 239267.97 | R25: =SUM(R16:R24) -> 246803.65 | ... U25: =SUM(U16:U24) -> 270881.68
C26: Expense Assumptions
D27: Payroll (Year 1) | G27: 55000 | I27: Net Operating Income | K27: =K13-K25 -> 306042.77 | L27: =L13-L25 -> 302993.86 | M27: =M13-M25 -> 357673.47 | N27: =N13-N25 -> 416004.38 | O27: =O13-O25 -> 444941.41 | P27: =P13-P25 -> 495311.64 | Q27: =Q13-Q25 -> 527745.43 | R27: =R13-R25 -> 547346.59 | ... U27: =U13-U25 -> 610736.41
D28: Utilities (Year 1) | G28: 34000
D29: Contracts (Year 1) | G29: 15000 | I29: Capital Expenses
D30: Repairs & Maintenance (per unit per year) | G30: 500 | I30: Renovation Schedule | K30: =IF(K$6<=$G$40,$G$41/$G$40,0) -> 111250 | L30: =IF(L$6<=$G$40,$G$41/$G$40,0) -> 111250 | M30: =IF(M$6<=$G$40,$G$41/$G$40,0) -> 111250 | N30: =IF(N$6<=$G$40,$G$41/$G$40,0) -> 111250 | O30: =IF(O$6<=$G$40,$G$41/$G$40,0) -> 0 | P30: =IF(P$6<=$G$40,$G$41/$G$40,0) -> 0 | Q30: =IF(Q$6<=$G$40,$G$41/$G$40,0) -> 0 | R30: =IF(R$6<=$G$40,$G$41/$G$40,0) -> 0 | ... T30: =IF(T$6<=$G$40,$G$41/$G$40,0) -> 0
D31: Administrative/G&A (Year 1) | G31: 10000 | I31: Façade Project (only include if it is provided in OM) | K31: 0 | L31: 0 | M31: 0 | N31: 0 | O31: 0 | P31: 0 | Q31: 0 | R31: 0 | S31: 0 | T31: 0
D32: Insurance (Year 1) | G32: 20000 | I32: Roof Replacement (only include if it is provided in OM) | K32: 0 | L32: 0 | M32: 0 | N32: 0 | O32: 0 | P32: 0 | Q32: 0 | R32: 0 | S32: 0 | T32: 0
D33: Management Fee (% of EGI) | G33: 0.03 | I33: Total Capital Expenses | K33: =SUM(K30:K32) -> 111250 | L33: =SUM(L30:L32) -> 111250 | M33: =SUM(M30:M32) -> 111250 | N33: =SUM(N30:N32) -> 111250 | O33: =SUM(O30:O32) -> 0 | P33: =SUM(P30:P32) -> 0 | Q33: =SUM(Q30:Q32) -> 0 | R33: =SUM(R30:R32) -> 0 | ... T33: =SUM(T30:T32) -> 0
D34: Real Estate Taxes (Year 1) | G34: 25000
D35: Reserves (per unit per year) | G35: 250 | I35: Net Cash Flow Before Debt | K35: =K27-K33 -> 194792.77 | L35: =L27-L33 -> 191743.86 | M35: =M27-M33 -> 246423.47 | N35: =N27-N33 -> 304754.38 | O35: =O27-O33 -> 444941.41 | P35: =P27-P33 -> 495311.64 | Q35: =Q27-Q33 -> 527745.43 | R35: =R27-R33 -> 547346.59 | ... T35: =T27-T33 -> 588812.89
D36: Expense Growth | G36: 0.03
D37: Real Estate Tax Growth | G37: 0.0375 | I37: Debt Service
I38: Total Debt Service | K38: ='Debt Amortization Schedule'!$B$8 -> 204392.74 | L38: ='Debt Amortization Schedule'!$B$8 -> 204392.74 | M38: ='Debt Amortization Schedule'!$B$8 -> 204392.74 | N38: ='Debt Amortization Schedule'!$B$8 -> 204392.74 | O38: ='Debt Amortization Schedule'!$B$8 -> 204392.74 | P38: ='Debt Amortization Schedule'!$B$8 -> 204392.74 | Q38: ='Debt Amortization Schedule'!$B$8 -> 204392.74 | R38: ='Debt Amortization Schedule'!$B$8 -> 204392.74 | ... T38: ='Debt Amortization Schedule'!$B$8 -> 204392.74
C39: Capital Expense Assumptions
D40: Renovation Schedule | G40: 4 | I40: Net Cash Flow After Debt | K40: =K35-K38 -> -9599.9615 | L40: =L35-L38 -> -12648.873 | M40: =M35-M38 -> 42030.73 | N40: =N35-N38 -> 100361.65 | O40: =O35-O38 -> 240548.68 | P40: =P35-P38 -> 290918.9 | Q40: =Q35-Q38 -> 323352.7 | R40: =R35-R38 -> 342953.85 | ... T40: =T35-T38 -> 384420.15
D41: Total Renovation Expense | G41: 445000
D42: Façade Project | G42: 0 | I42: Unlevered Analysis
D43: Total Façade Expense | G43: 0 | I43: Purchase Price | J43: =-('Sources & Uses'!J15+'Sources & Uses'!J16) -> -6597500
D44: Roof Replacement Project | G44: 0 | I44: Unlevered Cashflow | K44: =K35 -> 194792.77 | L44: =L35 -> 191743.86 | M44: =M35 -> 246423.47 | N44: =N35 -> 304754.38 | O44: =O35 -> 444941.41 | P44: =P35 -> 495311.64 | Q44: =Q35 -> 527745.43 | R44: =R35 -> 547346.59 | ... T44: =T35 -> 588812.89
...

Sheet Rent Roll
B1: Property Rent Roll
B6: "T-12" Property Rent Roll | I6: Year | J6: 0 | K6: 1 | L6: =+K6+1 -> 2 | M6: =+L6+1 -> 3 | N6: =+M6+1 -> 4 | O6: =+N6+1 -> 5 | P6: =+O6+1 -> 6 | Q6: =+P6+1 -> 7 | R6: =+Q6+1 -> 8 | S6: =+R6+1 -> 9 | ... U6: =+T6+1 -> 11
B7: Unit | C7: # of Bedrooms | D7: Unit SF | E7: Monthly Rent | F7: $ PSF | G7: T-12 Annual Rent | I7: Date | J7: ='Assumptions & Cash Flow'!J7 -> 46022 | K7: ='Assumptions & Cash Flow'!K7 -> 46387 | L7: =EDATE(K7,12) -> 46752 | M7: =EDATE(L7,12) -> 47118 | N7: =EDATE(M7,12) -> 47483 | O7: =EDATE(N7,12) -> 47848 | P7: =EDATE(O7,12) -> 48213 | Q7: =EDATE(P7,12) -> 48579 | R7: =EDATE(Q7,12) -> 48944 | S7: =EDATE(R7,12) -> 49309 | ... U7: =EDATE(T7,12) -> 50040
B8: 1A | C8: 1 | D8: 650 | E8: 1100 | F8: =+E8/D8 -> 1.6923077 | G8: =E8*12 -> 13200
B9: 1B | C9: 1 | D9: 675 | E9: 1125 | F9: =+E9/D9 -> 1.6666667 | G9: =E9*12 -> 13500 | I9: 1 Bedroom Rent Growth Rate | K9: 0.06 | L9: 0.065 | M9: 0.07 | N9: 0.065 | O9: 0.06 | P9: 0.035 | Q9: 0.035 | R9: 0.035 | S9: 0.035 | T9: 0.035 | U9: 0.035
B10: 2A | C10: 1 | D10: 700 | E10: 1150 | F10: =+E10/D10 -> 1.6428571 | G10: =E10*12 -> 13800 | I10: 2 Bedroom Rent Growth Rate | K10: 0.065 | L10: 0.07 | M10: 0.075 | N10: 0.07 | O10: 0.065 | P10: 0.04 | Q10: 0.04 | R10: 0.04 | S10: 0.04 | T10: 0.04 | U10: 0.04
B11: 2B | C11: 1 | D11: 725 | E11: 1175 | F11: =+E11/D11 -> 1.6206897 | G11: =E11*12 -> 14100
B12: 3A | C12: 1 | D12: 725 | E12: 1200 | F12: =+E12/D12 -> 1.6551724 | G12: =E12*12 -> 14400
B13: 3B | C13: 1 | D13: 750 | E13: 1225 | F13: =+E13/D13 -> 1.6333333 | G13: =E13*12 -> 14700
B14: 4A | C14: 1 | D14: 750 | E14: 1250 | F14: =+E14/D14 -> 1.6666667 | G14: =E14*12 -> 15000 | I14: Annual 1 Bedroom Rent | J14: =SUMIF($C$8:$C$35,1,$G$8:$G$35) -> 283500 | K14: =J14*(1+K9) -> 300510 | L14: =+K14*(1+L9) -> 320043.15 | M14: =+L14*(1+M9) -> 342446.17 | N14: =+M14*(1+N9) -> 364705.17 | O14: =+N14*(1+O9) -> 386587.48 | P14: =+O14*(1+P9) -> 400118.04 | Q14: =+P14*(1+Q9) -> 414122.18 | R14: =+Q14*(1+R9) -> 428616.45 | S14: =+R14*(1+S9) -> 443618.03 | ... U14: =+T14*(1+U9) -> 475214.72
B15: 4B | C15: 1 | D15: 750 | E15: 1275 | F15: =+E15/D15 -> 1.7 | G15: =E15*12 -> 15300 | I15: Annual 2 Bedroom Rent | J15: =SUMIF($C$8:$C$35,2,$G$8:$G$35) -> 205500 | K15: =J15*(1+K10) -> 218857.5 | L15: =K15*(1+L10) -> 234177.53 | M15: =L15*(1+M10) -> 251740.84 | N15: =M15*(1+N10) -> 269362.7 | O15: =N15*(1+O10) -> 286871.27 | P15: =O15*(1+P10) -> 298346.12 | Q15: =P15*(1+Q10) -> 310279.97 | R15: =Q15*(1+R10) -> 322691.17 | ... U15: =T15*(1+U10) -> 362983.68
B16: 5A | C16: 1 | D16: 775 | E16: 1300 | F16: =+E16/D16 -> 1.6774194 | G16: =E16*12 -> 15600
B17: 5B | C17: 1 | D17: 775 | E17: 1325 | F17: =+E17/D17 -> 1.7096774 | G17: =E17*12 -> 15900 | I17: Total Gross Potential Rent | J17: =SUM(J14:J15) -> 489000 | K17: =SUM(K14:K15) -> 519367.5 | L17: =SUM(L14:L15) -> 554220.68 | M17: =SUM(M14:M15) -> 594187.01 | N17: =SUM(N14:N15) -> 634067.87 | O17: =SUM(O14:O15) -> 673458.76 | P17: =SUM(P14:P15) -> 698464.17 | Q17: =SUM(Q14:Q15) -> 724402.14 | ... U17: =SUM(U14:U15) -> 838198.4
B18: 6A | C18: 1 | D18: 800 | E18: 1350 | F18: =+E18/D18 -> 1.6875 | G18: =E18*12 -> 16200
B19: 6B | C19: 1 | D19: 800 | E19: 1375 | F19: =+E19/D19 -> 1.71875 | G19: =E19*12 -> 16500 | I19: Vacancy Rate | K19: 0.15 | L19: 0.2 | M19: 0.15 | N19: 0.1 | O19: 0.1 | P19: 0.05 | Q19: 0.03 | R19: 0.03 | S19: 0.03 | T19: 0.03 | U19: 0.03
B20: 7A | C20: 1 | D20: 820 | E20: 1400 | F20: =+E20/D20 -> 1.7073171 | G20: =E20*12 -> 16800
B21: 7B | C21: 1 | D21: 820 | E21: 1425 | F21: =+E21/D21 -> 1.7378049 | G21: =E21*12 -> 17100 | I21: Vacancy Allowance | K21: =-K17*K19 -> -77905.125 | L21: =-L17*L19 -> -110844.14 | M21: =-M17*M19 -> -89128.051 | N21: =-N17*N19 -> -63406.787 | O21: =-O17*O19 -> -67345.876 | P21: =-P17*P19 -> -34923.208 | Q21: =-Q17*Q19 -> -21732.064 | R21: =-R17*R19 -> -22539.229 | ... U21: =-U17*U19 -> -25145.952
B22: 8A | C22: 1 | D22: 850 | E22: 1450 | F22: =+E22/D22 -> 1.7058824 | G22: =E22*12 -> 17400
B23: 8B | C23: 1 | D23: 850 | E23: 1475 | F23: =+E23/D23 -> 1.7352941 | G23: =E23*12 -> 17700 | I23: Total Rent Growth CAGR (5-Year ) | J23: =(O17/J17)^(1/5)-1 -> 0.066106101 | K23: Note: CAGR Formula is: =(Ending Balance/Starting Balance)^(1/Number of Years) – 1
B24: 9A | C24: 1 | D24: 875 | E24: 1500 | F24: =+E24/D24 -> 1.7142857 | G24: =E24*12 -> 18000 | I24: Total Rent Growth CAGR (10-Year ) | J24: =(T17/J17)^(1/10)-1 -> 0.051524142
B25: 9B | C25: 1 | D25: 875 | E25: 1525 | F25: =+E25/D25 -> 1.7428571 | G25: =E25*12 -> 18300
B26: 10A | C26: 2 | D26: 900 | E26: 1600 | F26: =+E26/D26 -> 1.7777778 | G26: =E26*12 -> 19200
B27: 10B | C27: 2 | D27: 900 | E27: 1625 | F27: =+E27/D27 -> 1.8055556 | G27: =E27*12 -> 19500
B28: 11A | C28: 2 | D28: 925 | E28: 1650 | F28: =+E28/D28 -> 1.7837838 | G28: =E28*12 -> 19800
B29: 11B | C29: 2 | D29: 950 | E29: 1675 | F29: =+E29/D29 -> 1.7631579 | G29: =E29*12 -> 20100
B30: 12A | C30: 2 | D30: 975 | E30: 1700 | F30: =+E30/D30 -> 1.7435897 | G30: =E30*12 -> 20400
B31: 12B | C31: 2 | D31: 1000 | E31: 1725 | F31: =+E31/D31 -> 1.725 | G31: =E31*12 -> 20700
B32: 13A | C32: 2 | D32: 1025 | E32: 1750 | F32: =+E32/D32 -> 1.7073171 | G32: =E32*12 -> 21000
B33: 13B | C33: 2 | D33: 1050 | E33: 1775 | F33: =+E33/D33 -> 1.6904762 | G33: =E33*12 -> 21300
B34: 14A | C34: 2 | D34: 1075 | E34: 1800 | F34: =+E34/D34 -> 1.6744186 | G34: =E34*12 -> 21600
B35: 14B | C35: 2 | D35: 1100 | E35: 1825 | F35: =+E35/D35 -> 1.6590909 | G35: =E35*12 -> 21900
B36: Total | C36: =COUNTA(C8:C35) -> 28 | D36: =SUM(D8:D35) -> 23865 | E36: =SUM(E8:E35) -> 40750 | F36: =+SUMPRODUCT(F8:F35,D8:D35)/D36 -> 1.7075215 | G36: =SUM(G8:G35) -> 489000

Sheet Sources & Uses
B1: Sources & Uses
B6: Property SF | C6: ='Assumptions & Cash Flow'!G10 -> 23865
B8: Sources & Uses
D9: Day 1 | G9: Future Funding | J9: Total Stack
B10: Sources | D10: Total | E10: PRSF | F10: % Total | G10: Total | H10: PRSF | I10: % Total | J10: Total | K10: PRSF | L10: % Total
B11: Debt | D11: ='Assumptions & Cash Flow'!G48 -> 3060427.7 | E11: =D11/$C$6 -> 128.23917 | F11: =D11/D$13 -> 0.46120262 | G11: 0 | H11: =G11/$C$6 -> 0 | I11: =G11/G$13 -> 0 | J11: =D11+G11 -> 3060427.7 | K11: =J11/$C$6 -> 128.23917 | L11: =J11/$J$13 -> 0.43221769
B12: Equity | D12: =D20-D11 -> 3575327.6 | E12: =D12/$C$6 -> 149.81469 | F12: =D12/D$13 -> 0.53879738 | G12: =G20-G11 -> 445000 | H12: =G12/$C$6 -> 18.646554 | I12: =G12/G$13 -> 1 | J12: =D12+G12 -> 4020327.6 | K12: =J12/$C$6 -> 168.46124 | L12: =J12/$J$13 -> 0.56778231
B13: Total Sources | D13: =SUM(D11:D12) -> 6635755.3 | E13: =SUM(E11:E12) -> 278.05386 | F13: =D13/D$13 -> 1 | G13: =SUM(G11:G12) -> 445000 | H13: =SUM(H11:H12) -> 18.646554 | I13: =G13/G$13 -> 1 | J13: =SUM(J11:J12) -> 7080755.3 | K13: =SUM(K11:K12) -> 296.70041 | L13: =SUM(L11:L12) -> 1
B14: Uses | D14: Total | E14: PRSF | F14: % Total | G14: Total | H14: PRSF | I14: % Total | J14: Total | K14: PRSF | L14: Total
B15: Property Purchase Price | D15: ='Assumptions & Cash Flow'!G14 -> 6500000 | E15: =D15/$C$6 -> 272.36539 | F15: =D15/D$20 -> 0.97954184 | G15: 0 | H15: =G15/$C$6 -> 0 | I15: =G15/G$20 -> 0 | J15: =D15+G15 -> 6500000 | K15: =J15/$C$6 -> 272.36539 | L15: =J15/$J$20 -> 0.91798116
B16: Closing Costs | D16: ='Assumptions & Cash Flow'!G16 -> 97500 | E16: =D16/$C$6 -> 4.0854808 | F16: =D16/D$20 -> 0.014693128 | G16: 0 | H16: =G16/$C$6 -> 0 | I16: =G16/G$20 -> 0 | J16: =D16+G16 -> 97500 | K16: =J16/$C$6 -> 4.0854808 | L16: =J16/$J$20 -> 0.013769717
B17: Debt Origination | D17: =+J11*'Assumptions & Cash Flow'!$G$17 -> 38255.347 | E17: =D17/$C$6 -> 1.6029896 | F17: =D17/D$20 -> 0.0057650327 | G17: 0 | H17: =G17/$C$6 -> 0 | I17: =G17/G$20 -> 0 | J17: =D17+G17 -> 38255.347 | K17: =J17/$C$6 -> 1.6029896 | L17: =J17/$J$20 -> 0.0054027212
B18: Renovation Hard Costs | D18: =E18*$C$6 -> 0 | E18: 0 | F18: =D18/D$20 -> 0 | G18: =H18*C6 -> 445000 | H18: ='Assumptions & Cash Flow'!G41/'Assumptions & Cash Flow'!G10 -> 18.646554 | I18: =G18/G$20 -> 1 | J18: =D18+G18 -> 445000 | K18: =J18/$C$6 -> 18.646554 | L18: =J18/$J$20 -> 0.062846402
B19: Renovation Soft Costs | D19: =E19*$C$6 -> 0 | E19: 0 | F19: =D19/D$20 -> 0 | G19: =H19*$C$6 -> 0 | H19: 0 | I19: =G19/G$20 -> 0 | J19: =D19+G19 -> 0 | K19: =J19/$C$6 -> 0 | L19: =J19/$J$20 -> 0
B20: Total Uses | D20: =SUM(D15:D19) -> 6635755.3 | E20: =SUM(E15:E19) -> 278.05386 | F20: =D20/D$20 -> 1 | G20: =SUM(G15:G19) -> 445000 | H20: =SUM(H15:H19) -> 18.646554 | I20: =G20/G$20 -> 1 | J20: =SUM(J15:J19) -> 7080755.3 | K20: =SUM(K15:K19) -> 296.70041 | L20: =SUM(L15:L19) -> 1

Sheet Debt Sizing
B1: Debt Sizing
C8: DSCR | F8: Debt Yield | I8: LTV
C9: Year 1 NOI | D9: ='Assumptions & Cash Flow'!K27 -> 306042.77 | F9: Year 1 NOI | G9: =D9 -> 306042.77 | I9: Property Purchase Price | J9: ='Assumptions & Cash Flow'!G14 -> 6500000
C10: DSCR | D10: 1.25 | F10: Debt Yield | G10: 0.1 | I10: LTV | J10: 0.65
C11: Debt Service | D11: =D9/D10 -> 244834.22 | F11: Loan Amount | G11: =G9/G10 -> 3060427.7 | I11: Loan Amount | J11: =J9*J10 -> 4225000
C12: Interest Rate | D12: ='Assumptions & Cash Flow'!G51 -> 0.0532
C13: # of years (Amortization Term) | D13: ='Assumptions & Cash Flow'!G50 -> 30
C14: Loan Amount | D14: =PV(D12/12,D13*12,-D11/12) -> 3665969
C16: Loan Choice | D16: =MIN(D14,G11,J11) -> 3060427.7

Sheet Debt Amortization Schedule
A1: Loan Assumptions
A2: Loan Amount | B2: ='Debt Sizing'!D16 -> 3060427.7
A3: Interest Rate | B3: ='Assumptions & Cash Flow'!G51 -> 0.0532
A4: Loan Term yrs) | B4: ='Assumptions & Cash Flow'!G49 -> 10 | C4: =B4*12 -> 120 | D4: months
A5: Amortization Term | B5: ='Assumptions & Cash Flow'!G50 -> 30
A6: Payments / Year | B6: ='Assumptions & Cash Flow'!G52 -> 12
A7: Monthly Payment (Debt Service) | B7: =B8/12 -> 17032.728
A8: Annual Payment (Debt Service) | B8: ='Assumptions & Cash Flow'!G53 -> 204392.74
A11: Month | B11: Starting Balance | C11: Interest Payment | D11: Principal Payment | E11: Total Payment | F11: Ending Balance
A12: 0 | F12: =B2 -> 3060427.7
A13: 1 | B13: =F12 -> 3060427.7 | C13: =($B$3*B13)/$B$6 -> 13567.896 | D13: =E13-C13 -> 3464.8317 | E13: =$B$7 -> 17032.728 | F13: =B13-D13 -> 3056962.9
A14: 2 | B14: =F13 -> 3056962.9 | C14: =($B$3*B14)/$B$6 -> 13552.536 | D14: =E14-C14 -> 3480.1924 | E14: =$B$7 -> 17032.728 | F14: =B14-D14 -> 3053482.7
A15: 3 | B15: =F14 -> 3053482.7 | C15: =($B$3*B15)/$B$6 -> 13537.107 | D15: =E15-C15 -> 3495.6213 | E15: =$B$7 -> 17032.728 | F15: =B15-D15 -> 3049987.1
A16: 4 | B16: =F15 -> 3049987.1 | C16: =($B$3*B16)/$B$6 -> 13521.609 | D16: =E16-C16 -> 3511.1185 | E16: =$B$7 -> 17032.728 | F16: =B16-D16 -> 3046476
A17: 5 | B17: =F16 -> 3046476 | C17: =($B$3*B17)/$B$6 -> 13506.044 | D17: =E17-C17 -> 3526.6845 | E17: =$B$7 -> 17032.728 | F17: =B17-D17 -> 3042949.3
A18: 6 | B18: =F17 -> 3042949.3 | C18: =($B$3*B18)/$B$6 -> 13490.409 | D18: =E18-C18 -> 3542.3194 | E18: =$B$7 -> 17032.728 | F18: =B18-D18 -> 3039407
A19: 7 | B19: =F18 -> 3039407 | C19: =($B$3*B19)/$B$6 -> 13474.704 | D19: =E19-C19 -> 3558.0237 | E19: =$B$7 -> 17032.728 | F19: =B19-D19 -> 3035849
A20: 8 | B20: =F19 -> 3035849 | C20: =($B$3*B20)/$B$6 -> 13458.93 | D20: =E20-C20 -> 3573.7976 | E20: =$B$7 -> 17032.728 | F20: =B20-D20 -> 3032275.2
A21: 9 | B21: =F20 -> 3032275.2 | C21: =($B$3*B21)/$B$6 -> 13443.087 | D21: =E21-C21 -> 3589.6415 | E21: =$B$7 -> 17032.728 | F21: =B21-D21 -> 3028685.5
A22: 10 | B22: =F21 -> 3028685.5 | C22: =($B$3*B22)/$B$6 -> 13427.172 | D22: =E22-C22 -> 3605.5555 | E22: =$B$7 -> 17032.728 | F22: =B22-D22 -> 3025080
A23: 11 | B23: =F22 -> 3025080 | C23: =($B$3*B23)/$B$6 -> 13411.188 | D23: =E23-C23 -> 3621.5402 | E23: =$B$7 -> 17032.728 | F23: =B23-D23 -> 3021458.4
A24: 12 | B24: =F23 -> 3021458.4 | C24: =($B$3*B24)/$B$6 -> 13395.132 | D24: =E24-C24 -> 3637.5957 | E24: =$B$7 -> 17032.728 | F24: =B24-D24 -> 3017820.8
... A131: 119 | B131: =F130 -> 2524793.5 | C131: =($B$3*B131)/$B$6 -> 11193.251 | D131: =E131-C131 -> 5839.4767 | E131: =$B$7 -> 17032.728 | F131: =B131-D131 -> 2518954
A132: 120 | B132: =F131 -> 2518954 | C132: =($B$3*B132)/$B$6 -> 11167.363 | D132: =E132-C132 -> 5865.365 | E132: =$B$7 -> 17032.728 | F132: =B132-D132 -> 2513088.7 | G132: end of loan term
A133: 121 | B133: =F132 -> 2513088.7 | C133: =($B$3*B133)/$B$6 -> 11141.36 | D133: =E133-C133 -> 5891.3682 | E133: =$B$7 -> 17032.728 | F133: =B133-D133 -> 2507197.3
A134: 122 | B134: =F133 -> 2507197.3 | C134: =($B$3*B134)/$B$6 -> 11115.241 | D134: =E134-C134 -> 5917.4865 | E134: =$B$7 -> 17032.728 | F134: =B134-D134 -> 2501279.8
A135: 123 | B135: =F134 -> 2501279.8 | C135: =($B$3*B135)/$B$6 -> 11089.007 | D135: =E135-C135 -> 5943.7207 | E135: =$B$7 -> 17032.728 | F135: =B135-D135 -> 2495336.1
A136: 124 | B136: =F135 -> 2495336.1 | C136: =($B$3*B136)/$B$6 -> 11062.657 | D136: =E136-C136 -> 5970.0712 | E136: =$B$7 -> 17032.728 | F136: =B136-D136 -> 2489366
A137: 125 | B137: =F136 -> 2489366 | C137: =($B$3*B137)/$B$6 -> 11036.189 | D137: =E137-C137 -> 5996.5386 | E137: =$B$7 -> 17032.728 | F137: =B137-D137 -> 2483369.5
A138: 126 | B138: =F137 -> 2483369.5 | C138: =($B$3*B138)/$B$6 -> 11009.605 | D138: =E138-C138 -> 6023.1232 | E138: =$B$7 -> 17032.728 | F138: =B138-D138 -> 2477346.4
A139: 127 | B139: =F138 -> 2477346.4 | C139: =($B$3*B139)/$B$6 -> 10982.902 | D139: =E139-C139 -> 6049.8257 | E139: =$B$7 -> 17032.728 | F139: =B139-D139 -> 2471296.5
A140: 128 | B140: =F139 -> 2471296.5 | C140: =($B$3*B140)/$B$6 -> 10956.081 | D140: =E140-C140 -> 6076.6466 | E140: =$B$7 -> 17032.728 | F140: =B140-D140 -> 2465219.9
A141: 129 | B141: =F140 -> 2465219.9 | C141: =($B$3*B141)/$B$6 -> 10929.142 | D141: =E141-C141 -> 6103.5864 | E141: =$B$7 -> 17032.728 | F141: =B141-D141 -> 2459116.3
A142: 130 | B142: =F141 -> 2459116.3 | C142: =($B$3*B142)/$B$6 -> 10902.082 | D142: =E142-C142 -> 6130.6456 | E142: =$B$7 -> 17032.728 | F142: =B142-D142 -> 2452985.7
A143: 131 | B143: =F142 -> 2452985.7 | C143: =($B$3*B143)/$B$6 -> 10874.903 | D143: =E143-C143 -> 6157.8248 | E143: =$B$7 -> 17032.728 | F143: =B143-D143 -> 2446827.8
A144: 132 | B144: =F143 -> 2446827.8 | C144: =($B$3*B144)/$B$6 -> 10847.603 | D144: =E144-C144 -> 6185.1245 | E144: =$B$7 -> 17032.728 | F144: =B144-D144 -> 2440642.7
... A312: 300 | B312: =F311 -> 908606.49 | C312: =($B$3*B312)/$B$6 -> 4028.1554 | D312: =E312-C312 -> 13004.573 | E312: =$B$7 -> 17032.728 | F312: =B312-D312 -> 895601.92
A313: =A312+1 -> 301 | B313: =F312 -> 895601.92 | C313: =($B$3*B313)/$B$6 -> 3970.5018 | D313: =E313-C313 -> 13062.226 | E313: =$B$7 -> 17032.728 | F313: =B313-D313 -> 882539.69
A314: =A313+1 -> 302 | B314: =F313 -> 882539.69 | C314: =($B$3*B314)/$B$6 -> 3912.5926 | D314: =E314-C314 -> 13120.135 | E314: =$B$7 -> 17032.728 | F314: =B314-D314 -> 869419.55
A315: =A314+1 -> 303 | B315: =F314 -> 869419.55 | C315: =($B$3*B315)/$B$6 -> 3854.4267 | D315: =E315-C315 -> 13178.301 | E315: =$B$7 -> 17032.728 | F315: =B315-D315 -> 856241.25
...
