Workbook
Name IQ_CH: 110000
Name IQ_CQ: 5000
Name IQ_CY: 10000
Name IQ_DAILY: 500000
Name IQ_FH: 100000
Name IQ_FQ: 500
Name IQ_FY: 1000
Name IQ_LTM: 2000
Name IQ_MONTH: 15000
Name IQ_NTM: 6000
Name IQ_WEEK: 50000
Name IQ_YTD: 3000

Sheet Cover Sheet
B2: Starbucks Corporation (NasdaqGS:SBUX), 10 Years Valuation
B3: Prepared by:
B4: Shaira Katuwal
B6: Kelley Deliverables Affirmation:
B7: As a Kelley student, I will act professionally with civility and respect toward others and with honor and integrity in all my work.
B8: I have neither given nor received unauthorized aid on this deliverable.
B10: Overview:
B11: Segment | C11: Description | D11: FY2023 % of Total Revenue (approx.)
B12: North America | C12: Primarily U.S. and Canada company-operated and licensed stores | D12: 0.73
B13: International | C13: Company-operated and licensed stores outside North America | D13: 0.23
B14: Channel Development | C14: Packaged coffee, tea, and ready-to-drink products sold through grocery stores and partners | D14: 0.04
B16: Starting Comments:
B17: Starbucks uses a 52/53-week fiscal year calendar (not a fixed “December 31” calendar year).
B18: Most fiscal years have 52 weeks. Every 5-6 years, one year has 53 weeks to realign the calendar.
B19: The extra week usually lands in the last quarter (Q4).
B20: Did not adjust these to exactly 365-day years because: The difference between 52 and 53 weeks is only about 2% of a year, which is immaterial in most valuation or forecasting contexts.
B21: Resources used: Capital IQ, AI tools, Professor Damodaran's website
B23: Summary of valuation
B24: Based on the pro forma financials, Starbucks’ Enterprise Value (EV) is estimated at $105.3B, leading to an Equity Value of $84.5B and an implied share price of $78.89 (based on 1,054.9 million shares outstanding). The valuation uses a Discounted Cash Flow (DCF) approach with forecasted Free Cash Flow to the Firm (FCFF) from 2025-2034 and a terminal value (TV) calculated using a perpetuity growth model.
B25: Key assumptions and adjustments
B26: Revenue & NOPAT growth: Forecasted based on historical growth trends and Starbucks’ guidance.
B27: CapEx stabilization: After 2030, CapEx assumed to stabilize at approx. 4-5% of sales, in line with historical Starbucks performance, to prevent negative FCFF.
B28: Net Working Capital (NWC): Historical trend of negative NWC continues, reflecting Starbucks’ operational efficiency.
... B44: Share repurchases, dividends, or changes in capital structure beyond historical trends are not explicitly modeled.

Sheet Historical Balance Sheet
A2: All values are in USD (in millions)
A3: Balance Sheet as of: | B3: Sep-27-2015 | C3: Oct-02-2016 | D3: Oct-01-2017 | E3: Sep-30-2018 | F3: Sep-29-2019 | G3: Sep-27-2020 | H3: Oct-03-2021 | I3: Oct-02-2022 | J3: Oct-01-2023 | K3: Sep-29-2024
A4: ASSETS
A5: Current Assets
A6: Cash and Cash Equivalents | B6: 1530.1 | C6: 2128.8 | D6: 2462.3 | E6: 8756.3 | F6: 2686.6 | G6: 4350.9 | H6: 6455.7 | I6: 2818.4 | J6: 3551.5 | K6: 3286.2
A7: Short-term Investments | B7: 81.3 | C7: 134.4 | D7: 228.6 | E7: 181.5 | F7: 70.5 | G7: 281.2 | H7: 162.2 | I7: 364.5 | J7: 401.5 | K7: 257
A8: Trading Asset Securities | B8: 0 | C8: 0 | D8: 0 | E8: 0 | F8: 0 | G8: 0 | H8: 0 | I8: 0 | J8: 0.4 | K8: 0
A9: Total Cash & ST Investments | B9: =SUM(B6:B8) -> 1611.4 | C9: =SUM(C6:C8) -> 2263.2 | D9: =SUM(D6:D8) -> 2690.9 | E9: =SUM(E6:E8) -> 8937.8 | F9: =SUM(F6:F8) -> 2757.1 | G9: =SUM(G6:G8) -> 4632.1 | H9: =SUM(H6:H8) -> 6617.9 | I9: =SUM(I6:I8) -> 3182.9 | ... K9: =SUM(K6:K8) -> 3543.2
A10: Accounts Receivable, Net | B10: 719 | C10: 768.8 | D10: 870.4 | E10: 693.1 | F10: 879.2 | G10: 883.4 | H10: 940 | I10: 1175.5 | J10: 1184.1 | K10: 1213.8
A11: Other Receivable | B11: 0 | C11: 0 | D11: 68 | E11: 955.4 | F11: 141.1 | G11: 512 | H11: 193.1 | I11: 69.4 | J11: 0 | K11: 0
A12: Total Receivables | B12: =SUM(B10:B11) -> 719 | C12: =SUM(C10:C11) -> 768.8 | D12: =SUM(D10:D11) -> 938.4 | E12: =SUM(E10:E11) -> 1648.5 | F12: =SUM(F10:F11) -> 1020.3 | G12: =SUM(G10:G11) -> 1395.4 | H12: =SUM(H10:H11) -> 1133.1 | I12: =SUM(I10:I11) -> 1244.9 | ... K12: =SUM(K10:K11) -> 1213.8
A13: Inventories | B13: 1306.4 | C13: 1378.5 | D13: 1364 | E13: 1400.5 | F13: 1529.4 | G13: 1551.4 | H13: 1603.9 | I13: 2176.6 | J13: 1806.4 | K13: 1777.3
A14: Prepaid Expenses | B14: 283.4 | C14: 319.7 | D14: 276.7 | E14: 482.9 | F14: 334.5 | G14: 211.9 | H14: 253.9 | I14: 339.2 | J14: 298.3 | K14: 292
A15: Restricted Cash | B15: 0 | C15: 0 | D15: 0 | E15: 0 | F15: 0 | G15: 0 | H15: 0 | I15: 0 | J15: 20.6 | K15: 12.4
A16: Other Current Assets | B16: 50.8 | C16: 27.7 | D16: 13.4 | E16: 24.5 | F16: 12.6 | G16: 15.6 | H16: 147.6 | I16: 75.1 | J16: 40.6 | K16: 8.7
A17: Total Current Assets | B17: =B9+B12+SUM(B13:B16) -> 3971 | C17: =C9+C12+SUM(C13:C16) -> 4757.9 | D17: =D9+D12+SUM(D13:D16) -> 5283.4 | E17: =E9+E12+SUM(E13:E16) -> 12494.2 | F17: =F9+F12+SUM(F13:F16) -> 5653.9 | G17: =G9+G12+SUM(G13:G16) -> 7806.4 | H17: =H9+H12+SUM(H13:H16) -> 9756.4 | I17: =I9+I12+SUM(I13:I16) -> 7018.7 | ... K17: =K9+K12+SUM(K13:K16) -> 6847.4
A19: Non Current Assets
A20: Gross Property, Plant & Equipment | B20: 9641.8 | C20: 10573.3 | D20: 11584 | E20: 13197.1 | F20: 14273.5 | G20: 22289.4 | H20: 23064.8 | I20: 23625.4 | J20: 25722.8 | K20: 28727.2
A21: Accumulated Depreciation | B21: 5553.5 | C21: 6039.5 | D21: 6664.5 | E21: 7268 | F21: 7841.8 | G21: 7913.9 | H21: 8459.3 | I21: 9049.3 | J21: 9923.1 | K21: 10775.5
A22: Net Property, Plant & Equipment | B22: =B20-B21 -> 4088.3 | C22: =C20-C21 -> 4533.8 | D22: =D20-D21 -> 4919.5 | E22: =E20-E21 -> 5929.1 | F22: =F20-F21 -> 6431.7 | G22: =G20-G21 -> 14375.5 | H22: =H20-H21 -> 14605.5 | I22: =I20-I21 -> 14576.1 | ... K22: =K20-K21 -> 17951.7
A24: Long-term Investments | B24: 664.5 | C24: 1496.2 | D24: 1023.9 | E24: 602.4 | F24: 634.3 | G24: 730.6 | H24: 572.9 | I24: 590.3 | J24: 687.3 | K24: 739.9
A25: Goodwill | B25: 1575.4 | C25: 1719.6 | D25: 1539.2 | E25: 3541.6 | F25: 3490.8 | G25: 3597.2 | H25: 3677.3 | I25: 3283.5 | J25: 3218.3 | K25: 3315.7
A26: Other Intangibles | B26: 520.4 | C26: 516.3 | D26: 441.4 | E26: 1042.2 | F26: 781.8 | G26: 552.1 | H26: 349.9 | I26: 155.9 | J26: 120.5 | K26: 100.9
A27: Deferred Tax Assets, LT | B27: 1180.8 | C27: 885.4 | D27: 795.4 | E27: 134.7 | F27: 1765.8 | G27: 1789.9 | H27: 1874.8 | I27: 1799.7 | J27: 1769.8 | K27: 1766.7
A28: Other Long-Term Assets | B28: 415.9 | C28: 403.3 | D28: 362.8 | E28: 412.2 | F28: 461.3 | G28: 522.8 | H28: 555.8 | I28: 554.2 | J28: 546.5 | K28: 617
A29: Total Assets | B29: =B17+SUM(B24:B28)+B22 -> 12416.3 | C29: =C17+SUM(C24:C28)+C22 -> 14312.5 | D29: =D17+SUM(D24:D28)+D22 -> 14365.6 | E29: =E17+SUM(E24:E28)+E22 -> 24156.4 | F29: =F17+SUM(F24:F28)+F22 -> 19219.6 | G29: =G17+SUM(G24:G28)+G22 -> 29374.5 | H29: =H17+SUM(H24:H28)+H22 -> 31392.6 | I29: =I17+SUM(I24:I28)+I22 -> 27978.4 | ... K29: =K17+SUM(K24:K28)+K22 -> 31339.3
A31: LIABILITIES
A32: Accounts Payable | B32: 684.2 | C32: 730.6 | D32: 782.5 | E32: 1179.3 | F32: 1189.7 | G32: 997.9 | H32: 1211.6 | I32: 1441.4 | J32: 1544.3 | K32: 1595.5
A33: Accrued Exp. | B33: 884.3 | C33: 894.3 | D33: 891 | E33: 1218.5 | F33: 1228.7 | G33: 1179.5 | H33: 1326.7 | I33: 1273.2 | J33: 1361.2 | K33: 1323.8
A34: Short-term Borrowings | B34: 0 | C34: 0 | D34: 0 | E34: 0 | F34: 0 | G34: 438.8 | H34: 0 | I34: 175 | J34: 33.5 | K34: 0
A35: Curr. Port. of LT Debt | B35: 0 | C35: 399.9 | D35: 0 | E35: 349.9 | F35: 0 | G35: 1249.9 | H35: 998.9 | I35: 1761 | J35: 1818.6 | K35: 1248.9
A36: Curr. Port. of Leases | B36: 0 | C36: 0 | D36: 0 | E36: 0 | F36: 0 | G36: 1248.8 | H36: 1251.3 | I36: 1245.7 | J36: 1275.3 | K36: 1463.1
A37: Curr. Income Taxes Payable | B37: 259 | C37: 368.4 | D37: 226.6 | E37: 102.8 | F37: 1291.7 | G37: 98.2 | H37: 348 | I37: 139.2 | J37: 189.3 | K37: 123.5
A38: Unearned Revenue, Current | B38: 983.8 | C38: 1171.2 | D38: 1288.5 | E38: 1642.9 | F38: 1269 | G38: 1456.5 | H38: 1596.1 | I38: 1641.9 | J38: 1700.2 | K38: 1781.2
A39: Other Current Liabilities | B39: 836.8 | C39: 982.4 | D39: 1032.1 | E39: 1190.8 | F39: 1189.6 | G39: 677.2 | H39: 1418.8 | I39: 1474.4 | J39: 1422.9 | K39: 1534
A40: Total Current Liabilities | B40: =SUM(B32:B39) -> 3648.1 | C40: =SUM(C32:C39) -> 4546.8 | D40: =SUM(D32:D39) -> 4220.7 | E40: =SUM(E32:E39) -> 5684.2 | F40: =SUM(F32:F39) -> 6168.7 | G40: =SUM(G32:G39) -> 7346.8 | H40: =SUM(H32:H39) -> 8151.4 | I40: =SUM(I32:I39) -> 9151.8 | ... K40: =SUM(K32:K39) -> 9070
A42: Long-Term Debt | B42: 2347.5 | C42: 3185.3 | D42: 3932.6 | E42: 9122.7 | F42: 11169.6 | G42: 14728.9 | H42: 13618.2 | I42: 13153.9 | J42: 13589 | K42: 14338.7
A43: Long-Term Leases | B43: 0 | C43: 0 | D43: 0 | E43: 0 | F43: 0 | G43: 7661.7 | H43: 7738 | I43: 7515.2 | J43: 7924.8 | K43: 8771.6
A44: Unearned Revenue, Non-Current | B44: 0 | C44: 0 | D44: 4.4 | E44: 6775.7 | F44: 6744.4 | G44: 6598.5 | H44: 6463 | I44: 6279.7 | J44: 6101.8 | K44: 5963.6
A45: Def. Tax Liability, Non-Curr. | B45: 43.4 | C45: 14.7 | D45: 6.3 | E45: 270.2 | F45: 186.4 | G45: 158.1 | H45: 148.5 | I45: 118.6 | J45: 14.6 | K45: 21.1
...

Sheet Historical Income Statement
A2: All values are in USD (in millions)
A3: Income Statement For the Fiscal Period Ending | B3: Sep-27-2015 | C3: Oct-02-2016 | D3: Oct-01-2017 | E3: Sep-30-2018 | F3: Sep-29-2019 | G3: Sep-27-2020 | H3: Oct-03-2021 | I3: Oct-02-2022 | J3: Oct-01-2023 | K3: Sep-29-2024
A4: Revenue | B4: 19162.7 | C4: 18998.3 | D4: 20005.7 | E4: 22342.5 | F4: 24419.4 | G4: 21491.7 | H4: 27290.6 | I4: 30231.6 | J4: 33975 | K4: 34271
A5: Other Revenue | B5: 0 | C5: 2317.6 | D5: 2381.1 | E5: 2377 | F5: 2089.2 | G5: 2026.3 | H5: 1770 | I5: 2018.7 | J5: 2000.6 | K5: 1905.2
A6: Total Revenue | B6: =SUM(B4:B5) -> 19162.7 | C6: =SUM(C4:C5) -> 21315.9 | D6: =SUM(D4:D5) -> 22386.8 | E6: =SUM(E4:E5) -> 24719.5 | F6: =SUM(F4:F5) -> 26508.6 | G6: =SUM(G4:G5) -> 23518 | H6: =SUM(H4:H5) -> 29060.6 | I6: =SUM(I4:I5) -> 32250.3 | ... K6: =SUM(K4:K5) -> 36176.2
A7: Cost of Goods Sold | B7: 13198.6 | C7: 14573.3 | D7: 15552.2 | E7: 17402.9 | F7: 19020.5 | G7: 18376.9 | H7: 20625.2 | I7: 23864.9 | J7: 26106.2 | K7: 26443.8
A8: Gross Profit | B8: =B6-B7 -> 5964.1 | C8: =C6-C7 -> 6742.6 | D8: =D6-D7 -> 6834.6 | E8: =E6-E7 -> 7316.6 | F8: =F6-F7 -> 7488.1 | G8: =G6-G7 -> 5141.1 | H8: =H6-H7 -> 8435.4 | I8: =I6-I7 -> 8385.4 | ... K8: =K6-K7 -> 9732.4
A9: Selling General & Admin Exp. | B9: 1196.7 | C9: 1408.9 | D9: 1408.4 | E9: 1704.6 | F9: 1824.1 | G9: 1679.6 | H9: 1932.6 | I9: 2032 | J9: 2441.3 | K9: 2523.3
A10: R & D Exp. | B10: 0 | C10: 0 | D10: 0 | E10: 0 | F10: 0 | G10: 0 | H10: 0 | I10: 0 | J10: 0 | K10: 0
A11: Depreciation & Amort. | B11: 893.9 | C11: 980.8 | D11: 1011.4 | E11: 1247 | F11: 1377.3 | G11: 1431.3 | H11: 1441.7 | I11: 1447.9 | J11: 1362.6 | K11: 1512.6
A12: Other Operating Expense/(Income) | B12: 522.4 | C12: 499.2 | D12: 518 | E12: 554.9 | F12: 371 | G12: 430.3 | H12: 359.5 | I12: 461.5 | J12: 539.4 | K12: 565.6
A13: Other Operating Expense, Total | B13: =SUM(B9:B12) -> 2613 | C13: =SUM(C9:C12) -> 2888.9 | D13: =SUM(D9:D12) -> 2937.8 | E13: =SUM(E9:E12) -> 3506.5 | F13: =SUM(F9:F12) -> 3572.4 | G13: =SUM(G9:G12) -> 3541.2 | H13: =SUM(H9:H12) -> 3733.8 | I13: =SUM(I9:I12) -> 3941.4 | ... K13: =SUM(K9:K12) -> 4601.5
A14: Earnings Before Interest and Taxes, Operating Income EBIT | B14: =B8-B13 -> 3351.1 | C14: =C8-C13 -> 3853.7 | D14: =D8-D13 -> 3896.8 | E14: =E8-E13 -> 3810.1 | F14: =F8-F13 -> 3915.7 | G14: =G8-G13 -> 1599.9 | H14: =H8-H13 -> 4701.6 | I14: =I8-I13 -> 4444 | ... K14: =K8-K13 -> 5130.9
A15: Interest Expense | B15: 70.5 | C15: 81.3 | D15: 92.5 | E15: 170.3 | F15: 331 | G15: 437 | H15: 473.4 | I15: 482.9 | J15: 550.1 | K15: 562
A16: Interest and Invest. Income | B16: 0 | C16: 153 | D16: 16.7 | E16: 33 | F16: 131.3 | G16: 45 | H16: 69.1 | I16: 0 | J16: 93.8 | K16: 125.7
A17: Net Interest Expense | B17: =B15-B16 -> 70.5 | C17: =C15-C16 -> -71.7 | D17: =D15-D16 -> 75.8 | E17: =E15-E16 -> 137.3 | F17: =F15-F16 -> 199.7 | G17: =G15-G16 -> 392 | H17: =H15-H16 -> 404.3 | I17: =I15-I16 -> 482.9 | ... K17: =K15-K16 -> 436.3
A18: Income/(Loss) from Affiliates | B18: 249.9 | C18: 318.2 | D18: 391.4 | E18: 301.2 | F18: 298 | G18: 322.5 | H18: 385.3 | I18: 234.1 | J18: 298.4 | K18: 301.2
A19: Currency Exchange Gains (Loss) | B19: 73.3 | C19: -106.8 | D19: 62.7 | E19: 6.5 | F19: -27.9 | G19: 0.3 | H19: 20.2 | I19: 99.9 | J19: -3.1 | K19: 0.2
A20: Other Non-Operating Inc. (Expense) | B20: -24.2 | C20: 54.8 | D20: 105.9 | E20: 157.2 | F20: -7.8 | G20: -10.5 | H20: 2.6 | I20: -2.5 | J20: -7.5 | K20: -2
A21: Earnings Before Taxes (EBT Excl. Unusual Items) | B21: =B14-B17+B18+B19+B20 -> 3579.6 | C21: =C14-C17+C18+C19+C20 -> 4191.6 | D21: =D14-D17+D18+D19+D20 -> 4381 | E21: =E14-E17+E18+E19+E20 -> 4137.7 | F21: =F14-F17+F18+F19+F20 -> 3978.3 | G21: =G14-G17+G18+G19+G20 -> 1520.2 | H21: =H14-H17+H18+H19+H20 -> 4705.4 | I21: =I14-I17+I18+I19+I20 -> 4292.6 | ... K21: =K14-K17+K18+K19+K20 -> 4994
A22: Restructuring Charges | B22: 0 | C22: 0 | D22: -153.5 | E22: -224.4 | F22: -135.8 | G22: -278.7 | H22: -170.4 | I22: -46 | J22: -21.8 | K22: 0
A23: Merger & Related Restruct. Charges | B23: 0 | C23: 0 | D23: 0 | E23: -3.6 | F23: 0 | G23: 0 | H23: 0 | I23: 0 | J23: 0 | K23: 0
A24: Impairment of Goodwill | B24: 0 | C24: 0 | D24: 0 | E24: 0 | F24: 0 | G24: 0 | H24: 0 | I24: 0 | J24: 0 | K24: 0
A25: Gain (Loss) On Sale Of Invest. | B25: 391.6 | C25: 1.6 | D25: -4.1 | E25: 1372.8 | F25: 0.9 | G25: 4.9 | H25: 1.8 | I25: -0.4 | J25: -0.7 | K25: -1.2
A26: Gain (Loss) On Sale Of Assets | B26: -7.1 | C26: 5.4 | D26: 94.1 | E26: 497.5 | F26: 622.8 | G26: 0 | H26: 864.5 | I26: 0 | J26: 91.3 | K26: 0
A27: Asset Writedown | B27: 0 | C27: 0 | D27: 0 | E27: 0 | F27: 0 | G27: -109.6 | H27: -44.4 | I27: -14.3 | J27: -23.2 | K27: -23.3
A28: Other Unusual Items | B28: -61.1 | C28: 0 | D28: 0 | E28: 0 | F28: 0 | G28: 27.6 | H28: 0 | I28: 0 | J28: -1.3 | K28: 0.1
A29: Earnings Before Taxes (EBT Including Unusual Items) | B29: =B21+SUM(B22:B28) -> 3903 | C29: =C21+SUM(C22:C28) -> 4198.6 | D29: =D21+SUM(D22:D28) -> 4317.5 | E29: =E21+SUM(E22:E28) -> 5780 | F29: =F21+SUM(F22:F28) -> 4466.2 | G29: =G21+SUM(G22:G28) -> 1164.4 | H29: =H21+SUM(H22:H28) -> 5356.9 | I29: =I21+SUM(I22:I28) -> 4231.9 | ... K29: =K21+SUM(K22:K28) -> 4969.6
A30: Income Tax Expense | B30: 1143.7 | C30: 1379.7 | D30: 1432.6 | E30: 1262 | F30: 871.6 | G30: 239.7 | H30: 1156.6 | I30: 948.5 | J30: 1277.2 | K30: 1207.3
A31: Earnings from Continued Operations | B31: =B29-B30 -> 2759.3 | C31: =C29-C30 -> 2818.9 | D31: =D29-D30 -> 2884.9 | E31: =E29-E30 -> 4518 | F31: =F29-F30 -> 3594.6 | G31: =G29-G30 -> 924.7 | H31: =H29-H30 -> 4200.3 | I31: =I29-I30 -> 3283.4 | ... K31: =K29-K30 -> 3762.3
A32: Earnings of Discontinued Operations | B32: 0 | C32: 0 | D32: 0 | E32: 0 | F32: 0 | G32: 0 | H32: 0 | I32: 0 | J32: 0 | K32: 0
A33: Extraordinary Item & Account. Change | B33: 0 | C33: 0 | D33: 0 | E33: 0 | F33: 0 | G33: 0 | H33: 0 | I33: 0 | J33: 0 | K33: 0
A34: Net Income to Company | B34: =B31+B32+B33 -> 2759.3 | C34: =C31+C32+C33 -> 2818.9 | D34: =D31+D32+D33 -> 2884.9 | E34: =E31+E32+E33 -> 4518 | F34: =F31+F32+F33 -> 3594.6 | G34: =G31+G32+G33 -> 924.7 | H34: =H31+H32+H33 -> 4200.3 | I34: =I31+I32+I33 -> 3283.4 | ... K34: =K31+K32+K33 -> 3762.3
A35: Minority Interest in Earnings | B35: 1.9 | C35: 1.2 | D35: 0.2 | E35: -0.3 | F35: -4.6 | G35: -3.6 | H35: 1 | I35: 1.8 | J35: 0.2 | K35: 1.4
A36: Net Income | B36: =B34-B35 -> 2757.4 | C36: =C34-C35 -> 2817.7 | D36: =D34-D35 -> 2884.7 | E36: =E34-E35 -> 4518.3 | F36: =F34-F35 -> 3599.2 | G36: =G34-G35 -> 928.3 | H36: =H34-H35 -> 4199.3 | I36: =I34-I35 -> 3281.6 | ... K36: =K34-K35 -> 3760.9
A37: Pref. Dividends and Other Adjustment | B37: 0 | C37: 0 | D37: 0 | E37: 0 | F37: 0 | G37: 0 | H37: 0 | I37: 0 | J37: 0 | K37: 0
A38: NI to Common Incl Extra Items | B38: =B36+B37 -> 2757.4 | C38: =C36+C37 -> 2817.7 | D38: =D36+D37 -> 2884.7 | E38: =E36+E37 -> 4518.3 | F38: =F36+F37 -> 3599.2 | G38: =G36+G37 -> 928.3 | H38: =H36+H37 -> 4199.3 | I38: =I36+I37 -> 3281.6 | ... K38: =K36+K37 -> 3760.9
A39: NI to Common Excl. Extra Items | B39: =B36 -> 2757.4 | C39: =C36 -> 2817.7 | D39: =D36 -> 2884.7 | E39: =E36 -> 4518.3 | F39: =F36 -> 3599.2 | G39: =G36 -> 928.3 | H39: =H36 -> 4199.3 | I39: =I36 -> 3281.6 | ... K39: =K36 -> 3760.9
A41: Per Share Items
A42: Basic EPS | B42: 1.84 | C42: 1.91 | D42: 1.99 | E42: 3.27 | F42: 2.95 | G42: 0.79 | H42: 3.57 | I42: 2.85 | J42: 3.6 | K42: 3.32
...

Sheet Historical CashFlow Statement
A2: All values are in USD (in millions)
A3: Cash Flow Statement For the Fiscal Period Ending | B3: 12 months Sep-27-2015 | C3: 12 months Oct-02-2016 | D3: 12 months Oct-01-2017 | E3: 12 months Sep-30-2018 | F3: 12 months Sep-29-2019 | G3: 12 months Sep-27-2020 | H3: 12 months Oct-03-2021 | I3: 12 months Oct-02-2022 | J3: 12 months Oct-01-2023 | K3: 12 months Sep-29-2024
A4: Operating Activities
A5: Net Earnings, Including Noncontrolling Interests | B5: 2759.3 | C5: 2818.9 | D5: 2884.9 | E5: 4518 | F5: 3594.6 | G5: 924.7 | H5: 4200.3 | I5: 3283.4 | J5: 4124.7 | K5: 3762.3
A6: Depreciation and Amortization | B6: 933.8 | C6: 1030.1 | D6: 1067.1 | E6: 1305.9 | F6: 1449.3 | G6: 1503.2 | H6: 1524.1 | I6: 1529.4 | J6: 1450.3 | K6: 1592.4
A7: Gain on Sale of Assets | B7: - | C7: - | D7: - | E7: - | F7: - | G7: - | H7: - | I7: - | J7: -91.3 | K7: -
A8: Loss on Retirement and Impairment of Assets | B8: - | C8: - | D8: - | E8: 75.6 | F8: 142.6 | G8: 454.4 | H8: 226.2 | I8: 91.4 | J8: 101.4 | K8: 121.5
A9: Net Gain Resulting from Divestiture of Certain Retail Operations | B9: - | C9: -6.1 | D9: -93.5 | E9: -499.2 | F9: -622.8 | G9: - | H9: -864.5 | I9: - | J9: - | K9: -
A10: Gain Resulting from Sale/acquisition of Equity in Joint Ventures | B10: - | C10: - | D10: - | E10: -1376.4 | F10: - | G10: - | H10: - | I10: - | J10: - | K10: -
A11: Goodwill Impairments | B11: - | C11: - | D11: 87.2 | E11: 37.6 | F11: 10.5 | G11: - | H11: - | I11: - | J11: - | K11: -
A12: Gain Resulting from Acquisition/sale of Equity in Joint Ventures and Certain Retail Operations | B12: -394.3 | C12: - | D12: - | E12: - | F12: - | G12: - | H12: - | I12: - | J12: - | K12: -
A13: Equity in (Income)/losses of Investees | B13: -190.2 | C13: -250.2 | D13: -310.2 | E13: -242.8 | F13: -250.6 | G13: -280.7 | H13: -347.3 | I13: -268.7 | J13: -301.8 | K13: -306.4
A14: Distributions Received from Equity Method Investees | B14: 148.2 | C14: 223.3 | D14: 186.6 | E14: 226.8 | F14: 216.8 | G14: 227.7 | H14: 336 | I14: 231.2 | J14: 222.8 | K14: 333.3
A15: Stock based Compensation | B15: 209.8 | C15: 218.1 | D15: 176 | E15: 250.3 | F15: 308 | G15: 248.6 | H15: 319.1 | I15: 271.5 | J15: 302.7 | K15: 308.3
A16: Excess Tax Benefit from Exercise of Stock Options | B16: -132.4 | C16: - | D16: - | E16: - | F16: - | G16: - | H16: - | I16: - | J16: - | K16: -
A17: Deferred Income Taxes, Net | B17: 21.2 | C17: 265.7 | D17: 95.1 | E17: 714.9 | F17: -1495.4 | G17: -25.8 | H17: -146.2 | I17: -37.8 | J17: -59.4 | K17: -13.8
A18: Others | B18: 53.8 | C18: 45.1 | D18: 68.9 | E18: 13.4 | F18: 45.3 | G18: 24.5 | H18: -6 | I18: -67.8 | J18: 26.8 | K18: 31.9
A19: Loss on Extinguishment of Debt | B19: 61.1 | C19: - | D19: - | E19: - | F19: - | G19: - | H19: - | I19: - | J19: - | K19: -
A20: Non-cash Lease Costs | B20: - | C20: - | D20: - | E20: - | F20: - | G20: 1197.6 | H20: 1248.6 | I20: 1497.7 | J20: 1365.9 | K20: 1314.9
A21: Accounts Receivable | B21: -82.8 | C21: -55.6 | D21: -96.8 | E21: 131 | F21: -197.7 | G21: -2.7 | H21: -43 | I21: -326.1 | J21: -4.1 | K21: 18.4
A22: Inventories | B22: -207.9 | C22: -67.5 | D22: 14 | E22: -41.2 | F22: -173 | G22: -10.9 | H22: -49.8 | I22: -641 | J22: 366.4 | K22: 42.8
A23: Change in Accounts Payable | B23: 137.7 | C23: 46.9 | D23: 46.4 | E23: 391.6 | F23: 31.9 | G23: -210.8 | H23: 189.9 | I23: 345.5 | J23: 100.1 | K23: 28
A24: Income Taxes Payables | B24: - | C24: - | D24: -91.9 | E24: 146 | F24: 1237.1 | G24: -1214.6 | H24: 286.1 | I24: -149.6 | J24: 52.5 | K24: -61.9
A25: Deferred Revenue | B25: - | C25: 180.4 | D25: 130.8 | E25: 7109.4 | F25: -30.5 | G25: 31 | H25: -6.1 | I25: -75.8 | J25: -110.8 | K25: -72.2
A26: Stored Value Card Liability | B26: 170.3 | C26: - | D26: - | E26: - | F26: - | G26: - | H26: - | I26: - | J26: - | K26: -
A27: Prepaid Expenses and Other Current Assets | B27: - | C27: - | D27: -20 | E27: -839.5 | F27: 922 | G27: - | H27: - | I27: - | J27: - | K27: -
A28: Other Operating Assets and Liabilities | B28: 261.5 | C28: 248.8 | D28: 107.2 | E28: 16.4 | F28: -141.1 | G28: -37 | H28: 609.8 | I28: 339.6 | J28: -93.7 | K28: 291
A29: Operating Lease Liability | B29: - | C29: - | D29: - | E29: - | F29: - | G29: -1231.4 | H29: -1488.1 | I29: -1625.6 | J29: -1443.8 | K29: -1294.9
A30: Cash Flow from Operating Activities | B30: 3749.1 | C30: 4697.9 | D30: 4251.8 | E30: 11937.8 | F30: 5047 | G30: 1597.8 | H30: 5989.1 | I30: 4397.3 | J30: 6008.7 | K30: 6095.6
A32: Investing Activities
A33: Others | B33: 6.8 | C33: 24.9 | D33: 54.3 | E33: 5.6 | F33: -56.2 | G33: -44.4 | H33: -81.2 | I33: -126.3 | J33: -56.1 | K33: -72.7
A34: Additions to Property Plant and Equipment | B34: -1303.7 | C34: -1440.3 | D34: -1519.4 | E34: -1976.4 | F34: -1806.6 | G34: -1483.6 | H34: -1470 | I34: -1841.3 | J34: -2333.6 | K34: -2777.5
A35: Proceeds from the Sale of Property, Plant & Equipment | B35: - | C35: - | D35: - | E35: - | F35: - | G35: - | H35: - | I35: - | J35: 110 | K35: -
A36: Acquisitions, Net of Cash Acquired | B36: -284.3 | C36: - | D36: - | E36: -1311.3 | F36: - | G36: - | H36: - | I36: - | J36: - | K36: -
A37: Net Proceeds from the Divestiture of Certain Operations | B37: - | C37: 69.6 | D37: 85.4 | E37: 608.2 | F37: 684.3 | G37: - | H37: 1175 | I37: 59.3 | J37: - | K37: -
A38: Proceeds from Sale of Equity in Joint Ventures and Certain Retail Operations | B38: 8.9 | C38: - | D38: - | E38: - | F38: - | G38: - | H38: - | I38: - | J38: - | K38: -
A39: Purchase of Investments | B39: -567.4 | C39: -1585.7 | D39: -674.4 | E39: -191.9 | F39: -190.4 | G39: -443.9 | H39: -432 | I39: -377.9 | J39: -610.5 | K39: -627.5
A40: Sale of Investment | B40: 600.6 | C40: 680.7 | D40: 1054.5 | E40: 459 | F40: 298.3 | G40: 186.7 | H40: 143.2 | I40: 72.6 | J40: 2.5 | K40: 10.3
A41: Maturities and Calls of Investments | B41: 18.8 | C41: 27.9 | D41: 149.6 | E41: 45.3 | F41: 59.8 | G41: 73.7 | H41: 345.5 | I41: 67.3 | J41: 616.9 | K41: 768.2
A42: Cash Flow from Investing Activities | B42: -1520.3 | C42: -2222.9 | D42: -850 | E42: -2361.5 | F42: -1010.8 | G42: -1711.5 | H42: -319.5 | I42: -2146.3 | J42: -2270.8 | K42: -2699.2
...

Sheet Real Revenue
A1: (All values are in $million USD)
A3: Net Sales as of: | B3: 2015 | C3: =B3+1 -> 2016 | D3: =C3+1 -> 2017 | E3: =D3+1 -> 2018 | F3: =E3+1 -> 2019 | G3: =F3+1 -> 2020 | H3: =G3+1 -> 2021 | I3: =H3+1 -> 2022 | J3: =I3+1 -> 2023 | K3: =J3+1 -> 2024
A4: Net Revenue (millions) | B4: ='Historical Income Statement'!B6 -> 19162.7 | C4: ='Historical Income Statement'!C6 -> 21315.9 | D4: ='Historical Income Statement'!D6 -> 22386.8 | E4: ='Historical Income Statement'!E6 -> 24719.5 | F4: ='Historical Income Statement'!F6 -> 26508.6 | G4: ='Historical Income Statement'!G6 -> 23518 | H4: ='Historical Income Statement'!H6 -> 29060.6 | I4: ='Historical Income Statement'!I6 -> 32250.3 | ... K4: ='Historical Income Statement'!K6 -> 36176.2
A7: Real Sales (in 2024 USD) | B7: =B3 -> 2015 | C7: =C3 -> 2016 | D7: =D3 -> 2017 | E7: =E3 -> 2018 | F7: =F3 -> 2019 | G7: =G3 -> 2020 | H7: =H3 -> 2021 | I7: =I3 -> 2022 | ... K7: =K3 -> 2024
A8: Net Real Revenue (millions) | B8: =B4*C17 -> 25569.576 | C8: =C4*C18 -> 27864.594 | D8: =D4*C19 -> 28660.033 | E8: =E4*C20 -> 31053.237 | F8: =F4*C21 -> 32556.783 | G8: =G4*C22 -> 28495.736 | H8: =H4*C23 -> 32896.718 | I8: =I4*C24 -> 34293.999 | J8: =J4*C25 -> 37014.596 | K8: =K4*C26 -> 36176.2
A10: Real Annual Revenue Growth Rates, 2015-2024 | B10: =B7 -> 2015 | C10: =C7 -> 2016 | D10: =D7 -> 2017 | E10: =E7 -> 2018 | F10: =F7 -> 2019 | G10: =G7 -> 2020 | H10: =H7 -> 2021 | I10: =I7 -> 2022 | ... K10: =K7 -> 2024 | L10: Average Growth Rate Over the Period
A11: Real Growth Rate | C11: =(C8/B8)-1 -> 0.089755809 | D11: =(D8/C8)-1 -> 0.028546597 | E11: =(E8/D8)-1 -> 0.083503165 | F11: =(F8/E8)-1 -> 0.04841834 | G11: =(G8/F8)-1 -> -0.12473734 | H11: =(H8/G8)-1 -> 0.15444351 | I11: =(I8/H8)-1 -> 0.042474787 | J11: =(J8/I8)-1 -> 0.079331583 | K11: =(K8/J8)-1 -> -0.022650414 | L11: {=GEOMEAN(1+C11:K11)-1} -> 0.039308263
A12: Real GDP (Start of Year) | B12: 18666.621 | C12: 19001.69 | D12: 19398.343 | E12: 20044.077 | F12: 20431.641 | G12: 20709.212 | H12: 21082.134 | I12: 21932.71 | J12: 22439.607 | K12: 23082.119
A13: Real GDP Growth Rate | C13: =(C12-B12)/B12 -> 0.017950169 | D13: =(D12-C12)/C12 -> 0.020874617 | E13: =(E12-D12)/D12 -> 0.033288101 | F13: =(F12-E12)/E12 -> 0.019335587 | G13: =(G12-F12)/F12 -> 0.01358535 | H13: =(H12-G12)/G12 -> 0.018007542 | I13: =(I12-H12)/H12 -> 0.040345821 | J13: =(J12-I12)/I12 -> 0.023111462 | K13: =(K12-J12)/J12 -> 0.028632944 | L13: {=GEOMEAN(1+C13:K13)-1} -> 0.02387173
A14: Correlation, Real Sales vs Real GDP | B14: =CORREL(C11:K11,C13:K13) -> 0.15573221
A16: Year | B16: CPI (September) | C16: Adjustment Factor | D16: Rate of Growth
A17: 2015 | B17: 236.525 | C17: =$B$26/B17 -> 1.334341
A18: =A17+1 -> 2016 | B18: 241.432 | C18: =$B$26/B18 -> 1.3072211 | D18: =(B18-B17)/B17 -> 0.020746221
A19: =A18+1 -> 2017 | B19: 246.524 | C19: =$B$26/B19 -> 1.2802202 | D19: =(B19-B18)/B18 -> 0.021090825
A20: =A19+1 -> 2018 | B20: 251.233 | C20: =$B$26/B20 -> 1.2562243 | D20: =(B20-B19)/B19 -> 0.019101588
A21: =A20+1 -> 2019 | B21: 256.974 | C21: =$B$26/B21 -> 1.2281593 | D21: =(B21-B20)/B20 -> 0.022851297
A22: =A21+1 -> 2020 | B22: 260.474 | C22: =$B$26/B22 -> 1.2116564 | D22: =(B22-B21)/B21 -> 0.013620055
A23: =A22+1 -> 2021 | B23: 278.802 | C23: =$B$26/B23 -> 1.1320041 | D23: =(B23-B22)/B22 -> 0.070364029
A24: =A23+1 -> 2022 | B24: 296.797 | C24: =$B$26/B24 -> 1.0633699 | D24: =(B24-B23)/B23 -> 0.064544013
A25: =A24+1 -> 2023 | B25: 306.746 | C25: =$B$26/B25 -> 1.0288806 | D25: =(B25-B24)/B24 -> 0.033521228
A26: =A25+1 -> 2024 | B26: 315.605 | C26: =$B$26/B26 -> 1 | D26: =(B26-B25)/B25 -> 0.028880572
A29: Additional Comments:
A30: The -2.27%: Under normal circumstances, we would disregard this figure when calcultaing the average growth rate. However, since the growth rate in 2020 was negative due to the effect of the pandemic, whose effects are going to be felt in the upcoming years, we shall include this figure in our calculations.
A31: Correlation measures the linear relationship between Starbucks real sales growth and US real GDP growth.
A32: A low correlation means that Starbucks’ sales don’t strongly move with the economy, they are relatively independent of GDP trends. Hence, good argument for NOT using expected growth in GDP approach to forecast sales.
A33: Correlation measures the linear relationship between Starbucks real sales growth and US real GDP growth.
A34: A low correlation means that Starbucks’ sales don’t strongly move with the economy, they are relatively independent of GDP trends. Hence, good argument for NOT using expected growth in GDP approach to forecast sales.
A35: The “Real GDP (Start of Year)” numbers are the same no matter which company you are valuing, because they come from official macroeconomic data (BEA/FRED) and represent the entire US economy.

Sheet Real Operating Costs
A1: (All values are in $million)
B2: 2015 | C2: =B2+1 -> 2016 | D2: =C2+1 -> 2017 | E2: =D2+1 -> 2018 | F2: =E2+1 -> 2019 | G2: =F2+1 -> 2020 | H2: =G2+1 -> 2021 | I2: =H2+1 -> 2022 | J2: =I2+1 -> 2023 | K2: =J2+1 -> 2024
A3: Revenues | B3: ='Historical Income Statement'!B6 -> 19162.7 | C3: ='Historical Income Statement'!C6 -> 21315.9 | D3: ='Historical Income Statement'!D6 -> 22386.8 | E3: ='Historical Income Statement'!E6 -> 24719.5 | F3: ='Historical Income Statement'!F6 -> 26508.6 | G3: ='Historical Income Statement'!G6 -> 23518 | H3: ='Historical Income Statement'!H6 -> 29060.6 | I3: ='Historical Income Statement'!I6 -> 32250.3 | ... K3: ='Historical Income Statement'!K6 -> 36176.2
A5: Expenses:
A6: Cost of goods sold | B6: ='Historical Income Statement'!B7 -> 13198.6 | C6: ='Historical Income Statement'!C7 -> 14573.3 | D6: ='Historical Income Statement'!D7 -> 15552.2 | E6: ='Historical Income Statement'!E7 -> 17402.9 | F6: ='Historical Income Statement'!F7 -> 19020.5 | G6: ='Historical Income Statement'!G7 -> 18376.9 | H6: ='Historical Income Statement'!H7 -> 20625.2 | I6: ='Historical Income Statement'!I7 -> 23864.9 | ... K6: ='Historical Income Statement'!K7 -> 26443.8
A7: Selling General & Admin Exp. | B7: ='Historical Income Statement'!B9 -> 1196.7 | C7: ='Historical Income Statement'!C9 -> 1408.9 | D7: ='Historical Income Statement'!D9 -> 1408.4 | E7: ='Historical Income Statement'!E9 -> 1704.6 | F7: ='Historical Income Statement'!F9 -> 1824.1 | G7: ='Historical Income Statement'!G9 -> 1679.6 | H7: ='Historical Income Statement'!H9 -> 1932.6 | I7: ='Historical Income Statement'!I9 -> 2032 | ... K7: ='Historical Income Statement'!K9 -> 2523.3
A8: Depreciation and Amortization | B8: ='Historical Income Statement'!B11 -> 893.9 | C8: ='Historical Income Statement'!C11 -> 980.8 | D8: ='Historical Income Statement'!D11 -> 1011.4 | E8: ='Historical Income Statement'!E11 -> 1247 | F8: ='Historical Income Statement'!F11 -> 1377.3 | G8: ='Historical Income Statement'!G11 -> 1431.3 | H8: ='Historical Income Statement'!H11 -> 1441.7 | I8: ='Historical Income Statement'!I11 -> 1447.9 | ... K8: ='Historical Income Statement'!K11 -> 1512.6
A9: Other Operating Expense/(Income) | B9: ='Historical Income Statement'!B12 -> 522.4 | C9: ='Historical Income Statement'!C12 -> 499.2 | D9: ='Historical Income Statement'!D12 -> 518 | E9: ='Historical Income Statement'!E12 -> 554.9 | F9: ='Historical Income Statement'!F12 -> 371 | G9: ='Historical Income Statement'!G12 -> 430.3 | H9: ='Historical Income Statement'!H12 -> 359.5 | I9: ='Historical Income Statement'!I12 -> 461.5 | ... K9: ='Historical Income Statement'!K12 -> 565.6
A10: Adjusted Net Operating Costs | B10: =B6+B7-B8+B9 -> 14023.8 | C10: =C6+C7-C8+C9 -> 15500.6 | D10: =D6+D7-D8+D9 -> 16467.2 | E10: =E6+E7-E8+E9 -> 18415.4 | F10: =F6+F7-F8+F9 -> 19838.3 | G10: =G6+G7-G8+G9 -> 19055.5 | H10: =H6+H7-H8+H9 -> 21475.6 | I10: =I6+I7-I8+I9 -> 24910.5 | ... K10: =K6+K7-K8+K9 -> 28020.1
A14: Real Sales (in 2024 USD) | B14: =B2 -> 2015 | C14: =C2 -> 2016 | D14: =D2 -> 2017 | E14: =E2 -> 2018 | F14: =F2 -> 2019 | G14: =G2 -> 2020 | H14: =H2 -> 2021 | I14: =I2 -> 2022 | ... K14: =K2 -> 2024
A15: Net Real Costs (millions) | B15: =B10*C24 -> 18712.531 | C15: =C10*C25 -> 20262.711 | D15: =D10*C26 -> 21081.642 | E15: =E10*C27 -> 23133.873 | F15: =F10*C28 -> 24364.592 | G15: =G10*C29 -> 23088.719 | H15: =H10*C30 -> 24310.467 | I15: =I10*C31 -> 26489.076 | J15: =J10*C32 -> 28524.994 | K15: =K10*C33 -> 28020.1
A16: Net Real Revenue (millions) | B16: ='Real Revenue'!B8 -> 25569.576 | C16: ='Real Revenue'!C8 -> 27864.594 | D16: ='Real Revenue'!D8 -> 28660.033 | E16: ='Real Revenue'!E8 -> 31053.237 | F16: ='Real Revenue'!F8 -> 32556.783 | G16: ='Real Revenue'!G8 -> 28495.736 | H16: ='Real Revenue'!H8 -> 32896.718 | I16: ='Real Revenue'!I8 -> 34293.999 | ... K16: ='Real Revenue'!K8 -> 36176.2
A17: Correlation, Real Costs vs Real Sales | B17: =CORREL(B15:K15,B16:K16) -> 0.97612696
A19: Real Annual Revenue Growth Rates, 2015-2024 | B19: =B14 -> 2015 | C19: =C14 -> 2016 | D19: =D14 -> 2017 | E19: =E14 -> 2018 | F19: =F14 -> 2019 | G19: =G14 -> 2020 | H19: =H14 -> 2021 | I19: =I14 -> 2022 | ... K19: =K14 -> 2024
A20: Real Growth Rate | C20: =(C15/B15)-1 -> 0.082841817 | D20: =(D15/C15)-1 -> 0.040415652 | E20: =(E15/D15)-1 -> 0.097346841 | F20: =(F15/E15)-1 -> 0.053199869 | G20: =(G15/F15)-1 -> -0.052365855 | H20: =(H15/G15)-1 -> 0.052915338 | I20: =(I15/H15)-1 -> 0.089616112 | J20: =(J15/I15)-1 -> 0.076858756 | K20: =(K15/J15)-1 -> -0.017700044
A23: Year | B23: CPI (September) | C23: Adjustment Factor | D23: Rate of Growth
A24: 2015 | B24: 236.525 | C24: =$B$33/B24 -> 1.334341
A25: =A24+1 -> 2016 | B25: 241.432 | C25: =$B$33/B25 -> 1.3072211 | D25: =(B25-B24)/B24 -> 0.020746221
A26: =A25+1 -> 2017 | B26: 246.524 | C26: =$B$33/B26 -> 1.2802202 | D26: =(B26-B25)/B25 -> 0.021090825
A27: =A26+1 -> 2018 | B27: 251.233 | C27: =$B$33/B27 -> 1.2562243 | D27: =(B27-B26)/B26 -> 0.019101588
A28: =A27+1 -> 2019 | B28: 256.974 | C28: =$B$33/B28 -> 1.2281593 | D28: =(B28-B27)/B27 -> 0.022851297
A29: =A28+1 -> 2020 | B29: 260.474 | C29: =$B$33/B29 -> 1.2116564 | D29: =(B29-B28)/B28 -> 0.013620055
A30: =A29+1 -> 2021 | B30: 278.802 | C30: =$B$33/B30 -> 1.1320041 | D30: =(B30-B29)/B29 -> 0.070364029
A31: =A30+1 -> 2022 | B31: 296.797 | C31: =$B$33/B31 -> 1.0633699 | D31: =(B31-B30)/B30 -> 0.064544013
A32: =A31+1 -> 2023 | B32: 306.746 | C32: =$B$33/B32 -> 1.0288806 | D32: =(B32-B31)/B31 -> 0.033521228
A33: =A32+1 -> 2024 | B33: 315.605 | C33: =$B$33/B33 -> 1 | D33: =(B33-B32)/B32 -> 0.028880572
A35: Additional Comments:
A36: Calculation of Net Real Operating Costs = COGS + SG&A − Depreciation caused problems:
A37: Depreciation is non-cash, so subtracting just that made costs artificially small in later years.
A38: This led to the weird negative correlation with revenue. To fix this, added other expenses to the calculation
A39: Correlation = 0.98 is very high and positive, almost perfect.
A40: This means that Net Real Operating Costs increase almost proportionally with Real Revenue.
A41: In other words, as Starbucks earns more revenue, its costs rise in a very predictable way.
A42: This is exactly what we expect for a stable operating business, revenues and operating expenses are strongly linked.

Sheet Forecasting Sales
A2: Real Sales (in 2024 USD) | B2: 2015 | C2: 2016 | D2: 2017 | E2: 2018 | F2: 2019 | G2: 2020 | H2: 2021 | I2: 2022 | J2: 2023 | K2: 2024
A3: Net Real Revenue (millions) | B3: ='Real Operating Costs'!B16 -> 25569.576 | C3: ='Real Operating Costs'!C16 -> 27864.594 | D3: ='Real Operating Costs'!D16 -> 28660.033 | E3: ='Real Operating Costs'!E16 -> 31053.237 | F3: ='Real Operating Costs'!F16 -> 32556.783 | G3: ='Real Operating Costs'!G16 -> 28495.736 | H3: ='Real Operating Costs'!H16 -> 32896.718 | I3: ='Real Operating Costs'!I16 -> 34293.999 | ... K3: ='Real Operating Costs'!K16 -> 36176.2
A4: Net Real Operating Costs (millions) | B4: ='Real Operating Costs'!B15 -> 18712.531 | C4: ='Real Operating Costs'!C15 -> 20262.711 | D4: ='Real Operating Costs'!D15 -> 21081.642 | E4: ='Real Operating Costs'!E15 -> 23133.873 | F4: ='Real Operating Costs'!F15 -> 24364.592 | G4: ='Real Operating Costs'!G15 -> 23088.719 | H4: ='Real Operating Costs'!H15 -> 24310.467 | I4: ='Real Operating Costs'!I15 -> 26489.076 | ... K4: ='Real Operating Costs'!K15 -> 28020.1
A21: Period | B21: Net Real Revenue (millions) | C21: Forecasts
A22: 2015 | B22: 25569.576
A23: 2016 | B23: 27864.594
A24: 2017 | B24: 28660.033
A25: 2018 | B25: 31053.237
A26: 2019 | B26: 32556.783
A27: 2021 | B27: 32896.718 | C27: Excluding year 2020: COVID
A28: 2022 | B28: 34293.999
A29: 2023 | B29: 37014.596 | C29: FORECAST.LINEAR Approach
A30: 2024 | B30: 36176.2 | C30: Projected Sales | D30: Projected Growth Rates
A31: 2025 | C31: =_xlfn.FORECAST.LINEAR(A31,$B$22:$B$30,$A$22:$A$30) -> 38288.669 | D31: =(C31-B29)/B29 -> 0.034420842 | E31: Slight post-COVID normalization
A32: 2026 | C32: =_xlfn.FORECAST.LINEAR(A32,$B$22:$B$30,$A$22:$A$30) -> 39458.915 | D32: =(C32-C31)/C31 -> 0.030563763
A33: 2027 | C33: =_xlfn.FORECAST.LINEAR(A33,$B$22:$B$30,$A$22:$A$30) -> 40629.161 | D33: =(C33-C32)/C32 -> 0.029657324 | E33: Growth rate decreasing hereon, Reflects mature company stabilization
A34: 2028 | C34: =_xlfn.FORECAST.LINEAR(A34,$B$22:$B$30,$A$22:$A$30) -> 41799.407 | D34: =(C34-C33)/C33 -> 0.028803101
A35: 2029 | C35: =_xlfn.FORECAST.LINEAR(A35,$B$22:$B$30,$A$22:$A$30) -> 42969.653 | D35: =(C35-C34)/C34 -> 0.027996709
A36: 2030 | C36: =_xlfn.FORECAST.LINEAR(A36,$B$22:$B$30,$A$22:$A$30) -> 44139.899 | D36: =(C36-C35)/C35 -> 0.02723424
A37: 2031 | C37: =_xlfn.FORECAST.LINEAR(A37,$B$22:$B$30,$A$22:$A$30) -> 45310.144 | D37: =(C37-C36)/C36 -> 0.0265122
A38: 2032 | C38: =_xlfn.FORECAST.LINEAR(A38,$B$22:$B$30,$A$22:$A$30) -> 46480.39 | D38: =(C38-C37)/C37 -> 0.025827457
A39: 2033 | C39: =_xlfn.FORECAST.LINEAR(A39,$B$22:$B$30,$A$22:$A$30) -> 47650.636 | D39: =(C39-C38)/C38 -> 0.025177194
A40: 2034 | C40: =_xlfn.FORECAST.LINEAR(A40,$B$22:$B$30,$A$22:$A$30) -> 48820.882 | D40: =(C40-C39)/C39 -> 0.024558871
C42: Additional Commment: I used FORECAST.LINEAR() because the trend is mostly linear beside COVID year where the dip is an outlier. Excluding year 2020 as an outlier, 2020 was a pandemic shock year, not representative of Starbucks’ long-term fundamentals.

Sheet Forecasting Costs
A2: Period | B2: 2015 | C2: =B2+1 -> 2016 | D2: =C2+1 -> 2017 | E2: =D2+1 -> 2018 | F2: =E2+1 -> 2019 | G2: =F2+1 -> 2020 | H2: =G2+1 -> 2021 | I2: =H2+1 -> 2022 | J2: =I2+1 -> 2023 | K2: =J2+1 -> 2024
A3: Net Real Revenue (millions) | B3: ='Real Operating Costs'!B16 -> 25569.576 | C3: ='Real Operating Costs'!C16 -> 27864.594 | D3: ='Real Operating Costs'!D16 -> 28660.033 | E3: ='Real Operating Costs'!E16 -> 31053.237 | F3: ='Real Operating Costs'!F16 -> 32556.783 | G3: ='Real Operating Costs'!G16 -> 28495.736 | H3: ='Real Operating Costs'!H16 -> 32896.718 | I3: ='Real Operating Costs'!I16 -> 34293.999 | ... K3: ='Real Operating Costs'!K16 -> 36176.2
A4: Net Real Operating Costs (millions) | B4: ='Real Operating Costs'!B15 -> 18712.531 | C4: ='Real Operating Costs'!C15 -> 20262.711 | D4: ='Real Operating Costs'!D15 -> 21081.642 | E4: ='Real Operating Costs'!E15 -> 23133.873 | F4: ='Real Operating Costs'!F15 -> 24364.592 | G4: ='Real Operating Costs'!G15 -> 23088.719 | H4: ='Real Operating Costs'!H15 -> 24310.467 | I4: ='Real Operating Costs'!I15 -> 26489.076 | ... K4: ='Real Operating Costs'!K15 -> 28020.1
J5: Correlation | K5: =CORREL(B3:K3,B4:K4) -> 0.97612696 | L5: positive correlation, this confirms again that Net Real Operating Costs increase almost proportionally with Real Revenue.
A21: Period | B21: Net Real Revenue (millions) | C21: Net Real Operating Costs
A22: 2015 | B22: 25569.576 | C22: 10795.219 | E22: Costs = f(Revenues) intercept | H22: =INTERCEPT(C22:C30,B22:B30) -> 38871.15 | I22: excluded 2020 here as well for consistency
A23: 2016 | B23: 27864.594 | C23: 11682.766 | E23: Costs = f(Revenues) slope | H23: =SLOPE(C22:C30,B22:B30) -> -1.0954159
A24: 2017 | B24: 28660.033 | C24: 9554.0272
A25: 2018 | B25: 31053.237 | C25: 579.37065
A26: 2019 | B26: 32556.783 | C26: 548.74156
A27: 2021 | B27: 32896.718 | C27: 555.7008
A28: 2022 | B28: 34293.999 | C28: 621.11437
A29: 2023 | B29: 37014.596 | C29: 1109.8535
A30: 2024 | B30: 36176.2 | C30: 1010.7
A31: 2025 | B31: ='Forecasting Sales'!C31 -> 38288.669 | C31: =$H$22+$H$23*B31 -> -3070.8668
A32: 2026 | B32: ='Forecasting Sales'!C32 -> 39458.915 | C32: =$H$22+$H$23*B32 -> -4352.7727
A33: 2027 | B33: ='Forecasting Sales'!C33 -> 40629.161 | C33: =$H$22+$H$23*B33 -> -5634.6785
A34: 2028 | B34: ='Forecasting Sales'!C34 -> 41799.407 | C34: =$H$22+$H$23*B34 -> -6916.5844
A35: 2029 | B35: ='Forecasting Sales'!C35 -> 42969.653 | C35: =$H$22+$H$23*B35 -> -8198.4903
A36: 2030 | B36: ='Forecasting Sales'!C36 -> 44139.899 | C36: =$H$22+$H$23*B36 -> -9480.3961
A37: 2031 | B37: ='Forecasting Sales'!C37 -> 45310.144 | C37: =$H$22+$H$23*B37 -> -10762.302
A38: 2032 | B38: ='Forecasting Sales'!C38 -> 46480.39 | C38: =$H$22+$H$23*B38 -> -12044.208
A39: 2033 | B39: ='Forecasting Sales'!C39 -> 47650.636 | C39: =$H$22+$H$23*B39 -> -13326.114
A40: 2034 | B40: ='Forecasting Sales'!C40 -> 48820.882 | C40: =$H$22+$H$23*B40 -> -14608.02

Sheet Interest & Taxes
A1: All values are in $million, USD
B2: 2015 | C2: =B2+1 -> 2016 | D2: =C2+1 -> 2017 | E2: =D2+1 -> 2018 | F2: =E2+1 -> 2019 | G2: =F2+1 -> 2020 | H2: =G2+1 -> 2021 | I2: =H2+1 -> 2022 | J2: =I2+1 -> 2023 | K2: =J2+1 -> 2024
A3: Total Revenue (Net Real Revenue) | B3: ='Real Operating Costs'!B16 -> 25569.576 | C3: ='Real Operating Costs'!C16 -> 27864.594 | D3: ='Real Operating Costs'!D16 -> 28660.033 | E3: ='Real Operating Costs'!E16 -> 31053.237 | F3: ='Real Operating Costs'!F16 -> 32556.783 | G3: ='Real Operating Costs'!G16 -> 28495.736 | H3: ='Real Operating Costs'!H16 -> 32896.718 | I3: ='Real Operating Costs'!I16 -> 34293.999 | ... K3: ='Real Operating Costs'!K16 -> 36176.2
A4: EBITDA | B4: ='Historical Income Statement'!B59 -> 4284.9 | C4: ='Historical Income Statement'!C59 -> 4883.8 | D4: ='Historical Income Statement'!D59 -> 4963.9 | E4: ='Historical Income Statement'!E59 -> 5116 | F4: ='Historical Income Statement'!F59 -> 5365 | G4: ='Historical Income Statement'!G59 -> 3103.1 | H4: ='Historical Income Statement'!H59 -> 6225.7 | I4: ='Historical Income Statement'!I59 -> 5973.4 | ... K4: ='Historical Income Statement'!K59 -> 6723.3
A6: Long-Term Debt | B6: ='Historical Balance Sheet'!B42 -> 2347.5 | C6: ='Historical Balance Sheet'!C42 -> 3185.3 | D6: ='Historical Balance Sheet'!D42 -> 3932.6 | E6: ='Historical Balance Sheet'!E42 -> 9122.7 | F6: ='Historical Balance Sheet'!F42 -> 11169.6 | G6: ='Historical Balance Sheet'!G42 -> 14728.9 | H6: ='Historical Balance Sheet'!H42 -> 13618.2 | I6: ='Historical Balance Sheet'!I42 -> 13153.9 | ... K6: ='Historical Balance Sheet'!K42 -> 14338.7
A7: Interest Expense | B7: ='Historical Income Statement'!B17 -> 70.5 | C7: ='Historical Income Statement'!C17 -> -71.7 | D7: ='Historical Income Statement'!D17 -> 75.8 | E7: ='Historical Income Statement'!E17 -> 137.3 | F7: ='Historical Income Statement'!F17 -> 199.7 | G7: ='Historical Income Statement'!G17 -> 392 | H7: ='Historical Income Statement'!H17 -> 404.3 | I7: ='Historical Income Statement'!I17 -> 482.9 | ... K7: ='Historical Income Statement'!K17 -> 436.3
A8: Imputed Rate (Effectove Interest Rate) | B8: =B7/B6 -> 0.030031949 | C8: =C7/C6 -> -0.022509654 | D8: =D7/D6 -> 0.01927478 | E8: =E7/E6 -> 0.015050369 | F8: =F7/F6 -> 0.017878886 | G8: =G7/G6 -> 0.026614343 | H8: =H7/H6 -> 0.029688211 | I8: =I7/I6 -> 0.036711546 | ... K8: =K7/K6 -> 0.030428142
A10: Interest on debt | B10: =AVERAGE(B8:K8) -> 0.02167472
A11: Income tax rate | B11: =B17 -> 0.26043366 | C11: This one is biased by having historics from before flat corporate rate was implemented. May understate future tax burden if Starbucks’ operations or tax policy changes. Going to use 31%
B13: =B2 -> 2015 | C13: =C2 -> 2016 | D13: =D2 -> 2017 | E13: =E2 -> 2018 | F13: =F2 -> 2019 | G13: =G2 -> 2020 | H13: =H2 -> 2021 | I13: =I2 -> 2022 | ... K13: =K2 -> 2024
A14: Earnings before tax | B14: ='Historical Income Statement'!B21 -> 3579.6 | C14: ='Historical Income Statement'!C21 -> 4191.6 | D14: ='Historical Income Statement'!D21 -> 4381 | E14: ='Historical Income Statement'!E21 -> 4137.7 | F14: ='Historical Income Statement'!F21 -> 3978.3 | G14: ='Historical Income Statement'!G21 -> 1520.2 | H14: ='Historical Income Statement'!H21 -> 4705.4 | I14: ='Historical Income Statement'!I21 -> 4292.6 | ... K14: ='Historical Income Statement'!K21 -> 4994
A15: Income tax | B15: ='Historical Income Statement'!B30 -> 1143.7 | C15: ='Historical Income Statement'!C30 -> 1379.7 | D15: ='Historical Income Statement'!D30 -> 1432.6 | E15: ='Historical Income Statement'!E30 -> 1262 | F15: ='Historical Income Statement'!F30 -> 871.6 | G15: ='Historical Income Statement'!G30 -> 239.7 | H15: ='Historical Income Statement'!H30 -> 1156.6 | I15: ='Historical Income Statement'!I30 -> 948.5 | ... K15: ='Historical Income Statement'!K30 -> 1207.3
A16: Tax rate | B16: =B15/B14 -> 0.31950497 | C16: =C15/C14 -> 0.32915832 | D16: =D15/D14 -> 0.32700297 | E16: =E15/E14 -> 0.30500036 | F16: =F15/F14 -> 0.21908856 | G16: =G15/G14 -> 0.15767662 | H16: =H15/H14 -> 0.24580269 | I16: =I15/I14 -> 0.22096165 | ... K16: =K15/K14 -> 0.2417501
A17: Average tax rate | B17: =AVERAGE(B16:K16) -> 0.26043366
A19: Normalized effective Tax rate | B19: 0.31
A21: Additional Comments:
A22: Calculated based on Net Real Revenue (millions) because it accounts for inflation and is correct predictor for valuation
A23: Doesn’t look like my tax rate had any outliers, including year 2021 and 2022 where there were changes due to Trump's tax policy
A24: The 31% is normalized / smoothed effective tax rate calculated by CapIQ

Sheet Fixed Asset Forecasting
A1: (All values are in $million USD)
B2: 2015 | C2: =B2+1 -> 2016 | D2: =C2+1 -> 2017 | E2: =D2+1 -> 2018 | F2: =E2+1 -> 2019 | G2: =F2+1 -> 2020 | H2: =G2+1 -> 2021 | I2: =H2+1 -> 2022 | J2: =I2+1 -> 2023 | K2: =J2+1 -> 2024
A3: Gross Property, Plant & Equipment | B3: ='Historical Balance Sheet'!B20 -> 9641.8 | C3: ='Historical Balance Sheet'!C20 -> 10573.3 | D3: ='Historical Balance Sheet'!D20 -> 11584 | E3: ='Historical Balance Sheet'!E20 -> 13197.1 | F3: ='Historical Balance Sheet'!F20 -> 14273.5 | G3: ='Historical Balance Sheet'!G20 -> 22289.4 | H3: ='Historical Balance Sheet'!H20 -> 23064.8 | I3: ='Historical Balance Sheet'!I20 -> 23625.4 | ... K3: ='Historical Balance Sheet'!K20 -> 28727.2
A4: Pct Change | C4: =(C3-B3)/B3 -> 0.096610591 | D4: =(D3-C3)/C3 -> 0.095589835 | E4: =(E3-D3)/D3 -> 0.13925242 | F4: =(F3-E3)/E3 -> 0.081563374 | G4: =(G3-F3)/F3 -> 0.56159316 | H4: =(H3-G3)/G3 -> 0.034787836 | I4: =(I3-H3)/H3 -> 0.024305435 | J4: =(J3-I3)/I3 -> 0.088777333 | K4: =(K3-J3)/J3 -> 0.1167991
A6: Long-term Investments | B6: ='Historical Balance Sheet'!B24 -> 664.5 | C6: ='Historical Balance Sheet'!C24 -> 1496.2 | D6: ='Historical Balance Sheet'!D24 -> 1023.9 | E6: ='Historical Balance Sheet'!E24 -> 602.4 | F6: ='Historical Balance Sheet'!F24 -> 634.3 | G6: ='Historical Balance Sheet'!G24 -> 730.6 | H6: ='Historical Balance Sheet'!H24 -> 572.9 | I6: ='Historical Balance Sheet'!I24 -> 590.3 | ... K6: ='Historical Balance Sheet'!K24 -> 739.9
A7: Goodwill | B7: ='Historical Balance Sheet'!B25 -> 1575.4 | C7: ='Historical Balance Sheet'!C25 -> 1719.6 | D7: ='Historical Balance Sheet'!D25 -> 1539.2 | E7: ='Historical Balance Sheet'!E25 -> 3541.6 | F7: ='Historical Balance Sheet'!F25 -> 3490.8 | G7: ='Historical Balance Sheet'!G25 -> 3597.2 | H7: ='Historical Balance Sheet'!H25 -> 3677.3 | I7: ='Historical Balance Sheet'!I25 -> 3283.5 | ... K7: ='Historical Balance Sheet'!K25 -> 3315.7
A8: Other Intangibles | B8: ='Historical Balance Sheet'!B26 -> 520.4 | C8: ='Historical Balance Sheet'!C26 -> 516.3 | D8: ='Historical Balance Sheet'!D26 -> 441.4 | E8: ='Historical Balance Sheet'!E26 -> 1042.2 | F8: ='Historical Balance Sheet'!F26 -> 781.8 | G8: ='Historical Balance Sheet'!G26 -> 552.1 | H8: ='Historical Balance Sheet'!H26 -> 349.9 | I8: ='Historical Balance Sheet'!I26 -> 155.9 | ... K8: ='Historical Balance Sheet'!K26 -> 100.9
A9: Deferred Charges, LT | B9: ='Historical Balance Sheet'!B27 -> 1180.8 | C9: ='Historical Balance Sheet'!C27 -> 885.4 | D9: ='Historical Balance Sheet'!D27 -> 795.4 | E9: ='Historical Balance Sheet'!E27 -> 134.7 | F9: ='Historical Balance Sheet'!F27 -> 1765.8 | G9: ='Historical Balance Sheet'!G27 -> 1789.9 | H9: ='Historical Balance Sheet'!H27 -> 1874.8 | I9: ='Historical Balance Sheet'!I27 -> 1799.7 | ... K9: ='Historical Balance Sheet'!K27 -> 1766.7
A10: Other Long-Term Assets | B10: ='Historical Balance Sheet'!B28 -> 415.9 | C10: ='Historical Balance Sheet'!C28 -> 403.3 | D10: ='Historical Balance Sheet'!D28 -> 362.8 | E10: ='Historical Balance Sheet'!E28 -> 412.2 | F10: ='Historical Balance Sheet'!F28 -> 461.3 | G10: ='Historical Balance Sheet'!G28 -> 522.8 | H10: ='Historical Balance Sheet'!H28 -> 555.8 | I10: ='Historical Balance Sheet'!I28 -> 554.2 | ... K10: ='Historical Balance Sheet'!K28 -> 617
B11: =SUM(B6:B10) -> 4357 | C11: =SUM(C6:C10) -> 5020.8 | D11: =SUM(D6:D10) -> 4162.7 | E11: =SUM(E6:E10) -> 5733.1 | F11: =SUM(F6:F10) -> 7134 | G11: =SUM(G6:G10) -> 7192.6 | H11: =SUM(H6:H10) -> 7030.7 | I11: =SUM(I6:I10) -> 6383.6 | ... K11: =SUM(K6:K10) -> 6540.2
A12: Pct Change | C12: =(C11-B11)/B11 -> 0.15235254 | D12: =(D11-C11)/C11 -> -0.17090902 | E12: =(E11-D11)/D11 -> 0.37725515 | F12: =(F11-E11)/E11 -> 0.24435297 | G12: =(G11-F11)/F11 -> 0.0082141856 | H12: =(H11-G11)/G11 -> -0.022509246 | I12: =(I11-H11)/H11 -> -0.0920392 | J12: =(J11-I11)/I11 -> -0.0064540385 | K12: =(K11-J11)/J11 -> 0.031186932

Sheet Dividend Forecasting
B2: 2015 | C2: =B2+1 -> 2016 | D2: =C2+1 -> 2017 | E2: =D2+1 -> 2018 | F2: =E2+1 -> 2019 | G2: =F2+1 -> 2020 | H2: =G2+1 -> 2021 | I2: =H2+1 -> 2022 | J2: =I2+1 -> 2023 | K2: =J2+1 -> 2024
A3: Dividends per Share | B3: ='Historical Income Statement'!B53 -> 0.68 | C3: ='Historical Income Statement'!C53 -> 0.85 | D3: ='Historical Income Statement'!D53 -> 1.05 | E3: ='Historical Income Statement'!E53 -> 1.32 | F3: ='Historical Income Statement'!F53 -> 1.49 | G3: ='Historical Income Statement'!G53 -> 1.68 | H3: ='Historical Income Statement'!H53 -> 1.84 | I3: ='Historical Income Statement'!I53 -> 2 | ... K3: ='Historical Income Statement'!K53 -> 2.32
A4: Payout Ratio % | B4: ='Historical Income Statement'!B54 -> 0.336766 | C4: ='Historical Income Statement'!C54 -> 0.418071 | D4: ='Historical Income Statement'!D54 -> 0.50279 | E4: ='Historical Income Statement'!E54 -> 0.385853 | F4: ='Historical Income Statement'!F54 -> 0.489358 | G4: ='Historical Income Statement'!G54 -> 2.072067 | H4: ='Historical Income Statement'!H54 -> 0.504607 | I4: ='Historical Income Statement'!I54 -> 0.689694 | ... K4: ='Historical Income Statement'!K54 -> 0.687335
A6: Dividend Growth Rate | C6: =(C3-B3)/C3 -> 0.2 | D6: =(D3-C3)/D3 -> 0.19047619 | E6: =(E3-D3)/E3 -> 0.20454545 | F6: =(F3-E3)/F3 -> 0.11409396 | G6: =(G3-F3)/G3 -> 0.11309524 | H6: =(H3-G3)/H3 -> 0.086956522 | I6: =(I3-H3)/I3 -> 0.08 | J6: =(J3-I3)/J3 -> 0.074074074 | K6: =(K3-J3)/K3 -> 0.068965517
A7: Dividend Growth Amount | C7: =C3-B3 -> 0.17 | D7: =D3-C3 -> 0.2 | E7: =E3-D3 -> 0.27 | F7: =F3-E3 -> 0.17 | G7: =G3-F3 -> 0.19 | H7: =H3-G3 -> 0.16 | I7: =I3-H3 -> 0.16 | J7: =J3-I3 -> 0.16 | K7: =K3-J3 -> 0.16

Sheet Net Working Capital
A1: (All values are in $million USD)
A3: Analysis of Net Working Capital | B3: 2015 | C3: =B3+1 -> 2016 | D3: =C3+1 -> 2017 | E3: =D3+1 -> 2018 | F3: =E3+1 -> 2019 | G3: =F3+1 -> 2020 | H3: =G3+1 -> 2021 | I3: =H3+1 -> 2022 | J3: =I3+1 -> 2023 | K3: =J3+1 -> 2024
A4: Revenues | B4: ='Historical Income Statement'!B6 -> 19162.7 | C4: ='Historical Income Statement'!C6 -> 21315.9 | D4: ='Historical Income Statement'!D6 -> 22386.8 | E4: ='Historical Income Statement'!E6 -> 24719.5 | F4: ='Historical Income Statement'!F6 -> 26508.6 | G4: ='Historical Income Statement'!G6 -> 23518 | H4: ='Historical Income Statement'!H6 -> 29060.6 | I4: ='Historical Income Statement'!I6 -> 32250.3 | ... K4: ='Historical Income Statement'!K6 -> 36176.2
A5: Cost of Goods Sold | B5: ='Historical Income Statement'!B7 -> 13198.6 | C5: ='Historical Income Statement'!C7 -> 14573.3 | D5: ='Historical Income Statement'!D7 -> 15552.2 | E5: ='Historical Income Statement'!E7 -> 17402.9 | F5: ='Historical Income Statement'!F7 -> 19020.5 | G5: ='Historical Income Statement'!G7 -> 18376.9 | H5: ='Historical Income Statement'!H7 -> 20625.2 | I5: ='Historical Income Statement'!I7 -> 23864.9 | ... K5: ='Historical Income Statement'!K7 -> 26443.8
A6: Selling General & Admin Exp. | B6: ='Historical Income Statement'!B9 -> 1196.7 | C6: ='Historical Income Statement'!C9 -> 1408.9 | D6: ='Historical Income Statement'!D9 -> 1408.4 | E6: ='Historical Income Statement'!E9 -> 1704.6 | F6: ='Historical Income Statement'!F9 -> 1824.1 | G6: ='Historical Income Statement'!G9 -> 1679.6 | H6: ='Historical Income Statement'!H9 -> 1932.6 | I6: ='Historical Income Statement'!I9 -> 2032 | ... K6: ='Historical Income Statement'!K9 -> 2523.3
A7: Depreciation & Amort. | B7: ='Historical Income Statement'!B11 -> 893.9 | C7: ='Historical Income Statement'!C11 -> 980.8 | D7: ='Historical Income Statement'!D11 -> 1011.4 | E7: ='Historical Income Statement'!E11 -> 1247 | F7: ='Historical Income Statement'!F11 -> 1377.3 | G7: ='Historical Income Statement'!G11 -> 1431.3 | H7: ='Historical Income Statement'!H11 -> 1441.7 | I7: ='Historical Income Statement'!I11 -> 1447.9 | ... K7: ='Historical Income Statement'!K11 -> 1512.6
A8: Other Operating Expense/(Income) | B8: ='Historical Income Statement'!B12 -> 522.4 | C8: ='Historical Income Statement'!C12 -> 499.2 | D8: ='Historical Income Statement'!D12 -> 518 | E8: ='Historical Income Statement'!E12 -> 554.9 | F8: ='Historical Income Statement'!F12 -> 371 | G8: ='Historical Income Statement'!G12 -> 430.3 | H8: ='Historical Income Statement'!H12 -> 359.5 | I8: ='Historical Income Statement'!I12 -> 461.5 | ... K8: ='Historical Income Statement'!K12 -> 565.6
A9: Operating Costs | B9: ='Historical Income Statement'!B13+'Historical Income Statement'!B7 -> 15811.6 | C9: ='Historical Income Statement'!C13+'Historical Income Statement'!C7 -> 17462.2 | D9: ='Historical Income Statement'!D13+'Historical Income Statement'!D7 -> 18490 | E9: ='Historical Income Statement'!E13+'Historical Income Statement'!E7 -> 20909.4 | F9: ='Historical Income Statement'!F13+'Historical Income Statement'!F7 -> 22592.9 | G9: ='Historical Income Statement'!G13+'Historical Income Statement'!G7 -> 21918.1 | H9: ='Historical Income Statement'!H13+'Historical Income Statement'!H7 -> 24359 | I9: ='Historical Income Statement'!I13+'Historical Income Statement'!I7 -> 27806.3 | ... K9: ='Historical Income Statement'!K13+'Historical Income Statement'!K7 -> 31045.3
A11: Current Assets
A12: Cash and Cash Equivalents | B12: ='Historical Balance Sheet'!B6 -> 1530.1 | C12: ='Historical Balance Sheet'!C6 -> 2128.8 | D12: ='Historical Balance Sheet'!D6 -> 2462.3 | E12: ='Historical Balance Sheet'!E6 -> 8756.3 | F12: ='Historical Balance Sheet'!F6 -> 2686.6 | G12: ='Historical Balance Sheet'!G6 -> 4350.9 | H12: ='Historical Balance Sheet'!H6 -> 6455.7 | I12: ='Historical Balance Sheet'!I6 -> 2818.4 | ... K12: ='Historical Balance Sheet'!K6 -> 3286.2
A13: Short-term Investments | B13: ='Historical Balance Sheet'!B7 -> 81.3 | C13: ='Historical Balance Sheet'!C7 -> 134.4 | D13: ='Historical Balance Sheet'!D7 -> 228.6 | E13: ='Historical Balance Sheet'!E7 -> 181.5 | F13: ='Historical Balance Sheet'!F7 -> 70.5 | G13: ='Historical Balance Sheet'!G7 -> 281.2 | H13: ='Historical Balance Sheet'!H7 -> 162.2 | I13: ='Historical Balance Sheet'!I7 -> 364.5 | ... K13: ='Historical Balance Sheet'!K7 -> 257
A14: Trading Asset Securities | B14: ='Historical Balance Sheet'!B8 -> 0 | C14: ='Historical Balance Sheet'!C8 -> 0 | D14: ='Historical Balance Sheet'!D8 -> 0 | E14: ='Historical Balance Sheet'!E8 -> 0 | F14: ='Historical Balance Sheet'!F8 -> 0 | G14: ='Historical Balance Sheet'!G8 -> 0 | H14: ='Historical Balance Sheet'!H8 -> 0 | I14: ='Historical Balance Sheet'!I8 -> 0 | ... K14: ='Historical Balance Sheet'!K8 -> 0
A15: Receivables | B15: ='Historical Balance Sheet'!B12 -> 719 | C15: ='Historical Balance Sheet'!C12 -> 768.8 | D15: ='Historical Balance Sheet'!D12 -> 938.4 | E15: ='Historical Balance Sheet'!E12 -> 1648.5 | F15: ='Historical Balance Sheet'!F12 -> 1020.3 | G15: ='Historical Balance Sheet'!G12 -> 1395.4 | H15: ='Historical Balance Sheet'!H12 -> 1133.1 | I15: ='Historical Balance Sheet'!I12 -> 1244.9 | ... K15: ='Historical Balance Sheet'!K12 -> 1213.8
A16: Inventories | B16: ='Historical Balance Sheet'!B13 -> 1306.4 | C16: ='Historical Balance Sheet'!C13 -> 1378.5 | D16: ='Historical Balance Sheet'!D13 -> 1364 | E16: ='Historical Balance Sheet'!E13 -> 1400.5 | F16: ='Historical Balance Sheet'!F13 -> 1529.4 | G16: ='Historical Balance Sheet'!G13 -> 1551.4 | H16: ='Historical Balance Sheet'!H13 -> 1603.9 | I16: ='Historical Balance Sheet'!I13 -> 2176.6 | ... K16: ='Historical Balance Sheet'!K13 -> 1777.3
A17: Prepaid Expenses | B17: ='Historical Balance Sheet'!B14 -> 283.4 | C17: ='Historical Balance Sheet'!C14 -> 319.7 | D17: ='Historical Balance Sheet'!D14 -> 276.7 | E17: ='Historical Balance Sheet'!E14 -> 482.9 | F17: ='Historical Balance Sheet'!F14 -> 334.5 | G17: ='Historical Balance Sheet'!G14 -> 211.9 | H17: ='Historical Balance Sheet'!H14 -> 253.9 | I17: ='Historical Balance Sheet'!I14 -> 339.2 | ... K17: ='Historical Balance Sheet'!K14 -> 292
A18: Restricted Cash | B18: ='Historical Balance Sheet'!B15 -> 0 | C18: ='Historical Balance Sheet'!C15 -> 0 | D18: ='Historical Balance Sheet'!D15 -> 0 | E18: ='Historical Balance Sheet'!E15 -> 0 | F18: ='Historical Balance Sheet'!F15 -> 0 | G18: ='Historical Balance Sheet'!G15 -> 0 | H18: ='Historical Balance Sheet'!H15 -> 0 | I18: ='Historical Balance Sheet'!I15 -> 0 | ... K18: ='Historical Balance Sheet'!K15 -> 12.4
A19: Other Current Assets | B19: ='Historical Balance Sheet'!B16 -> 50.8 | C19: ='Historical Balance Sheet'!C16 -> 27.7 | D19: ='Historical Balance Sheet'!D16 -> 13.4 | E19: ='Historical Balance Sheet'!E16 -> 24.5 | F19: ='Historical Balance Sheet'!F16 -> 12.6 | G19: ='Historical Balance Sheet'!G16 -> 15.6 | H19: ='Historical Balance Sheet'!H16 -> 147.6 | I19: ='Historical Balance Sheet'!I16 -> 75.1 | ... K19: ='Historical Balance Sheet'!K16 -> 8.7
A21: Current Liabilites
A22: Accounts Payable | B22: ='Historical Balance Sheet'!B32 -> 684.2 | C22: ='Historical Balance Sheet'!C32 -> 730.6 | D22: ='Historical Balance Sheet'!D32 -> 782.5 | E22: ='Historical Balance Sheet'!E32 -> 1179.3 | F22: ='Historical Balance Sheet'!F32 -> 1189.7 | G22: ='Historical Balance Sheet'!G32 -> 997.9 | H22: ='Historical Balance Sheet'!H32 -> 1211.6 | I22: ='Historical Balance Sheet'!I32 -> 1441.4 | ... K22: ='Historical Balance Sheet'!K32 -> 1595.5
A23: Accrued Expense | B23: ='Historical Balance Sheet'!B33 -> 884.3 | C23: ='Historical Balance Sheet'!C33 -> 894.3 | D23: ='Historical Balance Sheet'!D33 -> 891 | E23: ='Historical Balance Sheet'!E33 -> 1218.5 | F23: ='Historical Balance Sheet'!F33 -> 1228.7 | G23: ='Historical Balance Sheet'!G33 -> 1179.5 | H23: ='Historical Balance Sheet'!H33 -> 1326.7 | I23: ='Historical Balance Sheet'!I33 -> 1273.2 | ... K23: ='Historical Balance Sheet'!K33 -> 1323.8
A24: Short-term Borrowings | B24: ='Historical Balance Sheet'!B34 -> 0 | C24: ='Historical Balance Sheet'!C34 -> 0 | D24: ='Historical Balance Sheet'!D34 -> 0 | E24: ='Historical Balance Sheet'!E34 -> 0 | F24: ='Historical Balance Sheet'!F34 -> 0 | G24: ='Historical Balance Sheet'!G34 -> 438.8 | H24: ='Historical Balance Sheet'!H34 -> 0 | I24: ='Historical Balance Sheet'!I34 -> 175 | ... K24: ='Historical Balance Sheet'!K34 -> 0
A25: Curr. Port. of LT Debt | B25: ='Historical Balance Sheet'!B35 -> 0 | C25: ='Historical Balance Sheet'!C35 -> 399.9 | D25: ='Historical Balance Sheet'!D35 -> 0 | E25: ='Historical Balance Sheet'!E35 -> 349.9 | F25: ='Historical Balance Sheet'!F35 -> 0 | G25: ='Historical Balance Sheet'!G35 -> 1249.9 | H25: ='Historical Balance Sheet'!H35 -> 998.9 | I25: ='Historical Balance Sheet'!I35 -> 1761 | ... K25: ='Historical Balance Sheet'!K35 -> 1248.9
A26: Curr. Port. of Leases | B26: ='Historical Balance Sheet'!B36 -> 0 | C26: ='Historical Balance Sheet'!C36 -> 0 | D26: ='Historical Balance Sheet'!D36 -> 0 | E26: ='Historical Balance Sheet'!E36 -> 0 | F26: ='Historical Balance Sheet'!F36 -> 0 | G26: ='Historical Balance Sheet'!G36 -> 1248.8 | H26: ='Historical Balance Sheet'!H36 -> 1251.3 | I26: ='Historical Balance Sheet'!I36 -> 1245.7 | ... K26: ='Historical Balance Sheet'!K36 -> 1463.1
A27: Curr. Income Taxes Payable | B27: ='Historical Balance Sheet'!B37 -> 259 | C27: ='Historical Balance Sheet'!C37 -> 368.4 | D27: ='Historical Balance Sheet'!D37 -> 226.6 | E27: ='Historical Balance Sheet'!E37 -> 102.8 | F27: ='Historical Balance Sheet'!F37 -> 1291.7 | G27: ='Historical Balance Sheet'!G37 -> 98.2 | H27: ='Historical Balance Sheet'!H37 -> 348 | I27: ='Historical Balance Sheet'!I37 -> 139.2 | ... K27: ='Historical Balance Sheet'!K37 -> 123.5
